2024-02-24 01:00:27,179 INFO org.apache.hadoop.yarn.server.resourcemanager.ResourceManager: STARTUP_MSG: 
/************************************************************
STARTUP_MSG: Starting ResourceManager
STARTUP_MSG:   user = ubuntu
STARTUP_MSG:   host = 5acd4955-724f-452a-817c-900b09ccd050-node1/10.30.6.115
STARTUP_MSG:   args = []
STARTUP_MSG:   version = 2.8.1
STARTUP_MSG:   build = https://git-wip-us.apache.org/repos/asf/hadoop.git -r 20fe5304904fc2f5a18053c389e43cd26f7a70fe; compiled by 'vinodkv' on 2017-06-02T06:14Z
STARTUP_MSG:   java = 1.8.0_362
************************************************************/
2024-02-24 01:00:27,187 INFO org.apache.hadoop.yarn.server.resourcemanager.ResourceManager: registered UNIX signal handlers for [TERM, HUP, INT]
2024-02-24 01:00:27,388 INFO org.apache.hadoop.conf.Configuration: found resource core-site.xml at file:/home/ubuntu/bigdata/hadoop-2.8.1/etc/hadoop/core-site.xml
2024-02-24 01:00:27,421 WARN org.apache.hadoop.util.NativeCodeLoader: Unable to load native-hadoop library for your platform... using builtin-java classes where applicable
2024-02-24 01:00:27,439 INFO org.apache.hadoop.security.Groups: clearing userToGroupsMap cache
2024-02-24 01:00:27,486 INFO org.apache.hadoop.conf.Configuration: found resource yarn-site.xml at file:/home/ubuntu/bigdata/hadoop-2.8.1/etc/hadoop/yarn-site.xml
2024-02-24 01:00:27,615 INFO org.apache.hadoop.yarn.event.AsyncDispatcher: Registering class org.apache.hadoop.yarn.server.resourcemanager.RMFatalEventType for class org.apache.hadoop.yarn.server.resourcemanager.ResourceManager$RMFatalEventDispatcher
2024-02-24 01:00:27,649 INFO org.apache.hadoop.yarn.server.resourcemanager.security.NMTokenSecretManagerInRM: NMTokenKeyRollingInterval: 86400000ms and NMTokenKeyActivationDelay: 900000ms
2024-02-24 01:00:27,652 INFO org.apache.hadoop.yarn.server.resourcemanager.security.RMContainerTokenSecretManager: ContainerTokenKeyRollingInterval: 86400000ms and ContainerTokenKeyActivationDelay: 900000ms
2024-02-24 01:00:27,656 INFO org.apache.hadoop.yarn.server.resourcemanager.security.AMRMTokenSecretManager: AMRMTokenKeyRollingInterval: 86400000ms and AMRMTokenKeyActivationDelay: 900000 ms
2024-02-24 01:00:27,683 INFO org.apache.hadoop.yarn.event.AsyncDispatcher: Registering class org.apache.hadoop.yarn.server.resourcemanager.recovery.RMStateStoreEventType for class org.apache.hadoop.yarn.server.resourcemanager.recovery.RMStateStore$ForwardingEventHandler
2024-02-24 01:00:27,685 INFO org.apache.hadoop.yarn.event.AsyncDispatcher: Registering class org.apache.hadoop.yarn.server.resourcemanager.NodesListManagerEventType for class org.apache.hadoop.yarn.server.resourcemanager.NodesListManager
2024-02-24 01:00:27,685 INFO org.apache.hadoop.yarn.server.resourcemanager.ResourceManager: Using Scheduler: org.apache.hadoop.yarn.server.resourcemanager.scheduler.capacity.CapacityScheduler
2024-02-24 01:00:27,698 INFO org.apache.hadoop.yarn.event.AsyncDispatcher: Registering class org.apache.hadoop.yarn.server.resourcemanager.scheduler.event.SchedulerEventType for class org.apache.hadoop.yarn.server.resourcemanager.ResourceManager$SchedulerEventDispatcher
2024-02-24 01:00:27,699 INFO org.apache.hadoop.yarn.event.AsyncDispatcher: Registering class org.apache.hadoop.yarn.server.resourcemanager.rmapp.RMAppEventType for class org.apache.hadoop.yarn.server.resourcemanager.ResourceManager$ApplicationEventDispatcher
2024-02-24 01:00:27,700 INFO org.apache.hadoop.yarn.event.AsyncDispatcher: Registering class org.apache.hadoop.yarn.server.resourcemanager.rmapp.attempt.RMAppAttemptEventType for class org.apache.hadoop.yarn.server.resourcemanager.ResourceManager$ApplicationAttemptEventDispatcher
2024-02-24 01:00:27,700 INFO org.apache.hadoop.yarn.event.AsyncDispatcher: Registering class org.apache.hadoop.yarn.server.resourcemanager.rmnode.RMNodeEventType for class org.apache.hadoop.yarn.server.resourcemanager.ResourceManager$NodeEventDispatcher
2024-02-24 01:00:27,730 INFO org.apache.hadoop.metrics2.impl.MetricsConfig: loaded properties from hadoop-metrics2.properties
2024-02-24 01:00:27,791 INFO org.apache.hadoop.metrics2.impl.MetricsSystemImpl: Scheduled Metric snapshot period at 10 second(s).
2024-02-24 01:00:27,791 INFO org.apache.hadoop.metrics2.impl.MetricsSystemImpl: ResourceManager metrics system started
2024-02-24 01:00:27,799 INFO org.apache.hadoop.yarn.event.AsyncDispatcher: Registering class org.apache.hadoop.yarn.server.resourcemanager.RMAppManagerEventType for class org.apache.hadoop.yarn.server.resourcemanager.RMAppManager
2024-02-24 01:00:27,805 INFO org.apache.hadoop.yarn.event.AsyncDispatcher: Registering class org.apache.hadoop.yarn.server.resourcemanager.amlauncher.AMLauncherEventType for class org.apache.hadoop.yarn.server.resourcemanager.amlauncher.ApplicationMasterLauncher
2024-02-24 01:00:27,807 INFO org.apache.hadoop.yarn.server.resourcemanager.RMNMInfo: Registered RMNMInfo MBean
2024-02-24 01:00:27,811 INFO org.apache.hadoop.yarn.security.YarnAuthorizationProvider: org.apache.hadoop.yarn.security.ConfiguredYarnAuthorizer is instiantiated.
2024-02-24 01:00:27,813 INFO org.apache.hadoop.util.HostsFileReader: Refreshing hosts (include/exclude) list
2024-02-24 01:00:27,817 INFO org.apache.hadoop.conf.Configuration: found resource capacity-scheduler.xml at file:/home/ubuntu/bigdata/hadoop-2.8.1/etc/hadoop/capacity-scheduler.xml
2024-02-24 01:00:27,855 INFO org.apache.hadoop.yarn.server.resourcemanager.scheduler.capacity.CapacitySchedulerConfiguration: max alloc mb per queue for root is undefined
2024-02-24 01:00:27,855 INFO org.apache.hadoop.yarn.server.resourcemanager.scheduler.capacity.CapacitySchedulerConfiguration: max alloc vcore per queue for root is undefined
2024-02-24 01:00:27,863 INFO org.apache.hadoop.yarn.server.resourcemanager.scheduler.capacity.ParentQueue: root, capacity=1.0, asboluteCapacity=1.0, maxCapacity=1.0, asboluteMaxCapacity=1.0, state=RUNNING, acls=ADMINISTER_QUEUE:*SUBMIT_APP:*, labels=*,, offswitchPerHeartbeatLimit = 1, reservationsContinueLooking=true
2024-02-24 01:00:27,863 INFO org.apache.hadoop.yarn.server.resourcemanager.scheduler.capacity.ParentQueue: Initialized parent-queue root name=root, fullname=root
2024-02-24 01:00:27,871 INFO org.apache.hadoop.yarn.server.resourcemanager.scheduler.capacity.CapacitySchedulerConfiguration: max alloc mb per queue for root.default is undefined
2024-02-24 01:00:27,871 INFO org.apache.hadoop.yarn.server.resourcemanager.scheduler.capacity.CapacitySchedulerConfiguration: max alloc vcore per queue for root.default is undefined
2024-02-24 01:00:27,872 INFO org.apache.hadoop.yarn.server.resourcemanager.scheduler.capacity.LeafQueue: Initializing default
capacity = 1.0 [= (float) configuredCapacity / 100 ]
asboluteCapacity = 1.0 [= parentAbsoluteCapacity * capacity ]
maxCapacity = 1.0 [= configuredMaxCapacity ]
absoluteMaxCapacity = 1.0 [= 1.0 maximumCapacity undefined, (parentAbsoluteMaxCapacity * maximumCapacity) / 100 otherwise ]
userLimit = 100 [= configuredUserLimit ]
userLimitFactor = 1.0 [= configuredUserLimitFactor ]
maxApplications = 10000 [= configuredMaximumSystemApplicationsPerQueue or (int)(configuredMaximumSystemApplications * absoluteCapacity)]
maxApplicationsPerUser = 10000 [= (int)(maxApplications * (userLimit / 100.0f) * userLimitFactor) ]
usedCapacity = 0.0 [= usedResourcesMemory / (clusterResourceMemory * absoluteCapacity)]
absoluteUsedCapacity = 0.0 [= usedResourcesMemory / clusterResourceMemory]
maxAMResourcePerQueuePercent = 0.1 [= configuredMaximumAMResourcePercent ]
minimumAllocationFactor = 0.875 [= (float)(maximumAllocationMemory - minimumAllocationMemory) / maximumAllocationMemory ]
maximumAllocation = <memory:8192, vCores:4> [= configuredMaxAllocation ]
numContainers = 0 [= currentNumContainers ]
state = RUNNING [= configuredState ]
acls = ADMINISTER_QUEUE:*SUBMIT_APP:* [= configuredAcls ]
nodeLocalityDelay = 40
labels=*,
reservationsContinueLooking = true
preemptionDisabled = true
defaultAppPriorityPerQueue = 0
2024-02-24 01:00:27,872 INFO org.apache.hadoop.yarn.server.resourcemanager.scheduler.capacity.CapacityScheduler: Initialized queue: default: capacity=1.0, absoluteCapacity=1.0, usedResources=<memory:0, vCores:0>, usedCapacity=0.0, absoluteUsedCapacity=0.0, numApps=0, numContainers=0
2024-02-24 01:00:27,873 INFO org.apache.hadoop.yarn.server.resourcemanager.scheduler.capacity.CapacityScheduler: Initialized queue: root: numChildQueue= 1, capacity=1.0, absoluteCapacity=1.0, usedResources=<memory:0, vCores:0>usedCapacity=0.0, numApps=0, numContainers=0
2024-02-24 01:00:27,873 INFO org.apache.hadoop.yarn.server.resourcemanager.scheduler.capacity.CapacityScheduler: Initialized root queue root: numChildQueue= 1, capacity=1.0, absoluteCapacity=1.0, usedResources=<memory:0, vCores:0>usedCapacity=0.0, numApps=0, numContainers=0
2024-02-24 01:00:27,873 INFO org.apache.hadoop.yarn.server.resourcemanager.scheduler.capacity.CapacityScheduler: Initialized queue mappings, override: false
2024-02-24 01:00:27,874 INFO org.apache.hadoop.yarn.server.resourcemanager.scheduler.capacity.CapacityScheduler: Initialized CapacityScheduler with calculator=class org.apache.hadoop.yarn.util.resource.DefaultResourceCalculator, minimumAllocation=<<memory:1024, vCores:1>>, maximumAllocation=<<memory:8192, vCores:4>>, asynchronousScheduling=false, asyncScheduleInterval=5ms
2024-02-24 01:00:27,876 INFO org.apache.hadoop.conf.Configuration: dynamic-resources.xml not found
2024-02-24 01:00:27,896 INFO org.apache.hadoop.yarn.server.resourcemanager.metrics.SystemMetricsPublisher: YARN system metrics publishing service is not enabled
2024-02-24 01:00:27,896 INFO org.apache.hadoop.yarn.server.resourcemanager.ResourceManager: Transitioning to active state
2024-02-24 01:00:27,900 INFO org.apache.hadoop.util.JvmPauseMonitor: Starting JVM pause monitor
2024-02-24 01:00:27,909 INFO org.apache.hadoop.yarn.server.resourcemanager.recovery.RMStateStore: Updating AMRMToken
2024-02-24 01:00:27,909 INFO org.apache.hadoop.yarn.server.resourcemanager.security.RMContainerTokenSecretManager: Rolling master-key for container-tokens
2024-02-24 01:00:27,909 INFO org.apache.hadoop.yarn.server.resourcemanager.security.NMTokenSecretManagerInRM: Rolling master-key for nm-tokens
2024-02-24 01:00:27,909 INFO org.apache.hadoop.security.token.delegation.AbstractDelegationTokenSecretManager: Updating the current master key for generating delegation tokens
2024-02-24 01:00:27,910 INFO org.apache.hadoop.yarn.server.resourcemanager.security.RMDelegationTokenSecretManager: storing master key with keyID 1
2024-02-24 01:00:27,910 INFO org.apache.hadoop.yarn.server.resourcemanager.recovery.RMStateStore: Storing RMDTMasterKey.
2024-02-24 01:00:27,911 INFO org.apache.hadoop.security.token.delegation.AbstractDelegationTokenSecretManager: Starting expired delegation token remover thread, tokenRemoverScanInterval=60 min(s)
2024-02-24 01:00:27,911 INFO org.apache.hadoop.security.token.delegation.AbstractDelegationTokenSecretManager: Updating the current master key for generating delegation tokens
2024-02-24 01:00:27,911 INFO org.apache.hadoop.yarn.server.resourcemanager.security.RMDelegationTokenSecretManager: storing master key with keyID 2
2024-02-24 01:00:27,911 INFO org.apache.hadoop.yarn.server.resourcemanager.recovery.RMStateStore: Storing RMDTMasterKey.
2024-02-24 01:00:27,912 INFO org.apache.hadoop.yarn.event.AsyncDispatcher: Registering class org.apache.hadoop.yarn.nodelabels.event.NodeLabelsStoreEventType for class org.apache.hadoop.yarn.nodelabels.CommonNodeLabelsManager$ForwardingEventHandler
2024-02-24 01:00:27,929 INFO org.apache.hadoop.ipc.CallQueueManager: Using callQueue: class java.util.concurrent.LinkedBlockingQueue queueCapacity: 5000 scheduler: class org.apache.hadoop.ipc.DefaultRpcScheduler
2024-02-24 01:00:27,936 INFO org.apache.hadoop.ipc.Server: Starting Socket Reader #1 for port 8031
2024-02-24 01:00:28,036 INFO org.apache.hadoop.yarn.factories.impl.pb.RpcServerFactoryPBImpl: Adding protocol org.apache.hadoop.yarn.server.api.ResourceTrackerPB to the server
2024-02-24 01:00:28,037 INFO org.apache.hadoop.ipc.Server: IPC Server Responder: starting
2024-02-24 01:00:28,037 INFO org.apache.hadoop.ipc.Server: IPC Server listener on 8031: starting
2024-02-24 01:00:28,061 INFO org.apache.hadoop.ipc.CallQueueManager: Using callQueue: class java.util.concurrent.LinkedBlockingQueue queueCapacity: 5000 scheduler: class org.apache.hadoop.ipc.DefaultRpcScheduler
2024-02-24 01:00:28,067 INFO org.apache.hadoop.ipc.Server: Starting Socket Reader #1 for port 8030
2024-02-24 01:00:28,075 INFO org.apache.hadoop.yarn.factories.impl.pb.RpcServerFactoryPBImpl: Adding protocol org.apache.hadoop.yarn.api.ApplicationMasterProtocolPB to the server
2024-02-24 01:00:28,076 INFO org.apache.hadoop.ipc.Server: IPC Server Responder: starting
2024-02-24 01:00:28,076 INFO org.apache.hadoop.ipc.Server: IPC Server listener on 8030: starting
2024-02-24 01:00:28,132 INFO org.apache.hadoop.ipc.CallQueueManager: Using callQueue: class java.util.concurrent.LinkedBlockingQueue queueCapacity: 5000 scheduler: class org.apache.hadoop.ipc.DefaultRpcScheduler
2024-02-24 01:00:28,133 INFO org.apache.hadoop.ipc.Server: Starting Socket Reader #1 for port 8032
2024-02-24 01:00:28,138 INFO org.apache.hadoop.yarn.factories.impl.pb.RpcServerFactoryPBImpl: Adding protocol org.apache.hadoop.yarn.api.ApplicationClientProtocolPB to the server
2024-02-24 01:00:28,138 INFO org.apache.hadoop.ipc.Server: IPC Server Responder: starting
2024-02-24 01:00:28,139 INFO org.apache.hadoop.ipc.Server: IPC Server listener on 8032: starting
2024-02-24 01:00:28,155 INFO org.apache.hadoop.yarn.server.resourcemanager.ResourceManager: Transitioned to active state
2024-02-24 01:00:28,255 INFO org.mortbay.log: Logging to org.slf4j.impl.Log4jLoggerAdapter(org.mortbay.log) via org.mortbay.log.Slf4jLog
2024-02-24 01:00:28,260 INFO org.apache.hadoop.security.authentication.server.AuthenticationFilter: Unable to initialize FileSignerSecretProvider, falling back to use random secrets.
2024-02-24 01:00:28,265 INFO org.apache.hadoop.http.HttpRequestLog: Http request log for http.requests.resourcemanager is not defined
2024-02-24 01:00:28,270 INFO org.apache.hadoop.http.HttpServer2: Added global filter 'safety' (class=org.apache.hadoop.http.HttpServer2$QuotingInputFilter)
2024-02-24 01:00:28,272 INFO org.apache.hadoop.http.HttpServer2: Added filter RMAuthenticationFilter (class=org.apache.hadoop.yarn.server.security.http.RMAuthenticationFilter) to context cluster
2024-02-24 01:00:28,272 INFO org.apache.hadoop.http.HttpServer2: Added filter RMAuthenticationFilter (class=org.apache.hadoop.yarn.server.security.http.RMAuthenticationFilter) to context static
2024-02-24 01:00:28,273 INFO org.apache.hadoop.http.HttpServer2: Added filter RMAuthenticationFilter (class=org.apache.hadoop.yarn.server.security.http.RMAuthenticationFilter) to context logs
2024-02-24 01:00:28,273 INFO org.apache.hadoop.http.HttpServer2: Added filter static_user_filter (class=org.apache.hadoop.http.lib.StaticUserWebFilter$StaticUserFilter) to context cluster
2024-02-24 01:00:28,273 INFO org.apache.hadoop.http.HttpServer2: Added filter static_user_filter (class=org.apache.hadoop.http.lib.StaticUserWebFilter$StaticUserFilter) to context static
2024-02-24 01:00:28,273 INFO org.apache.hadoop.http.HttpServer2: Added filter static_user_filter (class=org.apache.hadoop.http.lib.StaticUserWebFilter$StaticUserFilter) to context logs
2024-02-24 01:00:28,275 INFO org.apache.hadoop.http.HttpServer2: adding path spec: /cluster/*
2024-02-24 01:00:28,275 INFO org.apache.hadoop.http.HttpServer2: adding path spec: /ws/*
2024-02-24 01:00:28,495 INFO org.apache.hadoop.yarn.webapp.WebApps: Registered webapp guice modules
2024-02-24 01:00:28,498 INFO org.apache.hadoop.http.HttpServer2: Jetty bound to port 8088
2024-02-24 01:00:28,498 INFO org.mortbay.log: jetty-6.1.26
2024-02-24 01:00:28,520 INFO org.mortbay.log: Extract jar:file:/home/ubuntu/bigdata/hadoop-2.8.1/share/hadoop/yarn/hadoop-yarn-common-2.8.1.jar!/webapps/cluster to /tmp/Jetty_0_0_0_0_8088_cluster____u0rgz3/webapp
2024-02-24 01:00:28,667 INFO org.apache.hadoop.security.token.delegation.AbstractDelegationTokenSecretManager: Updating the current master key for generating delegation tokens
2024-02-24 01:00:28,667 INFO org.apache.hadoop.security.token.delegation.AbstractDelegationTokenSecretManager: Starting expired delegation token remover thread, tokenRemoverScanInterval=60 min(s)
2024-02-24 01:00:28,667 INFO org.apache.hadoop.security.token.delegation.AbstractDelegationTokenSecretManager: Updating the current master key for generating delegation tokens
2024-02-24 01:00:29,377 INFO org.mortbay.log: Started HttpServer2$SelectChannelConnectorWithSafeStartup@0.0.0.0:8088
2024-02-24 01:00:29,378 INFO org.apache.hadoop.yarn.webapp.WebApps: Web app cluster started at 8088
2024-02-24 01:00:29,399 INFO org.apache.hadoop.ipc.CallQueueManager: Using callQueue: class java.util.concurrent.LinkedBlockingQueue queueCapacity: 100 scheduler: class org.apache.hadoop.ipc.DefaultRpcScheduler
2024-02-24 01:00:29,443 INFO org.apache.hadoop.ipc.Server: Starting Socket Reader #1 for port 8033
2024-02-24 01:00:29,445 INFO org.apache.hadoop.yarn.factories.impl.pb.RpcServerFactoryPBImpl: Adding protocol org.apache.hadoop.yarn.server.api.ResourceManagerAdministrationProtocolPB to the server
2024-02-24 01:00:29,446 INFO org.apache.hadoop.ipc.Server: IPC Server Responder: starting
2024-02-24 01:00:29,446 INFO org.apache.hadoop.ipc.Server: IPC Server listener on 8033: starting
2024-02-24 01:00:30,735 INFO org.apache.hadoop.yarn.server.resourcemanager.ResourceTrackerService: NodeManager from node 5acd4955-724f-452a-817c-900b09ccd050-node1(cmPort: 40703 httpPort: 8042) registered with capability: <memory:8192, vCores:8>, assigned nodeId 5acd4955-724f-452a-817c-900b09ccd050-node1:40703
2024-02-24 01:00:30,739 INFO org.apache.hadoop.yarn.server.resourcemanager.rmnode.RMNodeImpl: 5acd4955-724f-452a-817c-900b09ccd050-node1:40703 Node Transitioned from NEW to RUNNING
2024-02-24 01:00:30,744 INFO org.apache.hadoop.yarn.server.resourcemanager.scheduler.capacity.CapacityScheduler: Added node 5acd4955-724f-452a-817c-900b09ccd050-node1:40703 clusterResource: <memory:8192, vCores:8>
2024-02-24 01:01:06,684 ERROR org.apache.hadoop.yarn.server.resourcemanager.ResourceManager: RECEIVED SIGNAL 15: SIGTERM
2024-02-24 01:01:06,686 ERROR org.apache.hadoop.security.token.delegation.AbstractDelegationTokenSecretManager: ExpiredTokenRemover received java.lang.InterruptedException: sleep interrupted
2024-02-24 01:01:06,687 INFO org.mortbay.log: Stopped HttpServer2$SelectChannelConnectorWithSafeStartup@0.0.0.0:8088
2024-02-24 01:01:06,787 INFO org.apache.hadoop.ipc.Server: Stopping server on 8032
2024-02-24 01:01:06,788 INFO org.apache.hadoop.ipc.Server: Stopping IPC Server listener on 8032
2024-02-24 01:01:06,788 INFO org.apache.hadoop.ipc.Server: Stopping server on 8033
2024-02-24 01:01:06,788 INFO org.apache.hadoop.ipc.Server: Stopping IPC Server Responder
2024-02-24 01:01:06,788 INFO org.apache.hadoop.ipc.Server: Stopping IPC Server listener on 8033
2024-02-24 01:01:06,788 INFO org.apache.hadoop.ipc.Server: Stopping IPC Server Responder
2024-02-24 01:01:06,788 INFO org.apache.hadoop.yarn.server.resourcemanager.ResourceManager: Transitioning to standby state
2024-02-24 01:01:06,789 WARN org.apache.hadoop.yarn.server.resourcemanager.amlauncher.ApplicationMasterLauncher: org.apache.hadoop.yarn.server.resourcemanager.amlauncher.ApplicationMasterLauncher$LauncherThread interrupted. Returning.
2024-02-24 01:01:06,789 INFO org.apache.hadoop.ipc.Server: Stopping server on 8030
2024-02-24 01:01:06,789 INFO org.apache.hadoop.ipc.Server: Stopping IPC Server listener on 8030
2024-02-24 01:01:06,790 INFO org.apache.hadoop.ipc.Server: Stopping server on 8031
2024-02-24 01:01:06,791 INFO org.apache.hadoop.yarn.util.AbstractLivelinessMonitor: NMLivelinessMonitor thread interrupted
2024-02-24 01:01:06,791 INFO org.apache.hadoop.ipc.Server: Stopping IPC Server Responder
2024-02-24 01:01:06,791 INFO org.apache.hadoop.ipc.Server: Stopping IPC Server listener on 8031
2024-02-24 01:01:06,791 INFO org.apache.hadoop.ipc.Server: Stopping IPC Server Responder
2024-02-24 01:01:06,791 ERROR org.apache.hadoop.yarn.server.resourcemanager.ResourceManager: Returning, interrupted : java.lang.InterruptedException
2024-02-24 01:01:06,793 INFO org.apache.hadoop.yarn.event.AsyncDispatcher: AsyncDispatcher is draining to stop, igonring any new events.
2024-02-24 01:01:06,793 INFO org.apache.hadoop.yarn.util.AbstractLivelinessMonitor: AMLivelinessMonitor thread interrupted
2024-02-24 01:01:06,794 ERROR org.apache.hadoop.security.token.delegation.AbstractDelegationTokenSecretManager: ExpiredTokenRemover received java.lang.InterruptedException: sleep interrupted
2024-02-24 01:01:06,794 INFO org.apache.hadoop.yarn.util.AbstractLivelinessMonitor: org.apache.hadoop.yarn.server.resourcemanager.rmcontainer.ContainerAllocationExpirer thread interrupted
2024-02-24 01:01:06,793 INFO org.apache.hadoop.yarn.util.AbstractLivelinessMonitor: AMLivelinessMonitor thread interrupted
2024-02-24 01:01:06,799 INFO org.apache.hadoop.metrics2.impl.MetricsSystemImpl: Stopping ResourceManager metrics system...
2024-02-24 01:01:06,800 INFO org.apache.hadoop.metrics2.impl.MetricsSystemImpl: ResourceManager metrics system stopped.
2024-02-24 01:01:06,800 INFO org.apache.hadoop.metrics2.impl.MetricsSystemImpl: ResourceManager metrics system shutdown complete.
2024-02-24 01:01:06,800 INFO org.apache.hadoop.yarn.event.AsyncDispatcher: AsyncDispatcher is draining to stop, igonring any new events.
2024-02-24 01:01:06,801 INFO org.apache.hadoop.yarn.server.resourcemanager.ResourceManager: Transitioned to standby state
2024-02-24 01:01:06,801 INFO org.apache.hadoop.yarn.server.resourcemanager.ResourceManager: SHUTDOWN_MSG: 
/************************************************************
SHUTDOWN_MSG: Shutting down ResourceManager at 5acd4955-724f-452a-817c-900b09ccd050-node1/10.30.6.115
************************************************************/
2024-02-24 01:01:38,828 INFO org.apache.hadoop.yarn.server.resourcemanager.ResourceManager: STARTUP_MSG: 
/************************************************************
STARTUP_MSG: Starting ResourceManager
STARTUP_MSG:   user = ubuntu
STARTUP_MSG:   host = 5acd4955-724f-452a-817c-900b09ccd050-node1/10.30.6.115
STARTUP_MSG:   args = []
STARTUP_MSG:   version = 2.8.1
STARTUP_MSG:   build = https://git-wip-us.apache.org/repos/asf/hadoop.git -r 20fe5304904fc2f5a18053c389e43cd26f7a70fe; compiled by 'vinodkv' on 2017-06-02T06:14Z
STARTUP_MSG:   java = 1.8.0_362
************************************************************/
2024-02-24 01:01:38,834 INFO org.apache.hadoop.yarn.server.resourcemanager.ResourceManager: registered UNIX signal handlers for [TERM, HUP, INT]
2024-02-24 01:01:39,015 INFO org.apache.hadoop.conf.Configuration: found resource core-site.xml at file:/home/ubuntu/bigdata/hadoop-2.8.1/etc/hadoop/core-site.xml
2024-02-24 01:01:39,040 WARN org.apache.hadoop.util.NativeCodeLoader: Unable to load native-hadoop library for your platform... using builtin-java classes where applicable
2024-02-24 01:01:39,056 INFO org.apache.hadoop.security.Groups: clearing userToGroupsMap cache
2024-02-24 01:01:39,096 INFO org.apache.hadoop.conf.Configuration: found resource yarn-site.xml at file:/home/ubuntu/bigdata/hadoop-2.8.1/etc/hadoop/yarn-site.xml
2024-02-24 01:01:39,202 INFO org.apache.hadoop.yarn.event.AsyncDispatcher: Registering class org.apache.hadoop.yarn.server.resourcemanager.RMFatalEventType for class org.apache.hadoop.yarn.server.resourcemanager.ResourceManager$RMFatalEventDispatcher
2024-02-24 01:01:39,230 INFO org.apache.hadoop.yarn.server.resourcemanager.security.NMTokenSecretManagerInRM: NMTokenKeyRollingInterval: 86400000ms and NMTokenKeyActivationDelay: 900000ms
2024-02-24 01:01:39,233 INFO org.apache.hadoop.yarn.server.resourcemanager.security.RMContainerTokenSecretManager: ContainerTokenKeyRollingInterval: 86400000ms and ContainerTokenKeyActivationDelay: 900000ms
2024-02-24 01:01:39,235 INFO org.apache.hadoop.yarn.server.resourcemanager.security.AMRMTokenSecretManager: AMRMTokenKeyRollingInterval: 86400000ms and AMRMTokenKeyActivationDelay: 900000 ms
2024-02-24 01:01:39,254 INFO org.apache.hadoop.yarn.event.AsyncDispatcher: Registering class org.apache.hadoop.yarn.server.resourcemanager.recovery.RMStateStoreEventType for class org.apache.hadoop.yarn.server.resourcemanager.recovery.RMStateStore$ForwardingEventHandler
2024-02-24 01:01:39,255 INFO org.apache.hadoop.yarn.event.AsyncDispatcher: Registering class org.apache.hadoop.yarn.server.resourcemanager.NodesListManagerEventType for class org.apache.hadoop.yarn.server.resourcemanager.NodesListManager
2024-02-24 01:01:39,255 INFO org.apache.hadoop.yarn.server.resourcemanager.ResourceManager: Using Scheduler: org.apache.hadoop.yarn.server.resourcemanager.scheduler.capacity.CapacityScheduler
2024-02-24 01:01:39,268 INFO org.apache.hadoop.yarn.event.AsyncDispatcher: Registering class org.apache.hadoop.yarn.server.resourcemanager.scheduler.event.SchedulerEventType for class org.apache.hadoop.yarn.server.resourcemanager.ResourceManager$SchedulerEventDispatcher
2024-02-24 01:01:39,269 INFO org.apache.hadoop.yarn.event.AsyncDispatcher: Registering class org.apache.hadoop.yarn.server.resourcemanager.rmapp.RMAppEventType for class org.apache.hadoop.yarn.server.resourcemanager.ResourceManager$ApplicationEventDispatcher
2024-02-24 01:01:39,269 INFO org.apache.hadoop.yarn.event.AsyncDispatcher: Registering class org.apache.hadoop.yarn.server.resourcemanager.rmapp.attempt.RMAppAttemptEventType for class org.apache.hadoop.yarn.server.resourcemanager.ResourceManager$ApplicationAttemptEventDispatcher
2024-02-24 01:01:39,270 INFO org.apache.hadoop.yarn.event.AsyncDispatcher: Registering class org.apache.hadoop.yarn.server.resourcemanager.rmnode.RMNodeEventType for class org.apache.hadoop.yarn.server.resourcemanager.ResourceManager$NodeEventDispatcher
2024-02-24 01:01:39,297 INFO org.apache.hadoop.metrics2.impl.MetricsConfig: loaded properties from hadoop-metrics2.properties
2024-02-24 01:01:39,349 INFO org.apache.hadoop.metrics2.impl.MetricsSystemImpl: Scheduled Metric snapshot period at 10 second(s).
2024-02-24 01:01:39,349 INFO org.apache.hadoop.metrics2.impl.MetricsSystemImpl: ResourceManager metrics system started
2024-02-24 01:01:39,357 INFO org.apache.hadoop.yarn.event.AsyncDispatcher: Registering class org.apache.hadoop.yarn.server.resourcemanager.RMAppManagerEventType for class org.apache.hadoop.yarn.server.resourcemanager.RMAppManager
2024-02-24 01:01:39,361 INFO org.apache.hadoop.yarn.event.AsyncDispatcher: Registering class org.apache.hadoop.yarn.server.resourcemanager.amlauncher.AMLauncherEventType for class org.apache.hadoop.yarn.server.resourcemanager.amlauncher.ApplicationMasterLauncher
2024-02-24 01:01:39,362 INFO org.apache.hadoop.yarn.server.resourcemanager.RMNMInfo: Registered RMNMInfo MBean
2024-02-24 01:01:39,366 INFO org.apache.hadoop.yarn.security.YarnAuthorizationProvider: org.apache.hadoop.yarn.security.ConfiguredYarnAuthorizer is instiantiated.
2024-02-24 01:01:39,367 INFO org.apache.hadoop.util.HostsFileReader: Refreshing hosts (include/exclude) list
2024-02-24 01:01:39,370 INFO org.apache.hadoop.conf.Configuration: found resource capacity-scheduler.xml at file:/home/ubuntu/bigdata/hadoop-2.8.1/etc/hadoop/capacity-scheduler.xml
2024-02-24 01:01:39,401 INFO org.apache.hadoop.yarn.server.resourcemanager.scheduler.capacity.CapacitySchedulerConfiguration: max alloc mb per queue for root is undefined
2024-02-24 01:01:39,401 INFO org.apache.hadoop.yarn.server.resourcemanager.scheduler.capacity.CapacitySchedulerConfiguration: max alloc vcore per queue for root is undefined
2024-02-24 01:01:39,409 INFO org.apache.hadoop.yarn.server.resourcemanager.scheduler.capacity.ParentQueue: root, capacity=1.0, asboluteCapacity=1.0, maxCapacity=1.0, asboluteMaxCapacity=1.0, state=RUNNING, acls=ADMINISTER_QUEUE:*SUBMIT_APP:*, labels=*,, offswitchPerHeartbeatLimit = 1, reservationsContinueLooking=true
2024-02-24 01:01:39,409 INFO org.apache.hadoop.yarn.server.resourcemanager.scheduler.capacity.ParentQueue: Initialized parent-queue root name=root, fullname=root
2024-02-24 01:01:39,416 INFO org.apache.hadoop.yarn.server.resourcemanager.scheduler.capacity.CapacitySchedulerConfiguration: max alloc mb per queue for root.default is undefined
2024-02-24 01:01:39,416 INFO org.apache.hadoop.yarn.server.resourcemanager.scheduler.capacity.CapacitySchedulerConfiguration: max alloc vcore per queue for root.default is undefined
2024-02-24 01:01:39,418 INFO org.apache.hadoop.yarn.server.resourcemanager.scheduler.capacity.LeafQueue: Initializing default
capacity = 1.0 [= (float) configuredCapacity / 100 ]
asboluteCapacity = 1.0 [= parentAbsoluteCapacity * capacity ]
maxCapacity = 1.0 [= configuredMaxCapacity ]
absoluteMaxCapacity = 1.0 [= 1.0 maximumCapacity undefined, (parentAbsoluteMaxCapacity * maximumCapacity) / 100 otherwise ]
userLimit = 100 [= configuredUserLimit ]
userLimitFactor = 1.0 [= configuredUserLimitFactor ]
maxApplications = 10000 [= configuredMaximumSystemApplicationsPerQueue or (int)(configuredMaximumSystemApplications * absoluteCapacity)]
maxApplicationsPerUser = 10000 [= (int)(maxApplications * (userLimit / 100.0f) * userLimitFactor) ]
usedCapacity = 0.0 [= usedResourcesMemory / (clusterResourceMemory * absoluteCapacity)]
absoluteUsedCapacity = 0.0 [= usedResourcesMemory / clusterResourceMemory]
maxAMResourcePerQueuePercent = 0.1 [= configuredMaximumAMResourcePercent ]
minimumAllocationFactor = 0.875 [= (float)(maximumAllocationMemory - minimumAllocationMemory) / maximumAllocationMemory ]
maximumAllocation = <memory:8192, vCores:4> [= configuredMaxAllocation ]
numContainers = 0 [= currentNumContainers ]
state = RUNNING [= configuredState ]
acls = ADMINISTER_QUEUE:*SUBMIT_APP:* [= configuredAcls ]
nodeLocalityDelay = 40
labels=*,
reservationsContinueLooking = true
preemptionDisabled = true
defaultAppPriorityPerQueue = 0
2024-02-24 01:01:39,418 INFO org.apache.hadoop.yarn.server.resourcemanager.scheduler.capacity.CapacityScheduler: Initialized queue: default: capacity=1.0, absoluteCapacity=1.0, usedResources=<memory:0, vCores:0>, usedCapacity=0.0, absoluteUsedCapacity=0.0, numApps=0, numContainers=0
2024-02-24 01:01:39,418 INFO org.apache.hadoop.yarn.server.resourcemanager.scheduler.capacity.CapacityScheduler: Initialized queue: root: numChildQueue= 1, capacity=1.0, absoluteCapacity=1.0, usedResources=<memory:0, vCores:0>usedCapacity=0.0, numApps=0, numContainers=0
2024-02-24 01:01:39,418 INFO org.apache.hadoop.yarn.server.resourcemanager.scheduler.capacity.CapacityScheduler: Initialized root queue root: numChildQueue= 1, capacity=1.0, absoluteCapacity=1.0, usedResources=<memory:0, vCores:0>usedCapacity=0.0, numApps=0, numContainers=0
2024-02-24 01:01:39,419 INFO org.apache.hadoop.yarn.server.resourcemanager.scheduler.capacity.CapacityScheduler: Initialized queue mappings, override: false
2024-02-24 01:01:39,419 INFO org.apache.hadoop.yarn.server.resourcemanager.scheduler.capacity.CapacityScheduler: Initialized CapacityScheduler with calculator=class org.apache.hadoop.yarn.util.resource.DefaultResourceCalculator, minimumAllocation=<<memory:1024, vCores:1>>, maximumAllocation=<<memory:8192, vCores:4>>, asynchronousScheduling=false, asyncScheduleInterval=5ms
2024-02-24 01:01:39,421 INFO org.apache.hadoop.conf.Configuration: dynamic-resources.xml not found
2024-02-24 01:01:39,436 INFO org.apache.hadoop.yarn.server.resourcemanager.metrics.SystemMetricsPublisher: YARN system metrics publishing service is not enabled
2024-02-24 01:01:39,436 INFO org.apache.hadoop.yarn.server.resourcemanager.ResourceManager: Transitioning to active state
2024-02-24 01:01:39,440 INFO org.apache.hadoop.util.JvmPauseMonitor: Starting JVM pause monitor
2024-02-24 01:01:39,447 INFO org.apache.hadoop.yarn.server.resourcemanager.recovery.RMStateStore: Updating AMRMToken
2024-02-24 01:01:39,447 INFO org.apache.hadoop.yarn.server.resourcemanager.security.RMContainerTokenSecretManager: Rolling master-key for container-tokens
2024-02-24 01:01:39,447 INFO org.apache.hadoop.yarn.server.resourcemanager.security.NMTokenSecretManagerInRM: Rolling master-key for nm-tokens
2024-02-24 01:01:39,447 INFO org.apache.hadoop.security.token.delegation.AbstractDelegationTokenSecretManager: Updating the current master key for generating delegation tokens
2024-02-24 01:01:39,447 INFO org.apache.hadoop.yarn.server.resourcemanager.security.RMDelegationTokenSecretManager: storing master key with keyID 1
2024-02-24 01:01:39,447 INFO org.apache.hadoop.yarn.server.resourcemanager.recovery.RMStateStore: Storing RMDTMasterKey.
2024-02-24 01:01:39,448 INFO org.apache.hadoop.security.token.delegation.AbstractDelegationTokenSecretManager: Starting expired delegation token remover thread, tokenRemoverScanInterval=60 min(s)
2024-02-24 01:01:39,448 INFO org.apache.hadoop.security.token.delegation.AbstractDelegationTokenSecretManager: Updating the current master key for generating delegation tokens
2024-02-24 01:01:39,448 INFO org.apache.hadoop.yarn.server.resourcemanager.security.RMDelegationTokenSecretManager: storing master key with keyID 2
2024-02-24 01:01:39,448 INFO org.apache.hadoop.yarn.server.resourcemanager.recovery.RMStateStore: Storing RMDTMasterKey.
2024-02-24 01:01:39,449 INFO org.apache.hadoop.yarn.event.AsyncDispatcher: Registering class org.apache.hadoop.yarn.nodelabels.event.NodeLabelsStoreEventType for class org.apache.hadoop.yarn.nodelabels.CommonNodeLabelsManager$ForwardingEventHandler
2024-02-24 01:01:39,466 INFO org.apache.hadoop.ipc.CallQueueManager: Using callQueue: class java.util.concurrent.LinkedBlockingQueue queueCapacity: 5000 scheduler: class org.apache.hadoop.ipc.DefaultRpcScheduler
2024-02-24 01:01:39,473 INFO org.apache.hadoop.ipc.Server: Starting Socket Reader #1 for port 8031
2024-02-24 01:01:39,568 INFO org.apache.hadoop.yarn.factories.impl.pb.RpcServerFactoryPBImpl: Adding protocol org.apache.hadoop.yarn.server.api.ResourceTrackerPB to the server
2024-02-24 01:01:39,568 INFO org.apache.hadoop.ipc.Server: IPC Server Responder: starting
2024-02-24 01:01:39,568 INFO org.apache.hadoop.ipc.Server: IPC Server listener on 8031: starting
2024-02-24 01:01:39,586 INFO org.apache.hadoop.ipc.CallQueueManager: Using callQueue: class java.util.concurrent.LinkedBlockingQueue queueCapacity: 5000 scheduler: class org.apache.hadoop.ipc.DefaultRpcScheduler
2024-02-24 01:01:39,590 INFO org.apache.hadoop.ipc.Server: Starting Socket Reader #1 for port 8030
2024-02-24 01:01:39,598 INFO org.apache.hadoop.yarn.factories.impl.pb.RpcServerFactoryPBImpl: Adding protocol org.apache.hadoop.yarn.api.ApplicationMasterProtocolPB to the server
2024-02-24 01:01:39,599 INFO org.apache.hadoop.ipc.Server: IPC Server Responder: starting
2024-02-24 01:01:39,599 INFO org.apache.hadoop.ipc.Server: IPC Server listener on 8030: starting
2024-02-24 01:01:39,645 INFO org.apache.hadoop.ipc.CallQueueManager: Using callQueue: class java.util.concurrent.LinkedBlockingQueue queueCapacity: 5000 scheduler: class org.apache.hadoop.ipc.DefaultRpcScheduler
2024-02-24 01:01:39,648 INFO org.apache.hadoop.ipc.Server: Starting Socket Reader #1 for port 8032
2024-02-24 01:01:39,651 INFO org.apache.hadoop.yarn.factories.impl.pb.RpcServerFactoryPBImpl: Adding protocol org.apache.hadoop.yarn.api.ApplicationClientProtocolPB to the server
2024-02-24 01:01:39,651 INFO org.apache.hadoop.ipc.Server: IPC Server Responder: starting
2024-02-24 01:01:39,651 INFO org.apache.hadoop.ipc.Server: IPC Server listener on 8032: starting
2024-02-24 01:01:39,675 INFO org.apache.hadoop.yarn.server.resourcemanager.ResourceManager: Transitioned to active state
2024-02-24 01:01:39,751 INFO org.mortbay.log: Logging to org.slf4j.impl.Log4jLoggerAdapter(org.mortbay.log) via org.mortbay.log.Slf4jLog
2024-02-24 01:01:39,755 INFO org.apache.hadoop.security.authentication.server.AuthenticationFilter: Unable to initialize FileSignerSecretProvider, falling back to use random secrets.
2024-02-24 01:01:39,758 INFO org.apache.hadoop.http.HttpRequestLog: Http request log for http.requests.resourcemanager is not defined
2024-02-24 01:01:39,763 INFO org.apache.hadoop.http.HttpServer2: Added global filter 'safety' (class=org.apache.hadoop.http.HttpServer2$QuotingInputFilter)
2024-02-24 01:01:39,765 INFO org.apache.hadoop.http.HttpServer2: Added filter RMAuthenticationFilter (class=org.apache.hadoop.yarn.server.security.http.RMAuthenticationFilter) to context cluster
2024-02-24 01:01:39,765 INFO org.apache.hadoop.http.HttpServer2: Added filter RMAuthenticationFilter (class=org.apache.hadoop.yarn.server.security.http.RMAuthenticationFilter) to context static
2024-02-24 01:01:39,765 INFO org.apache.hadoop.http.HttpServer2: Added filter RMAuthenticationFilter (class=org.apache.hadoop.yarn.server.security.http.RMAuthenticationFilter) to context logs
2024-02-24 01:01:39,765 INFO org.apache.hadoop.http.HttpServer2: Added filter static_user_filter (class=org.apache.hadoop.http.lib.StaticUserWebFilter$StaticUserFilter) to context cluster
2024-02-24 01:01:39,765 INFO org.apache.hadoop.http.HttpServer2: Added filter static_user_filter (class=org.apache.hadoop.http.lib.StaticUserWebFilter$StaticUserFilter) to context static
2024-02-24 01:01:39,765 INFO org.apache.hadoop.http.HttpServer2: Added filter static_user_filter (class=org.apache.hadoop.http.lib.StaticUserWebFilter$StaticUserFilter) to context logs
2024-02-24 01:01:39,767 INFO org.apache.hadoop.http.HttpServer2: adding path spec: /cluster/*
2024-02-24 01:01:39,767 INFO org.apache.hadoop.http.HttpServer2: adding path spec: /ws/*
2024-02-24 01:01:39,942 INFO org.apache.hadoop.yarn.webapp.WebApps: Registered webapp guice modules
2024-02-24 01:01:39,944 INFO org.apache.hadoop.http.HttpServer2: Jetty bound to port 8088
2024-02-24 01:01:39,944 INFO org.mortbay.log: jetty-6.1.26
2024-02-24 01:01:39,958 INFO org.mortbay.log: Extract jar:file:/home/ubuntu/bigdata/hadoop-2.8.1/share/hadoop/yarn/hadoop-yarn-common-2.8.1.jar!/webapps/cluster to /tmp/Jetty_0_0_0_0_8088_cluster____u0rgz3/webapp
2024-02-24 01:01:40,050 INFO org.apache.hadoop.security.token.delegation.AbstractDelegationTokenSecretManager: Updating the current master key for generating delegation tokens
2024-02-24 01:01:40,050 INFO org.apache.hadoop.security.token.delegation.AbstractDelegationTokenSecretManager: Starting expired delegation token remover thread, tokenRemoverScanInterval=60 min(s)
2024-02-24 01:01:40,050 INFO org.apache.hadoop.security.token.delegation.AbstractDelegationTokenSecretManager: Updating the current master key for generating delegation tokens
2024-02-24 01:01:40,516 INFO org.mortbay.log: Started HttpServer2$SelectChannelConnectorWithSafeStartup@0.0.0.0:8088
2024-02-24 01:01:40,516 INFO org.apache.hadoop.yarn.webapp.WebApps: Web app cluster started at 8088
2024-02-24 01:01:40,535 INFO org.apache.hadoop.ipc.CallQueueManager: Using callQueue: class java.util.concurrent.LinkedBlockingQueue queueCapacity: 100 scheduler: class org.apache.hadoop.ipc.DefaultRpcScheduler
2024-02-24 01:01:40,567 INFO org.apache.hadoop.ipc.Server: Starting Socket Reader #1 for port 8033
2024-02-24 01:01:40,569 INFO org.apache.hadoop.yarn.factories.impl.pb.RpcServerFactoryPBImpl: Adding protocol org.apache.hadoop.yarn.server.api.ResourceManagerAdministrationProtocolPB to the server
2024-02-24 01:01:40,569 INFO org.apache.hadoop.ipc.Server: IPC Server Responder: starting
2024-02-24 01:01:40,570 INFO org.apache.hadoop.ipc.Server: IPC Server listener on 8033: starting
2024-02-24 01:01:42,243 INFO org.apache.hadoop.yarn.server.resourcemanager.ResourceTrackerService: NodeManager from node 5acd4955-724f-452a-817c-900b09ccd050-node1(cmPort: 38895 httpPort: 8042) registered with capability: <memory:8192, vCores:8>, assigned nodeId 5acd4955-724f-452a-817c-900b09ccd050-node1:38895
2024-02-24 01:01:42,244 INFO org.apache.hadoop.yarn.server.resourcemanager.rmnode.RMNodeImpl: 5acd4955-724f-452a-817c-900b09ccd050-node1:38895 Node Transitioned from NEW to RUNNING
2024-02-24 01:01:42,251 INFO org.apache.hadoop.yarn.server.resourcemanager.scheduler.capacity.CapacityScheduler: Added node 5acd4955-724f-452a-817c-900b09ccd050-node1:38895 clusterResource: <memory:8192, vCores:8>
2024-02-24 01:11:39,370 INFO org.apache.hadoop.yarn.server.resourcemanager.scheduler.AbstractYarnScheduler: Release request cache is cleaned up
2024-02-24 01:16:55,309 INFO org.apache.hadoop.yarn.server.resourcemanager.ClientRMService: Allocated new applicationId: 1
2024-02-24 01:16:55,719 INFO org.apache.hadoop.yarn.server.resourcemanager.scheduler.capacity.CapacityScheduler: Application 'application_1708736499436_0001' is submitted without priority hence considering default queue/cluster priority: 0
2024-02-24 01:16:55,719 INFO org.apache.hadoop.yarn.server.resourcemanager.scheduler.capacity.CapacityScheduler: Priority '0' is acceptable in queue : default for application: application_1708736499436_0001 for the user: ubuntu
2024-02-24 01:16:55,731 INFO org.apache.hadoop.yarn.server.resourcemanager.ClientRMService: Application with id 1 submitted by user ubuntu
2024-02-24 01:16:55,731 INFO org.apache.hadoop.yarn.server.resourcemanager.rmapp.RMAppImpl: Storing application with id application_1708736499436_0001
2024-02-24 01:16:55,732 INFO org.apache.hadoop.yarn.server.resourcemanager.RMAuditLogger: USER=ubuntu	IP=10.30.6.115	OPERATION=Submit Application Request	TARGET=ClientRMService	RESULT=SUCCESS	APPID=application_1708736499436_0001
2024-02-24 01:16:55,737 INFO org.apache.hadoop.yarn.server.resourcemanager.rmapp.RMAppImpl: application_1708736499436_0001 State change from NEW to NEW_SAVING on event=START
2024-02-24 01:16:55,737 INFO org.apache.hadoop.yarn.server.resourcemanager.recovery.RMStateStore: Storing info for app: application_1708736499436_0001
2024-02-24 01:16:55,737 INFO org.apache.hadoop.yarn.server.resourcemanager.rmapp.RMAppImpl: application_1708736499436_0001 State change from NEW_SAVING to SUBMITTED on event=APP_NEW_SAVED
2024-02-24 01:16:55,738 INFO org.apache.hadoop.yarn.server.resourcemanager.scheduler.capacity.ParentQueue: Application added - appId: application_1708736499436_0001 user: ubuntu leaf-queue of parent: root #applications: 1
2024-02-24 01:16:55,738 INFO org.apache.hadoop.yarn.server.resourcemanager.scheduler.capacity.CapacityScheduler: Accepted application application_1708736499436_0001 from user: ubuntu, in queue: default
2024-02-24 01:16:55,748 INFO org.apache.hadoop.yarn.server.resourcemanager.rmapp.RMAppImpl: application_1708736499436_0001 State change from SUBMITTED to ACCEPTED on event=APP_ACCEPTED
2024-02-24 01:16:55,799 INFO org.apache.hadoop.yarn.server.resourcemanager.ApplicationMasterService: Registering app attempt : appattempt_1708736499436_0001_000001
2024-02-24 01:16:55,800 INFO org.apache.hadoop.yarn.server.resourcemanager.rmapp.attempt.RMAppAttemptImpl: appattempt_1708736499436_0001_000001 State change from NEW to SUBMITTED
2024-02-24 01:16:55,813 WARN org.apache.hadoop.yarn.server.resourcemanager.scheduler.capacity.LeafQueue: maximum-am-resource-percent is insufficient to start a single application in queue, it is likely set too low. skipping enforcement to allow at least one application to start
2024-02-24 01:16:55,813 WARN org.apache.hadoop.yarn.server.resourcemanager.scheduler.capacity.LeafQueue: maximum-am-resource-percent is insufficient to start a single application in queue for user, it is likely set too low. skipping enforcement to allow at least one application to start
2024-02-24 01:16:55,814 INFO org.apache.hadoop.yarn.server.resourcemanager.scheduler.capacity.LeafQueue: Application application_1708736499436_0001 from user: ubuntu activated in queue: default
2024-02-24 01:16:55,815 INFO org.apache.hadoop.yarn.server.resourcemanager.scheduler.capacity.LeafQueue: Application added - appId: application_1708736499436_0001 user: ubuntu, leaf-queue: default #user-pending-applications: 0 #user-active-applications: 1 #queue-pending-applications: 0 #queue-active-applications: 1
2024-02-24 01:16:55,820 INFO org.apache.hadoop.yarn.server.resourcemanager.scheduler.capacity.CapacityScheduler: Added Application Attempt appattempt_1708736499436_0001_000001 to scheduler from user ubuntu in queue default
2024-02-24 01:16:55,821 INFO org.apache.hadoop.yarn.server.resourcemanager.rmapp.attempt.RMAppAttemptImpl: appattempt_1708736499436_0001_000001 State change from SUBMITTED to SCHEDULED
2024-02-24 01:16:56,197 INFO org.apache.hadoop.yarn.server.resourcemanager.rmcontainer.RMContainerImpl: container_1708736499436_0001_01_000001 Container Transitioned from NEW to ALLOCATED
2024-02-24 01:16:56,197 INFO org.apache.hadoop.yarn.server.resourcemanager.RMAuditLogger: USER=ubuntu	OPERATION=AM Allocated Container	TARGET=SchedulerApp	RESULT=SUCCESS	APPID=application_1708736499436_0001	CONTAINERID=container_1708736499436_0001_01_000001
2024-02-24 01:16:56,198 INFO org.apache.hadoop.yarn.server.resourcemanager.scheduler.SchedulerNode: Assigned container container_1708736499436_0001_01_000001 of capacity <memory:2048, vCores:1> on host 5acd4955-724f-452a-817c-900b09ccd050-node1:38895, which has 1 containers, <memory:2048, vCores:1> used and <memory:6144, vCores:7> available after allocation
2024-02-24 01:16:56,198 INFO org.apache.hadoop.yarn.server.resourcemanager.scheduler.capacity.allocator.AbstractContainerAllocator: assignedContainer application attempt=appattempt_1708736499436_0001_000001 container=container_1708736499436_0001_01_000001 queue=org.apache.hadoop.yarn.server.resourcemanager.scheduler.capacity.allocator.RegularContainerAllocator@3569268 clusterResource=<memory:8192, vCores:8> type=OFF_SWITCH
2024-02-24 01:16:56,212 INFO org.apache.hadoop.yarn.server.resourcemanager.security.NMTokenSecretManagerInRM: Sending NMToken for nodeId : 5acd4955-724f-452a-817c-900b09ccd050-node1:38895 for container : container_1708736499436_0001_01_000001
2024-02-24 01:16:56,219 INFO org.apache.hadoop.yarn.server.resourcemanager.rmcontainer.RMContainerImpl: container_1708736499436_0001_01_000001 Container Transitioned from ALLOCATED to ACQUIRED
2024-02-24 01:16:56,219 INFO org.apache.hadoop.yarn.server.resourcemanager.security.NMTokenSecretManagerInRM: Clear node set for appattempt_1708736499436_0001_000001
2024-02-24 01:16:56,219 INFO org.apache.hadoop.yarn.server.resourcemanager.rmapp.attempt.RMAppAttemptImpl: Storing attempt: AppId: application_1708736499436_0001 AttemptId: appattempt_1708736499436_0001_000001 MasterContainer: Container: [ContainerId: container_1708736499436_0001_01_000001, Version: 0, NodeId: 5acd4955-724f-452a-817c-900b09ccd050-node1:38895, NodeHttpAddress: 5acd4955-724f-452a-817c-900b09ccd050-node1:8042, Resource: <memory:2048, vCores:1>, Priority: 0, Token: Token { kind: ContainerToken, service: 10.30.6.115:38895 }, ]
2024-02-24 01:16:56,223 INFO org.apache.hadoop.yarn.server.resourcemanager.scheduler.capacity.ParentQueue: Re-sorting assigned queue: root.default stats: default: capacity=1.0, absoluteCapacity=1.0, usedResources=<memory:2048, vCores:1>, usedCapacity=0.25, absoluteUsedCapacity=0.25, numApps=1, numContainers=1
2024-02-24 01:16:56,225 INFO org.apache.hadoop.yarn.server.resourcemanager.scheduler.capacity.ParentQueue: assignedContainer queue=root usedCapacity=0.25 absoluteUsedCapacity=0.25 used=<memory:2048, vCores:1> cluster=<memory:8192, vCores:8>
2024-02-24 01:16:56,226 INFO org.apache.hadoop.yarn.server.resourcemanager.rmapp.attempt.RMAppAttemptImpl: appattempt_1708736499436_0001_000001 State change from SCHEDULED to ALLOCATED_SAVING
2024-02-24 01:16:56,229 INFO org.apache.hadoop.yarn.server.resourcemanager.rmapp.attempt.RMAppAttemptImpl: appattempt_1708736499436_0001_000001 State change from ALLOCATED_SAVING to ALLOCATED
2024-02-24 01:16:56,231 INFO org.apache.hadoop.yarn.server.resourcemanager.amlauncher.AMLauncher: Launching masterappattempt_1708736499436_0001_000001
2024-02-24 01:16:56,255 INFO org.apache.hadoop.yarn.server.resourcemanager.amlauncher.AMLauncher: Setting up container Container: [ContainerId: container_1708736499436_0001_01_000001, Version: 0, NodeId: 5acd4955-724f-452a-817c-900b09ccd050-node1:38895, NodeHttpAddress: 5acd4955-724f-452a-817c-900b09ccd050-node1:8042, Resource: <memory:2048, vCores:1>, Priority: 0, Token: Token { kind: ContainerToken, service: 10.30.6.115:38895 }, ] for AM appattempt_1708736499436_0001_000001
2024-02-24 01:16:56,255 INFO org.apache.hadoop.yarn.server.resourcemanager.security.AMRMTokenSecretManager: Create AMRMToken for ApplicationAttempt: appattempt_1708736499436_0001_000001
2024-02-24 01:16:56,257 INFO org.apache.hadoop.yarn.server.resourcemanager.security.AMRMTokenSecretManager: Creating password for appattempt_1708736499436_0001_000001
2024-02-24 01:16:56,443 INFO org.apache.hadoop.yarn.server.resourcemanager.amlauncher.AMLauncher: Done launching container Container: [ContainerId: container_1708736499436_0001_01_000001, Version: 0, NodeId: 5acd4955-724f-452a-817c-900b09ccd050-node1:38895, NodeHttpAddress: 5acd4955-724f-452a-817c-900b09ccd050-node1:8042, Resource: <memory:2048, vCores:1>, Priority: 0, Token: Token { kind: ContainerToken, service: 10.30.6.115:38895 }, ] for AM appattempt_1708736499436_0001_000001
2024-02-24 01:16:56,443 INFO org.apache.hadoop.yarn.server.resourcemanager.rmapp.attempt.RMAppAttemptImpl: appattempt_1708736499436_0001_000001 State change from ALLOCATED to LAUNCHED
2024-02-24 01:16:57,192 INFO org.apache.hadoop.yarn.server.resourcemanager.rmcontainer.RMContainerImpl: container_1708736499436_0001_01_000001 Container Transitioned from ACQUIRED to RUNNING
2024-02-24 01:16:59,441 INFO SecurityLogger.org.apache.hadoop.ipc.Server: Auth successful for appattempt_1708736499436_0001_000001 (auth:SIMPLE)
2024-02-24 01:16:59,446 INFO org.apache.hadoop.yarn.server.resourcemanager.ApplicationMasterService: AM registration appattempt_1708736499436_0001_000001
2024-02-24 01:16:59,446 INFO org.apache.hadoop.yarn.server.resourcemanager.RMAuditLogger: USER=ubuntu	IP=10.30.6.115	OPERATION=Register App Master	TARGET=ApplicationMasterService	RESULT=SUCCESS	APPID=application_1708736499436_0001	APPATTEMPTID=appattempt_1708736499436_0001_000001
2024-02-24 01:16:59,446 INFO org.apache.hadoop.yarn.server.resourcemanager.rmapp.attempt.RMAppAttemptImpl: appattempt_1708736499436_0001_000001 State change from LAUNCHED to RUNNING
2024-02-24 01:16:59,446 INFO org.apache.hadoop.yarn.server.resourcemanager.rmapp.RMAppImpl: application_1708736499436_0001 State change from ACCEPTED to RUNNING on event=ATTEMPT_REGISTERED
2024-02-24 01:17:01,196 INFO org.apache.hadoop.yarn.server.resourcemanager.rmcontainer.RMContainerImpl: container_1708736499436_0001_01_000002 Container Transitioned from NEW to ALLOCATED
2024-02-24 01:17:01,196 INFO org.apache.hadoop.yarn.server.resourcemanager.RMAuditLogger: USER=ubuntu	OPERATION=AM Allocated Container	TARGET=SchedulerApp	RESULT=SUCCESS	APPID=application_1708736499436_0001	CONTAINERID=container_1708736499436_0001_01_000002
2024-02-24 01:17:01,196 INFO org.apache.hadoop.yarn.server.resourcemanager.scheduler.SchedulerNode: Assigned container container_1708736499436_0001_01_000002 of capacity <memory:1024, vCores:1> on host 5acd4955-724f-452a-817c-900b09ccd050-node1:38895, which has 2 containers, <memory:3072, vCores:2> used and <memory:5120, vCores:6> available after allocation
2024-02-24 01:17:01,196 INFO org.apache.hadoop.yarn.server.resourcemanager.scheduler.capacity.allocator.AbstractContainerAllocator: assignedContainer application attempt=appattempt_1708736499436_0001_000001 container=container_1708736499436_0001_01_000002 queue=org.apache.hadoop.yarn.server.resourcemanager.scheduler.capacity.allocator.RegularContainerAllocator@3569268 clusterResource=<memory:8192, vCores:8> type=NODE_LOCAL
2024-02-24 01:17:01,196 INFO org.apache.hadoop.yarn.server.resourcemanager.scheduler.capacity.ParentQueue: Re-sorting assigned queue: root.default stats: default: capacity=1.0, absoluteCapacity=1.0, usedResources=<memory:3072, vCores:2>, usedCapacity=0.375, absoluteUsedCapacity=0.375, numApps=1, numContainers=2
2024-02-24 01:17:01,196 INFO org.apache.hadoop.yarn.server.resourcemanager.scheduler.capacity.ParentQueue: assignedContainer queue=root usedCapacity=0.375 absoluteUsedCapacity=0.375 used=<memory:3072, vCores:2> cluster=<memory:8192, vCores:8>
2024-02-24 01:17:01,484 INFO org.apache.hadoop.yarn.server.resourcemanager.security.NMTokenSecretManagerInRM: Sending NMToken for nodeId : 5acd4955-724f-452a-817c-900b09ccd050-node1:38895 for container : container_1708736499436_0001_01_000002
2024-02-24 01:17:01,485 INFO org.apache.hadoop.yarn.server.resourcemanager.rmcontainer.RMContainerImpl: container_1708736499436_0001_01_000002 Container Transitioned from ALLOCATED to ACQUIRED
2024-02-24 01:17:02,197 INFO org.apache.hadoop.yarn.server.resourcemanager.rmcontainer.RMContainerImpl: container_1708736499436_0001_01_000002 Container Transitioned from ACQUIRED to RUNNING
2024-02-24 01:17:02,494 INFO org.apache.hadoop.yarn.server.resourcemanager.scheduler.AppSchedulingInfo: checking for deactivate of application :application_1708736499436_0001
2024-02-24 01:17:03,663 INFO org.apache.hadoop.yarn.server.resourcemanager.rmcontainer.RMContainerImpl: container_1708736499436_0001_01_000002 Container Transitioned from RUNNING to COMPLETED
2024-02-24 01:17:03,663 INFO org.apache.hadoop.yarn.server.resourcemanager.RMAuditLogger: USER=ubuntu	OPERATION=AM Released Container	TARGET=SchedulerApp	RESULT=SUCCESS	APPID=application_1708736499436_0001	CONTAINERID=container_1708736499436_0001_01_000002
2024-02-24 01:17:03,664 INFO org.apache.hadoop.yarn.server.resourcemanager.scheduler.SchedulerNode: Released container container_1708736499436_0001_01_000002 of capacity <memory:1024, vCores:1> on host 5acd4955-724f-452a-817c-900b09ccd050-node1:38895, which currently has 1 containers, <memory:2048, vCores:1> used and <memory:6144, vCores:7> available, release resources=true
2024-02-24 01:17:04,665 INFO org.apache.hadoop.yarn.server.resourcemanager.rmcontainer.RMContainerImpl: container_1708736499436_0001_01_000003 Container Transitioned from NEW to ALLOCATED
2024-02-24 01:17:04,665 INFO org.apache.hadoop.yarn.server.resourcemanager.RMAuditLogger: USER=ubuntu	OPERATION=AM Allocated Container	TARGET=SchedulerApp	RESULT=SUCCESS	APPID=application_1708736499436_0001	CONTAINERID=container_1708736499436_0001_01_000003
2024-02-24 01:17:04,665 INFO org.apache.hadoop.yarn.server.resourcemanager.scheduler.SchedulerNode: Assigned container container_1708736499436_0001_01_000003 of capacity <memory:1024, vCores:1> on host 5acd4955-724f-452a-817c-900b09ccd050-node1:38895, which has 2 containers, <memory:3072, vCores:2> used and <memory:5120, vCores:6> available after allocation
2024-02-24 01:17:04,665 INFO org.apache.hadoop.yarn.server.resourcemanager.scheduler.capacity.allocator.AbstractContainerAllocator: assignedContainer application attempt=appattempt_1708736499436_0001_000001 container=container_1708736499436_0001_01_000003 queue=org.apache.hadoop.yarn.server.resourcemanager.scheduler.capacity.allocator.RegularContainerAllocator@3569268 clusterResource=<memory:8192, vCores:8> type=OFF_SWITCH
2024-02-24 01:17:04,665 INFO org.apache.hadoop.yarn.server.resourcemanager.scheduler.capacity.ParentQueue: Re-sorting assigned queue: root.default stats: default: capacity=1.0, absoluteCapacity=1.0, usedResources=<memory:3072, vCores:2>, usedCapacity=0.375, absoluteUsedCapacity=0.375, numApps=1, numContainers=2
2024-02-24 01:17:04,665 INFO org.apache.hadoop.yarn.server.resourcemanager.scheduler.capacity.ParentQueue: assignedContainer queue=root usedCapacity=0.375 absoluteUsedCapacity=0.375 used=<memory:3072, vCores:2> cluster=<memory:8192, vCores:8>
2024-02-24 01:17:05,511 INFO org.apache.hadoop.yarn.server.resourcemanager.rmcontainer.RMContainerImpl: container_1708736499436_0001_01_000003 Container Transitioned from ALLOCATED to ACQUIRED
2024-02-24 01:17:05,666 INFO org.apache.hadoop.yarn.server.resourcemanager.rmcontainer.RMContainerImpl: container_1708736499436_0001_01_000003 Container Transitioned from ACQUIRED to RUNNING
2024-02-24 01:17:06,514 INFO org.apache.hadoop.yarn.server.resourcemanager.scheduler.AppSchedulingInfo: checking for deactivate of application :application_1708736499436_0001
2024-02-24 01:17:07,242 INFO org.apache.hadoop.yarn.server.resourcemanager.rmapp.attempt.RMAppAttemptImpl: Updating application attempt appattempt_1708736499436_0001_000001 with final state: FINISHING, and exit status: -1000
2024-02-24 01:17:07,242 INFO org.apache.hadoop.yarn.server.resourcemanager.rmapp.attempt.RMAppAttemptImpl: appattempt_1708736499436_0001_000001 State change from RUNNING to FINAL_SAVING
2024-02-24 01:17:07,242 INFO org.apache.hadoop.yarn.server.resourcemanager.rmapp.RMAppImpl: Updating application application_1708736499436_0001 with final state: FINISHING
2024-02-24 01:17:07,242 INFO org.apache.hadoop.yarn.server.resourcemanager.rmapp.RMAppImpl: application_1708736499436_0001 State change from RUNNING to FINAL_SAVING on event=ATTEMPT_UNREGISTERED
2024-02-24 01:17:07,242 INFO org.apache.hadoop.yarn.server.resourcemanager.recovery.RMStateStore: Updating info for app: application_1708736499436_0001
2024-02-24 01:17:07,243 INFO org.apache.hadoop.yarn.server.resourcemanager.rmapp.attempt.RMAppAttemptImpl: appattempt_1708736499436_0001_000001 State change from FINAL_SAVING to FINISHING
2024-02-24 01:17:07,243 INFO org.apache.hadoop.yarn.server.resourcemanager.rmapp.RMAppImpl: application_1708736499436_0001 State change from FINAL_SAVING to FINISHING on event=APP_UPDATE_SAVED
2024-02-24 01:17:07,255 INFO org.apache.hadoop.yarn.server.resourcemanager.rmcontainer.RMContainerImpl: container_1708736499436_0001_01_000003 Container Transitioned from RUNNING to COMPLETED
2024-02-24 01:17:07,255 INFO org.apache.hadoop.yarn.server.resourcemanager.RMAuditLogger: USER=ubuntu	OPERATION=AM Released Container	TARGET=SchedulerApp	RESULT=SUCCESS	APPID=application_1708736499436_0001	CONTAINERID=container_1708736499436_0001_01_000003
2024-02-24 01:17:07,255 INFO org.apache.hadoop.yarn.server.resourcemanager.scheduler.SchedulerNode: Released container container_1708736499436_0001_01_000003 of capacity <memory:1024, vCores:1> on host 5acd4955-724f-452a-817c-900b09ccd050-node1:38895, which currently has 1 containers, <memory:2048, vCores:1> used and <memory:6144, vCores:7> available, release resources=true
2024-02-24 01:17:08,245 INFO org.apache.hadoop.yarn.server.resourcemanager.ApplicationMasterService: application_1708736499436_0001 unregistered successfully. 
2024-02-24 01:17:13,710 INFO org.apache.hadoop.yarn.server.resourcemanager.rmcontainer.RMContainerImpl: container_1708736499436_0001_01_000001 Container Transitioned from RUNNING to COMPLETED
2024-02-24 01:17:13,710 INFO org.apache.hadoop.yarn.server.resourcemanager.ApplicationMasterService: Unregistering app attempt : appattempt_1708736499436_0001_000001
2024-02-24 01:17:13,710 INFO org.apache.hadoop.yarn.server.resourcemanager.RMAuditLogger: USER=ubuntu	OPERATION=AM Released Container	TARGET=SchedulerApp	RESULT=SUCCESS	APPID=application_1708736499436_0001	CONTAINERID=container_1708736499436_0001_01_000001
2024-02-24 01:17:13,710 INFO org.apache.hadoop.yarn.server.resourcemanager.scheduler.SchedulerNode: Released container container_1708736499436_0001_01_000001 of capacity <memory:2048, vCores:1> on host 5acd4955-724f-452a-817c-900b09ccd050-node1:38895, which currently has 0 containers, <memory:0, vCores:0> used and <memory:8192, vCores:8> available, release resources=true
2024-02-24 01:17:13,711 INFO org.apache.hadoop.yarn.server.resourcemanager.security.AMRMTokenSecretManager: Application finished, removing password for appattempt_1708736499436_0001_000001
2024-02-24 01:17:13,711 INFO org.apache.hadoop.yarn.server.resourcemanager.rmapp.attempt.RMAppAttemptImpl: appattempt_1708736499436_0001_000001 State change from FINISHING to FINISHED
2024-02-24 01:17:13,712 INFO org.apache.hadoop.yarn.server.resourcemanager.rmapp.RMAppImpl: application_1708736499436_0001 State change from FINISHING to FINISHED on event=ATTEMPT_FINISHED
2024-02-24 01:17:13,712 INFO org.apache.hadoop.yarn.server.resourcemanager.scheduler.capacity.CapacityScheduler: Application Attempt appattempt_1708736499436_0001_000001 is done. finalState=FINISHED
2024-02-24 01:17:13,713 INFO org.apache.hadoop.yarn.server.resourcemanager.scheduler.AppSchedulingInfo: Application application_1708736499436_0001 requests cleared
2024-02-24 01:17:13,713 INFO org.apache.hadoop.yarn.server.resourcemanager.RMAuditLogger: USER=ubuntu	OPERATION=Application Finished - Succeeded	TARGET=RMAppManager	RESULT=SUCCESS	APPID=application_1708736499436_0001
2024-02-24 01:17:13,713 INFO org.apache.hadoop.yarn.server.resourcemanager.scheduler.capacity.LeafQueue: Application removed - appId: application_1708736499436_0001 user: ubuntu queue: default #user-pending-applications: 0 #user-active-applications: 0 #queue-pending-applications: 0 #queue-active-applications: 0
2024-02-24 01:17:13,713 INFO org.apache.hadoop.yarn.server.resourcemanager.scheduler.capacity.ParentQueue: Application removed - appId: application_1708736499436_0001 user: ubuntu leaf-queue of parent: root #applications: 0
2024-02-24 01:17:13,713 INFO org.apache.hadoop.yarn.server.resourcemanager.amlauncher.AMLauncher: Cleaning master appattempt_1708736499436_0001_000001
2024-02-24 01:17:13,715 INFO org.apache.hadoop.yarn.server.resourcemanager.RMAppManager$ApplicationSummary: appId=application_1708736499436_0001,name=word count,user=ubuntu,queue=default,state=FINISHED,trackingUrl=http://5acd4955-724f-452a-817c-900b09ccd050-node1:8088/proxy/application_1708736499436_0001/,appMasterHost=5acd4955-724f-452a-817c-900b09ccd050-node1,startTime=1708737415728,finishTime=1708737427242,finalStatus=SUCCEEDED,memorySeconds=41048,vcoreSeconds=21,preemptedMemorySeconds=0,preemptedVcoreSeconds=0,preemptedAMContainers=0,preemptedNonAMContainers=0,preemptedResources=<memory:0\, vCores:0>,applicationType=MAPREDUCE
2024-02-24 01:17:15,713 INFO org.apache.hadoop.yarn.server.resourcemanager.scheduler.AbstractYarnScheduler: Container container_1708736499436_0001_01_000003 completed with event FINISHED, but corresponding RMContainer doesn't exist.
2024-02-24 06:44:44,388 INFO org.apache.hadoop.yarn.server.resourcemanager.ClientRMService: Allocated new applicationId: 2
2024-02-24 06:44:45,535 INFO org.apache.hadoop.yarn.server.resourcemanager.scheduler.capacity.CapacityScheduler: Application 'application_1708736499436_0002' is submitted without priority hence considering default queue/cluster priority: 0
2024-02-24 06:44:45,535 INFO org.apache.hadoop.yarn.server.resourcemanager.scheduler.capacity.CapacityScheduler: Priority '0' is acceptable in queue : default for application: application_1708736499436_0002 for the user: ubuntu
2024-02-24 06:44:45,535 INFO org.apache.hadoop.yarn.server.resourcemanager.ClientRMService: Application with id 2 submitted by user ubuntu
2024-02-24 06:44:45,535 INFO org.apache.hadoop.yarn.server.resourcemanager.RMAuditLogger: USER=ubuntu	IP=10.30.6.115	OPERATION=Submit Application Request	TARGET=ClientRMService	RESULT=SUCCESS	APPID=application_1708736499436_0002
2024-02-24 06:44:45,535 INFO org.apache.hadoop.yarn.server.resourcemanager.rmapp.RMAppImpl: Storing application with id application_1708736499436_0002
2024-02-24 06:44:45,535 INFO org.apache.hadoop.yarn.server.resourcemanager.rmapp.RMAppImpl: application_1708736499436_0002 State change from NEW to NEW_SAVING on event=START
2024-02-24 06:44:45,536 INFO org.apache.hadoop.yarn.server.resourcemanager.recovery.RMStateStore: Storing info for app: application_1708736499436_0002
2024-02-24 06:44:45,536 INFO org.apache.hadoop.yarn.server.resourcemanager.rmapp.RMAppImpl: application_1708736499436_0002 State change from NEW_SAVING to SUBMITTED on event=APP_NEW_SAVED
2024-02-24 06:44:45,537 INFO org.apache.hadoop.yarn.server.resourcemanager.scheduler.capacity.ParentQueue: Application added - appId: application_1708736499436_0002 user: ubuntu leaf-queue of parent: root #applications: 1
2024-02-24 06:44:45,537 INFO org.apache.hadoop.yarn.server.resourcemanager.scheduler.capacity.CapacityScheduler: Accepted application application_1708736499436_0002 from user: ubuntu, in queue: default
2024-02-24 06:44:45,538 INFO org.apache.hadoop.yarn.server.resourcemanager.rmapp.RMAppImpl: application_1708736499436_0002 State change from SUBMITTED to ACCEPTED on event=APP_ACCEPTED
2024-02-24 06:44:45,538 INFO org.apache.hadoop.yarn.server.resourcemanager.ApplicationMasterService: Registering app attempt : appattempt_1708736499436_0002_000001
2024-02-24 06:44:45,538 INFO org.apache.hadoop.yarn.server.resourcemanager.rmapp.attempt.RMAppAttemptImpl: appattempt_1708736499436_0002_000001 State change from NEW to SUBMITTED
2024-02-24 06:44:45,538 WARN org.apache.hadoop.yarn.server.resourcemanager.scheduler.capacity.LeafQueue: maximum-am-resource-percent is insufficient to start a single application in queue, it is likely set too low. skipping enforcement to allow at least one application to start
2024-02-24 06:44:45,538 WARN org.apache.hadoop.yarn.server.resourcemanager.scheduler.capacity.LeafQueue: maximum-am-resource-percent is insufficient to start a single application in queue for user, it is likely set too low. skipping enforcement to allow at least one application to start
2024-02-24 06:44:45,539 INFO org.apache.hadoop.yarn.server.resourcemanager.scheduler.capacity.LeafQueue: Application application_1708736499436_0002 from user: ubuntu activated in queue: default
2024-02-24 06:44:45,539 INFO org.apache.hadoop.yarn.server.resourcemanager.scheduler.capacity.LeafQueue: Application added - appId: application_1708736499436_0002 user: ubuntu, leaf-queue: default #user-pending-applications: 0 #user-active-applications: 1 #queue-pending-applications: 0 #queue-active-applications: 1
2024-02-24 06:44:45,539 INFO org.apache.hadoop.yarn.server.resourcemanager.scheduler.capacity.CapacityScheduler: Added Application Attempt appattempt_1708736499436_0002_000001 to scheduler from user ubuntu in queue default
2024-02-24 06:44:45,539 INFO org.apache.hadoop.yarn.server.resourcemanager.rmapp.attempt.RMAppAttemptImpl: appattempt_1708736499436_0002_000001 State change from SUBMITTED to SCHEDULED
2024-02-24 06:44:46,458 INFO org.apache.hadoop.yarn.server.resourcemanager.rmcontainer.RMContainerImpl: container_1708736499436_0002_01_000001 Container Transitioned from NEW to ALLOCATED
2024-02-24 06:44:46,458 INFO org.apache.hadoop.yarn.server.resourcemanager.RMAuditLogger: USER=ubuntu	OPERATION=AM Allocated Container	TARGET=SchedulerApp	RESULT=SUCCESS	APPID=application_1708736499436_0002	CONTAINERID=container_1708736499436_0002_01_000001
2024-02-24 06:44:46,458 INFO org.apache.hadoop.yarn.server.resourcemanager.scheduler.SchedulerNode: Assigned container container_1708736499436_0002_01_000001 of capacity <memory:2048, vCores:1> on host 5acd4955-724f-452a-817c-900b09ccd050-node1:38895, which has 1 containers, <memory:2048, vCores:1> used and <memory:6144, vCores:7> available after allocation
2024-02-24 06:44:46,458 INFO org.apache.hadoop.yarn.server.resourcemanager.scheduler.capacity.allocator.AbstractContainerAllocator: assignedContainer application attempt=appattempt_1708736499436_0002_000001 container=container_1708736499436_0002_01_000001 queue=org.apache.hadoop.yarn.server.resourcemanager.scheduler.capacity.allocator.RegularContainerAllocator@45ffee80 clusterResource=<memory:8192, vCores:8> type=OFF_SWITCH
2024-02-24 06:44:46,460 INFO org.apache.hadoop.yarn.server.resourcemanager.security.NMTokenSecretManagerInRM: Sending NMToken for nodeId : 5acd4955-724f-452a-817c-900b09ccd050-node1:38895 for container : container_1708736499436_0002_01_000001
2024-02-24 06:44:46,461 INFO org.apache.hadoop.yarn.server.resourcemanager.rmcontainer.RMContainerImpl: container_1708736499436_0002_01_000001 Container Transitioned from ALLOCATED to ACQUIRED
2024-02-24 06:44:46,461 INFO org.apache.hadoop.yarn.server.resourcemanager.security.NMTokenSecretManagerInRM: Clear node set for appattempt_1708736499436_0002_000001
2024-02-24 06:44:46,461 INFO org.apache.hadoop.yarn.server.resourcemanager.rmapp.attempt.RMAppAttemptImpl: Storing attempt: AppId: application_1708736499436_0002 AttemptId: appattempt_1708736499436_0002_000001 MasterContainer: Container: [ContainerId: container_1708736499436_0002_01_000001, Version: 0, NodeId: 5acd4955-724f-452a-817c-900b09ccd050-node1:38895, NodeHttpAddress: 5acd4955-724f-452a-817c-900b09ccd050-node1:8042, Resource: <memory:2048, vCores:1>, Priority: 0, Token: Token { kind: ContainerToken, service: 10.30.6.115:38895 }, ]
2024-02-24 06:44:46,461 INFO org.apache.hadoop.yarn.server.resourcemanager.scheduler.capacity.ParentQueue: Re-sorting assigned queue: root.default stats: default: capacity=1.0, absoluteCapacity=1.0, usedResources=<memory:2048, vCores:1>, usedCapacity=0.25, absoluteUsedCapacity=0.25, numApps=1, numContainers=1
2024-02-24 06:44:46,461 INFO org.apache.hadoop.yarn.server.resourcemanager.rmapp.attempt.RMAppAttemptImpl: appattempt_1708736499436_0002_000001 State change from SCHEDULED to ALLOCATED_SAVING
2024-02-24 06:44:46,461 INFO org.apache.hadoop.yarn.server.resourcemanager.rmapp.attempt.RMAppAttemptImpl: appattempt_1708736499436_0002_000001 State change from ALLOCATED_SAVING to ALLOCATED
2024-02-24 06:44:46,461 INFO org.apache.hadoop.yarn.server.resourcemanager.scheduler.capacity.ParentQueue: assignedContainer queue=root usedCapacity=0.25 absoluteUsedCapacity=0.25 used=<memory:2048, vCores:1> cluster=<memory:8192, vCores:8>
2024-02-24 06:44:46,462 INFO org.apache.hadoop.yarn.server.resourcemanager.amlauncher.AMLauncher: Launching masterappattempt_1708736499436_0002_000001
2024-02-24 06:44:46,464 INFO org.apache.hadoop.yarn.server.resourcemanager.amlauncher.AMLauncher: Setting up container Container: [ContainerId: container_1708736499436_0002_01_000001, Version: 0, NodeId: 5acd4955-724f-452a-817c-900b09ccd050-node1:38895, NodeHttpAddress: 5acd4955-724f-452a-817c-900b09ccd050-node1:8042, Resource: <memory:2048, vCores:1>, Priority: 0, Token: Token { kind: ContainerToken, service: 10.30.6.115:38895 }, ] for AM appattempt_1708736499436_0002_000001
2024-02-24 06:44:46,464 INFO org.apache.hadoop.yarn.server.resourcemanager.security.AMRMTokenSecretManager: Create AMRMToken for ApplicationAttempt: appattempt_1708736499436_0002_000001
2024-02-24 06:44:46,464 INFO org.apache.hadoop.yarn.server.resourcemanager.security.AMRMTokenSecretManager: Creating password for appattempt_1708736499436_0002_000001
2024-02-24 06:44:46,474 INFO org.apache.hadoop.yarn.server.resourcemanager.amlauncher.AMLauncher: Done launching container Container: [ContainerId: container_1708736499436_0002_01_000001, Version: 0, NodeId: 5acd4955-724f-452a-817c-900b09ccd050-node1:38895, NodeHttpAddress: 5acd4955-724f-452a-817c-900b09ccd050-node1:8042, Resource: <memory:2048, vCores:1>, Priority: 0, Token: Token { kind: ContainerToken, service: 10.30.6.115:38895 }, ] for AM appattempt_1708736499436_0002_000001
2024-02-24 06:44:46,474 INFO org.apache.hadoop.yarn.server.resourcemanager.rmapp.attempt.RMAppAttemptImpl: appattempt_1708736499436_0002_000001 State change from ALLOCATED to LAUNCHED
2024-02-24 06:44:47,459 INFO org.apache.hadoop.yarn.server.resourcemanager.rmcontainer.RMContainerImpl: container_1708736499436_0002_01_000001 Container Transitioned from ACQUIRED to RUNNING
2024-02-24 06:44:48,959 INFO SecurityLogger.org.apache.hadoop.ipc.Server: Auth successful for appattempt_1708736499436_0002_000001 (auth:SIMPLE)
2024-02-24 06:44:48,961 INFO org.apache.hadoop.yarn.server.resourcemanager.ApplicationMasterService: AM registration appattempt_1708736499436_0002_000001
2024-02-24 06:44:48,961 INFO org.apache.hadoop.yarn.server.resourcemanager.RMAuditLogger: USER=ubuntu	IP=10.30.6.115	OPERATION=Register App Master	TARGET=ApplicationMasterService	RESULT=SUCCESS	APPID=application_1708736499436_0002	APPATTEMPTID=appattempt_1708736499436_0002_000001
2024-02-24 06:44:48,961 INFO org.apache.hadoop.yarn.server.resourcemanager.rmapp.attempt.RMAppAttemptImpl: appattempt_1708736499436_0002_000001 State change from LAUNCHED to RUNNING
2024-02-24 06:44:48,961 INFO org.apache.hadoop.yarn.server.resourcemanager.rmapp.RMAppImpl: application_1708736499436_0002 State change from ACCEPTED to RUNNING on event=ATTEMPT_REGISTERED
2024-02-24 06:44:50,462 INFO org.apache.hadoop.yarn.server.resourcemanager.rmcontainer.RMContainerImpl: container_1708736499436_0002_01_000002 Container Transitioned from NEW to ALLOCATED
2024-02-24 06:44:50,462 INFO org.apache.hadoop.yarn.server.resourcemanager.RMAuditLogger: USER=ubuntu	OPERATION=AM Allocated Container	TARGET=SchedulerApp	RESULT=SUCCESS	APPID=application_1708736499436_0002	CONTAINERID=container_1708736499436_0002_01_000002
2024-02-24 06:44:50,462 INFO org.apache.hadoop.yarn.server.resourcemanager.scheduler.SchedulerNode: Assigned container container_1708736499436_0002_01_000002 of capacity <memory:1024, vCores:1> on host 5acd4955-724f-452a-817c-900b09ccd050-node1:38895, which has 2 containers, <memory:3072, vCores:2> used and <memory:5120, vCores:6> available after allocation
2024-02-24 06:44:50,462 INFO org.apache.hadoop.yarn.server.resourcemanager.scheduler.capacity.allocator.AbstractContainerAllocator: assignedContainer application attempt=appattempt_1708736499436_0002_000001 container=container_1708736499436_0002_01_000002 queue=org.apache.hadoop.yarn.server.resourcemanager.scheduler.capacity.allocator.RegularContainerAllocator@45ffee80 clusterResource=<memory:8192, vCores:8> type=NODE_LOCAL
2024-02-24 06:44:50,462 INFO org.apache.hadoop.yarn.server.resourcemanager.scheduler.capacity.ParentQueue: Re-sorting assigned queue: root.default stats: default: capacity=1.0, absoluteCapacity=1.0, usedResources=<memory:3072, vCores:2>, usedCapacity=0.375, absoluteUsedCapacity=0.375, numApps=1, numContainers=2
2024-02-24 06:44:50,462 INFO org.apache.hadoop.yarn.server.resourcemanager.scheduler.capacity.ParentQueue: assignedContainer queue=root usedCapacity=0.375 absoluteUsedCapacity=0.375 used=<memory:3072, vCores:2> cluster=<memory:8192, vCores:8>
2024-02-24 06:44:50,462 INFO org.apache.hadoop.yarn.server.resourcemanager.rmcontainer.RMContainerImpl: container_1708736499436_0002_01_000003 Container Transitioned from NEW to ALLOCATED
2024-02-24 06:44:50,463 INFO org.apache.hadoop.yarn.server.resourcemanager.RMAuditLogger: USER=ubuntu	OPERATION=AM Allocated Container	TARGET=SchedulerApp	RESULT=SUCCESS	APPID=application_1708736499436_0002	CONTAINERID=container_1708736499436_0002_01_000003
2024-02-24 06:44:50,463 INFO org.apache.hadoop.yarn.server.resourcemanager.scheduler.SchedulerNode: Assigned container container_1708736499436_0002_01_000003 of capacity <memory:1024, vCores:1> on host 5acd4955-724f-452a-817c-900b09ccd050-node1:38895, which has 3 containers, <memory:4096, vCores:3> used and <memory:4096, vCores:5> available after allocation
2024-02-24 06:44:50,463 INFO org.apache.hadoop.yarn.server.resourcemanager.scheduler.capacity.allocator.AbstractContainerAllocator: assignedContainer application attempt=appattempt_1708736499436_0002_000001 container=container_1708736499436_0002_01_000003 queue=org.apache.hadoop.yarn.server.resourcemanager.scheduler.capacity.allocator.RegularContainerAllocator@45ffee80 clusterResource=<memory:8192, vCores:8> type=NODE_LOCAL
2024-02-24 06:44:50,463 INFO org.apache.hadoop.yarn.server.resourcemanager.scheduler.capacity.ParentQueue: Re-sorting assigned queue: root.default stats: default: capacity=1.0, absoluteCapacity=1.0, usedResources=<memory:4096, vCores:3>, usedCapacity=0.5, absoluteUsedCapacity=0.5, numApps=1, numContainers=3
2024-02-24 06:44:50,463 INFO org.apache.hadoop.yarn.server.resourcemanager.scheduler.capacity.ParentQueue: assignedContainer queue=root usedCapacity=0.5 absoluteUsedCapacity=0.5 used=<memory:4096, vCores:3> cluster=<memory:8192, vCores:8>
2024-02-24 06:44:50,463 INFO org.apache.hadoop.yarn.server.resourcemanager.rmcontainer.RMContainerImpl: container_1708736499436_0002_01_000004 Container Transitioned from NEW to ALLOCATED
2024-02-24 06:44:50,463 INFO org.apache.hadoop.yarn.server.resourcemanager.RMAuditLogger: USER=ubuntu	OPERATION=AM Allocated Container	TARGET=SchedulerApp	RESULT=SUCCESS	APPID=application_1708736499436_0002	CONTAINERID=container_1708736499436_0002_01_000004
2024-02-24 06:44:50,463 INFO org.apache.hadoop.yarn.server.resourcemanager.scheduler.SchedulerNode: Assigned container container_1708736499436_0002_01_000004 of capacity <memory:1024, vCores:1> on host 5acd4955-724f-452a-817c-900b09ccd050-node1:38895, which has 4 containers, <memory:5120, vCores:4> used and <memory:3072, vCores:4> available after allocation
2024-02-24 06:44:50,463 INFO org.apache.hadoop.yarn.server.resourcemanager.scheduler.capacity.allocator.AbstractContainerAllocator: assignedContainer application attempt=appattempt_1708736499436_0002_000001 container=container_1708736499436_0002_01_000004 queue=org.apache.hadoop.yarn.server.resourcemanager.scheduler.capacity.allocator.RegularContainerAllocator@45ffee80 clusterResource=<memory:8192, vCores:8> type=NODE_LOCAL
2024-02-24 06:44:50,463 INFO org.apache.hadoop.yarn.server.resourcemanager.scheduler.capacity.ParentQueue: Re-sorting assigned queue: root.default stats: default: capacity=1.0, absoluteCapacity=1.0, usedResources=<memory:5120, vCores:4>, usedCapacity=0.625, absoluteUsedCapacity=0.625, numApps=1, numContainers=4
2024-02-24 06:44:50,463 INFO org.apache.hadoop.yarn.server.resourcemanager.scheduler.capacity.ParentQueue: assignedContainer queue=root usedCapacity=0.625 absoluteUsedCapacity=0.625 used=<memory:5120, vCores:4> cluster=<memory:8192, vCores:8>
2024-02-24 06:44:50,463 INFO org.apache.hadoop.yarn.server.resourcemanager.rmcontainer.RMContainerImpl: container_1708736499436_0002_01_000005 Container Transitioned from NEW to ALLOCATED
2024-02-24 06:44:50,463 INFO org.apache.hadoop.yarn.server.resourcemanager.RMAuditLogger: USER=ubuntu	OPERATION=AM Allocated Container	TARGET=SchedulerApp	RESULT=SUCCESS	APPID=application_1708736499436_0002	CONTAINERID=container_1708736499436_0002_01_000005
2024-02-24 06:44:50,463 INFO org.apache.hadoop.yarn.server.resourcemanager.scheduler.SchedulerNode: Assigned container container_1708736499436_0002_01_000005 of capacity <memory:1024, vCores:1> on host 5acd4955-724f-452a-817c-900b09ccd050-node1:38895, which has 5 containers, <memory:6144, vCores:5> used and <memory:2048, vCores:3> available after allocation
2024-02-24 06:44:50,463 INFO org.apache.hadoop.yarn.server.resourcemanager.scheduler.capacity.allocator.AbstractContainerAllocator: assignedContainer application attempt=appattempt_1708736499436_0002_000001 container=container_1708736499436_0002_01_000005 queue=org.apache.hadoop.yarn.server.resourcemanager.scheduler.capacity.allocator.RegularContainerAllocator@45ffee80 clusterResource=<memory:8192, vCores:8> type=NODE_LOCAL
2024-02-24 06:44:50,464 INFO org.apache.hadoop.yarn.server.resourcemanager.scheduler.capacity.ParentQueue: Re-sorting assigned queue: root.default stats: default: capacity=1.0, absoluteCapacity=1.0, usedResources=<memory:6144, vCores:5>, usedCapacity=0.75, absoluteUsedCapacity=0.75, numApps=1, numContainers=5
2024-02-24 06:44:50,464 INFO org.apache.hadoop.yarn.server.resourcemanager.scheduler.capacity.ParentQueue: assignedContainer queue=root usedCapacity=0.75 absoluteUsedCapacity=0.75 used=<memory:6144, vCores:5> cluster=<memory:8192, vCores:8>
2024-02-24 06:44:50,464 INFO org.apache.hadoop.yarn.server.resourcemanager.rmcontainer.RMContainerImpl: container_1708736499436_0002_01_000006 Container Transitioned from NEW to ALLOCATED
2024-02-24 06:44:50,464 INFO org.apache.hadoop.yarn.server.resourcemanager.RMAuditLogger: USER=ubuntu	OPERATION=AM Allocated Container	TARGET=SchedulerApp	RESULT=SUCCESS	APPID=application_1708736499436_0002	CONTAINERID=container_1708736499436_0002_01_000006
2024-02-24 06:44:50,464 INFO org.apache.hadoop.yarn.server.resourcemanager.scheduler.SchedulerNode: Assigned container container_1708736499436_0002_01_000006 of capacity <memory:1024, vCores:1> on host 5acd4955-724f-452a-817c-900b09ccd050-node1:38895, which has 6 containers, <memory:7168, vCores:6> used and <memory:1024, vCores:2> available after allocation
2024-02-24 06:44:50,464 INFO org.apache.hadoop.yarn.server.resourcemanager.scheduler.capacity.allocator.AbstractContainerAllocator: assignedContainer application attempt=appattempt_1708736499436_0002_000001 container=container_1708736499436_0002_01_000006 queue=org.apache.hadoop.yarn.server.resourcemanager.scheduler.capacity.allocator.RegularContainerAllocator@45ffee80 clusterResource=<memory:8192, vCores:8> type=NODE_LOCAL
2024-02-24 06:44:50,464 INFO org.apache.hadoop.yarn.server.resourcemanager.scheduler.capacity.ParentQueue: Re-sorting assigned queue: root.default stats: default: capacity=1.0, absoluteCapacity=1.0, usedResources=<memory:7168, vCores:6>, usedCapacity=0.875, absoluteUsedCapacity=0.875, numApps=1, numContainers=6
2024-02-24 06:44:50,464 INFO org.apache.hadoop.yarn.server.resourcemanager.scheduler.capacity.ParentQueue: assignedContainer queue=root usedCapacity=0.875 absoluteUsedCapacity=0.875 used=<memory:7168, vCores:6> cluster=<memory:8192, vCores:8>
2024-02-24 06:44:50,464 INFO org.apache.hadoop.yarn.server.resourcemanager.rmcontainer.RMContainerImpl: container_1708736499436_0002_01_000007 Container Transitioned from NEW to ALLOCATED
2024-02-24 06:44:50,464 INFO org.apache.hadoop.yarn.server.resourcemanager.RMAuditLogger: USER=ubuntu	OPERATION=AM Allocated Container	TARGET=SchedulerApp	RESULT=SUCCESS	APPID=application_1708736499436_0002	CONTAINERID=container_1708736499436_0002_01_000007
2024-02-24 06:44:50,464 INFO org.apache.hadoop.yarn.server.resourcemanager.scheduler.SchedulerNode: Assigned container container_1708736499436_0002_01_000007 of capacity <memory:1024, vCores:1> on host 5acd4955-724f-452a-817c-900b09ccd050-node1:38895, which has 7 containers, <memory:8192, vCores:7> used and <memory:0, vCores:1> available after allocation
2024-02-24 06:44:50,464 INFO org.apache.hadoop.yarn.server.resourcemanager.scheduler.capacity.allocator.AbstractContainerAllocator: assignedContainer application attempt=appattempt_1708736499436_0002_000001 container=container_1708736499436_0002_01_000007 queue=org.apache.hadoop.yarn.server.resourcemanager.scheduler.capacity.allocator.RegularContainerAllocator@45ffee80 clusterResource=<memory:8192, vCores:8> type=NODE_LOCAL
2024-02-24 06:44:50,465 INFO org.apache.hadoop.yarn.server.resourcemanager.scheduler.capacity.ParentQueue: Re-sorting assigned queue: root.default stats: default: capacity=1.0, absoluteCapacity=1.0, usedResources=<memory:8192, vCores:7>, usedCapacity=1.0, absoluteUsedCapacity=1.0, numApps=1, numContainers=7
2024-02-24 06:44:50,465 INFO org.apache.hadoop.yarn.server.resourcemanager.scheduler.capacity.ParentQueue: assignedContainer queue=root usedCapacity=1.0 absoluteUsedCapacity=1.0 used=<memory:8192, vCores:7> cluster=<memory:8192, vCores:8>
2024-02-24 06:44:50,993 INFO org.apache.hadoop.yarn.server.resourcemanager.security.NMTokenSecretManagerInRM: Sending NMToken for nodeId : 5acd4955-724f-452a-817c-900b09ccd050-node1:38895 for container : container_1708736499436_0002_01_000002
2024-02-24 06:44:50,993 INFO org.apache.hadoop.yarn.server.resourcemanager.rmcontainer.RMContainerImpl: container_1708736499436_0002_01_000002 Container Transitioned from ALLOCATED to ACQUIRED
2024-02-24 06:44:50,996 INFO org.apache.hadoop.yarn.server.resourcemanager.rmcontainer.RMContainerImpl: container_1708736499436_0002_01_000003 Container Transitioned from ALLOCATED to ACQUIRED
2024-02-24 06:44:50,997 INFO org.apache.hadoop.yarn.server.resourcemanager.rmcontainer.RMContainerImpl: container_1708736499436_0002_01_000004 Container Transitioned from ALLOCATED to ACQUIRED
2024-02-24 06:44:51,002 INFO org.apache.hadoop.yarn.server.resourcemanager.rmcontainer.RMContainerImpl: container_1708736499436_0002_01_000005 Container Transitioned from ALLOCATED to ACQUIRED
2024-02-24 06:44:51,003 INFO org.apache.hadoop.yarn.server.resourcemanager.rmcontainer.RMContainerImpl: container_1708736499436_0002_01_000006 Container Transitioned from ALLOCATED to ACQUIRED
2024-02-24 06:44:51,003 INFO org.apache.hadoop.yarn.server.resourcemanager.rmcontainer.RMContainerImpl: container_1708736499436_0002_01_000007 Container Transitioned from ALLOCATED to ACQUIRED
2024-02-24 06:44:51,463 INFO org.apache.hadoop.yarn.server.resourcemanager.rmcontainer.RMContainerImpl: container_1708736499436_0002_01_000002 Container Transitioned from ACQUIRED to RUNNING
2024-02-24 06:44:51,463 INFO org.apache.hadoop.yarn.server.resourcemanager.rmcontainer.RMContainerImpl: container_1708736499436_0002_01_000003 Container Transitioned from ACQUIRED to RUNNING
2024-02-24 06:44:51,464 INFO org.apache.hadoop.yarn.server.resourcemanager.rmcontainer.RMContainerImpl: container_1708736499436_0002_01_000004 Container Transitioned from ACQUIRED to RUNNING
2024-02-24 06:44:51,464 INFO org.apache.hadoop.yarn.server.resourcemanager.rmcontainer.RMContainerImpl: container_1708736499436_0002_01_000005 Container Transitioned from ACQUIRED to RUNNING
2024-02-24 06:44:51,464 INFO org.apache.hadoop.yarn.server.resourcemanager.rmcontainer.RMContainerImpl: container_1708736499436_0002_01_000006 Container Transitioned from ACQUIRED to RUNNING
2024-02-24 06:44:51,465 INFO org.apache.hadoop.yarn.server.resourcemanager.rmcontainer.RMContainerImpl: container_1708736499436_0002_01_000007 Container Transitioned from ACQUIRED to RUNNING
2024-02-24 06:44:54,745 INFO org.apache.hadoop.yarn.server.resourcemanager.rmcontainer.RMContainerImpl: container_1708736499436_0002_01_000003 Container Transitioned from RUNNING to COMPLETED
2024-02-24 06:44:54,745 INFO org.apache.hadoop.yarn.server.resourcemanager.RMAuditLogger: USER=ubuntu	OPERATION=AM Released Container	TARGET=SchedulerApp	RESULT=SUCCESS	APPID=application_1708736499436_0002	CONTAINERID=container_1708736499436_0002_01_000003
2024-02-24 06:44:54,746 INFO org.apache.hadoop.yarn.server.resourcemanager.scheduler.SchedulerNode: Released container container_1708736499436_0002_01_000003 of capacity <memory:1024, vCores:1> on host 5acd4955-724f-452a-817c-900b09ccd050-node1:38895, which currently has 6 containers, <memory:7168, vCores:6> used and <memory:1024, vCores:2> available, release resources=true
2024-02-24 06:44:54,746 INFO org.apache.hadoop.yarn.server.resourcemanager.rmcontainer.RMContainerImpl: container_1708736499436_0002_01_000008 Container Transitioned from NEW to ALLOCATED
2024-02-24 06:44:54,746 INFO org.apache.hadoop.yarn.server.resourcemanager.RMAuditLogger: USER=ubuntu	OPERATION=AM Allocated Container	TARGET=SchedulerApp	RESULT=SUCCESS	APPID=application_1708736499436_0002	CONTAINERID=container_1708736499436_0002_01_000008
2024-02-24 06:44:54,746 INFO org.apache.hadoop.yarn.server.resourcemanager.scheduler.SchedulerNode: Assigned container container_1708736499436_0002_01_000008 of capacity <memory:1024, vCores:1> on host 5acd4955-724f-452a-817c-900b09ccd050-node1:38895, which has 7 containers, <memory:8192, vCores:7> used and <memory:0, vCores:1> available after allocation
2024-02-24 06:44:54,746 INFO org.apache.hadoop.yarn.server.resourcemanager.scheduler.capacity.allocator.AbstractContainerAllocator: assignedContainer application attempt=appattempt_1708736499436_0002_000001 container=container_1708736499436_0002_01_000008 queue=org.apache.hadoop.yarn.server.resourcemanager.scheduler.capacity.allocator.RegularContainerAllocator@45ffee80 clusterResource=<memory:8192, vCores:8> type=NODE_LOCAL
2024-02-24 06:44:54,746 INFO org.apache.hadoop.yarn.server.resourcemanager.scheduler.capacity.ParentQueue: Re-sorting assigned queue: root.default stats: default: capacity=1.0, absoluteCapacity=1.0, usedResources=<memory:8192, vCores:7>, usedCapacity=1.0, absoluteUsedCapacity=1.0, numApps=1, numContainers=7
2024-02-24 06:44:54,746 INFO org.apache.hadoop.yarn.server.resourcemanager.scheduler.capacity.ParentQueue: assignedContainer queue=root usedCapacity=1.0 absoluteUsedCapacity=1.0 used=<memory:8192, vCores:7> cluster=<memory:8192, vCores:8>
2024-02-24 06:44:54,774 INFO org.apache.hadoop.yarn.server.resourcemanager.rmcontainer.RMContainerImpl: container_1708736499436_0002_01_000005 Container Transitioned from RUNNING to COMPLETED
2024-02-24 06:44:54,774 INFO org.apache.hadoop.yarn.server.resourcemanager.RMAuditLogger: USER=ubuntu	OPERATION=AM Released Container	TARGET=SchedulerApp	RESULT=SUCCESS	APPID=application_1708736499436_0002	CONTAINERID=container_1708736499436_0002_01_000005
2024-02-24 06:44:54,774 INFO org.apache.hadoop.yarn.server.resourcemanager.scheduler.SchedulerNode: Released container container_1708736499436_0002_01_000005 of capacity <memory:1024, vCores:1> on host 5acd4955-724f-452a-817c-900b09ccd050-node1:38895, which currently has 6 containers, <memory:7168, vCores:6> used and <memory:1024, vCores:2> available, release resources=true
2024-02-24 06:44:54,774 INFO org.apache.hadoop.yarn.server.resourcemanager.rmcontainer.RMContainerImpl: container_1708736499436_0002_01_000009 Container Transitioned from NEW to ALLOCATED
2024-02-24 06:44:54,774 INFO org.apache.hadoop.yarn.server.resourcemanager.RMAuditLogger: USER=ubuntu	OPERATION=AM Allocated Container	TARGET=SchedulerApp	RESULT=SUCCESS	APPID=application_1708736499436_0002	CONTAINERID=container_1708736499436_0002_01_000009
2024-02-24 06:44:54,774 INFO org.apache.hadoop.yarn.server.resourcemanager.scheduler.SchedulerNode: Assigned container container_1708736499436_0002_01_000009 of capacity <memory:1024, vCores:1> on host 5acd4955-724f-452a-817c-900b09ccd050-node1:38895, which has 7 containers, <memory:8192, vCores:7> used and <memory:0, vCores:1> available after allocation
2024-02-24 06:44:54,774 INFO org.apache.hadoop.yarn.server.resourcemanager.scheduler.capacity.allocator.AbstractContainerAllocator: assignedContainer application attempt=appattempt_1708736499436_0002_000001 container=container_1708736499436_0002_01_000009 queue=org.apache.hadoop.yarn.server.resourcemanager.scheduler.capacity.allocator.RegularContainerAllocator@45ffee80 clusterResource=<memory:8192, vCores:8> type=NODE_LOCAL
2024-02-24 06:44:54,775 INFO org.apache.hadoop.yarn.server.resourcemanager.scheduler.capacity.ParentQueue: Re-sorting assigned queue: root.default stats: default: capacity=1.0, absoluteCapacity=1.0, usedResources=<memory:8192, vCores:7>, usedCapacity=1.0, absoluteUsedCapacity=1.0, numApps=1, numContainers=7
2024-02-24 06:44:54,775 INFO org.apache.hadoop.yarn.server.resourcemanager.scheduler.capacity.ParentQueue: assignedContainer queue=root usedCapacity=1.0 absoluteUsedCapacity=1.0 used=<memory:8192, vCores:7> cluster=<memory:8192, vCores:8>
2024-02-24 06:44:54,786 INFO org.apache.hadoop.yarn.server.resourcemanager.rmcontainer.RMContainerImpl: container_1708736499436_0002_01_000007 Container Transitioned from RUNNING to COMPLETED
2024-02-24 06:44:54,786 INFO org.apache.hadoop.yarn.server.resourcemanager.RMAuditLogger: USER=ubuntu	OPERATION=AM Released Container	TARGET=SchedulerApp	RESULT=SUCCESS	APPID=application_1708736499436_0002	CONTAINERID=container_1708736499436_0002_01_000007
2024-02-24 06:44:54,787 INFO org.apache.hadoop.yarn.server.resourcemanager.scheduler.SchedulerNode: Released container container_1708736499436_0002_01_000007 of capacity <memory:1024, vCores:1> on host 5acd4955-724f-452a-817c-900b09ccd050-node1:38895, which currently has 6 containers, <memory:7168, vCores:6> used and <memory:1024, vCores:2> available, release resources=true
2024-02-24 06:44:54,896 INFO org.apache.hadoop.yarn.server.resourcemanager.rmcontainer.RMContainerImpl: container_1708736499436_0002_01_000002 Container Transitioned from RUNNING to COMPLETED
2024-02-24 06:44:54,896 INFO org.apache.hadoop.yarn.server.resourcemanager.RMAuditLogger: USER=ubuntu	OPERATION=AM Released Container	TARGET=SchedulerApp	RESULT=SUCCESS	APPID=application_1708736499436_0002	CONTAINERID=container_1708736499436_0002_01_000002
2024-02-24 06:44:54,896 INFO org.apache.hadoop.yarn.server.resourcemanager.scheduler.SchedulerNode: Released container container_1708736499436_0002_01_000002 of capacity <memory:1024, vCores:1> on host 5acd4955-724f-452a-817c-900b09ccd050-node1:38895, which currently has 5 containers, <memory:6144, vCores:5> used and <memory:2048, vCores:3> available, release resources=true
2024-02-24 06:44:54,907 INFO org.apache.hadoop.yarn.server.resourcemanager.rmcontainer.RMContainerImpl: container_1708736499436_0002_01_000004 Container Transitioned from RUNNING to COMPLETED
2024-02-24 06:44:54,907 INFO org.apache.hadoop.yarn.server.resourcemanager.RMAuditLogger: USER=ubuntu	OPERATION=AM Released Container	TARGET=SchedulerApp	RESULT=SUCCESS	APPID=application_1708736499436_0002	CONTAINERID=container_1708736499436_0002_01_000004
2024-02-24 06:44:54,907 INFO org.apache.hadoop.yarn.server.resourcemanager.scheduler.SchedulerNode: Released container container_1708736499436_0002_01_000004 of capacity <memory:1024, vCores:1> on host 5acd4955-724f-452a-817c-900b09ccd050-node1:38895, which currently has 4 containers, <memory:5120, vCores:4> used and <memory:3072, vCores:4> available, release resources=true
2024-02-24 06:44:54,939 INFO org.apache.hadoop.yarn.server.resourcemanager.rmcontainer.RMContainerImpl: container_1708736499436_0002_01_000006 Container Transitioned from RUNNING to COMPLETED
2024-02-24 06:44:54,939 INFO org.apache.hadoop.yarn.server.resourcemanager.RMAuditLogger: USER=ubuntu	OPERATION=AM Released Container	TARGET=SchedulerApp	RESULT=SUCCESS	APPID=application_1708736499436_0002	CONTAINERID=container_1708736499436_0002_01_000006
2024-02-24 06:44:54,939 INFO org.apache.hadoop.yarn.server.resourcemanager.scheduler.SchedulerNode: Released container container_1708736499436_0002_01_000006 of capacity <memory:1024, vCores:1> on host 5acd4955-724f-452a-817c-900b09ccd050-node1:38895, which currently has 3 containers, <memory:4096, vCores:3> used and <memory:4096, vCores:5> available, release resources=true
2024-02-24 06:44:55,031 INFO org.apache.hadoop.yarn.server.resourcemanager.rmcontainer.RMContainerImpl: container_1708736499436_0002_01_000008 Container Transitioned from ALLOCATED to ACQUIRED
2024-02-24 06:44:55,033 INFO org.apache.hadoop.yarn.server.resourcemanager.rmcontainer.RMContainerImpl: container_1708736499436_0002_01_000009 Container Transitioned from ALLOCATED to ACQUIRED
2024-02-24 06:44:55,940 INFO org.apache.hadoop.yarn.server.resourcemanager.rmcontainer.RMContainerImpl: container_1708736499436_0002_01_000008 Container Transitioned from ACQUIRED to RUNNING
2024-02-24 06:44:55,940 INFO org.apache.hadoop.yarn.server.resourcemanager.rmcontainer.RMContainerImpl: container_1708736499436_0002_01_000009 Container Transitioned from ACQUIRED to RUNNING
2024-02-24 06:44:56,040 INFO org.apache.hadoop.yarn.server.resourcemanager.scheduler.AppSchedulingInfo: checking for deactivate of application :application_1708736499436_0002
2024-02-24 06:44:56,942 INFO org.apache.hadoop.yarn.server.resourcemanager.rmcontainer.RMContainerImpl: container_1708736499436_0002_01_000010 Container Transitioned from NEW to ALLOCATED
2024-02-24 06:44:56,942 INFO org.apache.hadoop.yarn.server.resourcemanager.RMAuditLogger: USER=ubuntu	OPERATION=AM Allocated Container	TARGET=SchedulerApp	RESULT=SUCCESS	APPID=application_1708736499436_0002	CONTAINERID=container_1708736499436_0002_01_000010
2024-02-24 06:44:56,942 INFO org.apache.hadoop.yarn.server.resourcemanager.scheduler.SchedulerNode: Assigned container container_1708736499436_0002_01_000010 of capacity <memory:1024, vCores:1> on host 5acd4955-724f-452a-817c-900b09ccd050-node1:38895, which has 4 containers, <memory:5120, vCores:4> used and <memory:3072, vCores:4> available after allocation
2024-02-24 06:44:56,942 INFO org.apache.hadoop.yarn.server.resourcemanager.scheduler.capacity.allocator.AbstractContainerAllocator: assignedContainer application attempt=appattempt_1708736499436_0002_000001 container=container_1708736499436_0002_01_000010 queue=org.apache.hadoop.yarn.server.resourcemanager.scheduler.capacity.allocator.RegularContainerAllocator@45ffee80 clusterResource=<memory:8192, vCores:8> type=OFF_SWITCH
2024-02-24 06:44:56,942 INFO org.apache.hadoop.yarn.server.resourcemanager.scheduler.capacity.ParentQueue: Re-sorting assigned queue: root.default stats: default: capacity=1.0, absoluteCapacity=1.0, usedResources=<memory:5120, vCores:4>, usedCapacity=0.625, absoluteUsedCapacity=0.625, numApps=1, numContainers=4
2024-02-24 06:44:56,942 INFO org.apache.hadoop.yarn.server.resourcemanager.scheduler.capacity.ParentQueue: assignedContainer queue=root usedCapacity=0.625 absoluteUsedCapacity=0.625 used=<memory:5120, vCores:4> cluster=<memory:8192, vCores:8>
2024-02-24 06:44:57,044 INFO org.apache.hadoop.yarn.server.resourcemanager.rmcontainer.RMContainerImpl: container_1708736499436_0002_01_000010 Container Transitioned from ALLOCATED to ACQUIRED
2024-02-24 06:44:57,150 INFO org.apache.hadoop.yarn.server.resourcemanager.rmcontainer.RMContainerImpl: container_1708736499436_0002_01_000010 Container Transitioned from ACQUIRED to RUNNING
2024-02-24 06:44:57,151 INFO org.apache.hadoop.yarn.server.resourcemanager.rmcontainer.RMContainerImpl: container_1708736499436_0002_01_000008 Container Transitioned from RUNNING to COMPLETED
2024-02-24 06:44:57,151 INFO org.apache.hadoop.yarn.server.resourcemanager.RMAuditLogger: USER=ubuntu	OPERATION=AM Released Container	TARGET=SchedulerApp	RESULT=SUCCESS	APPID=application_1708736499436_0002	CONTAINERID=container_1708736499436_0002_01_000008
2024-02-24 06:44:57,151 INFO org.apache.hadoop.yarn.server.resourcemanager.scheduler.SchedulerNode: Released container container_1708736499436_0002_01_000008 of capacity <memory:1024, vCores:1> on host 5acd4955-724f-452a-817c-900b09ccd050-node1:38895, which currently has 3 containers, <memory:4096, vCores:3> used and <memory:4096, vCores:5> available, release resources=true
2024-02-24 06:44:57,269 INFO org.apache.hadoop.yarn.server.resourcemanager.rmcontainer.RMContainerImpl: container_1708736499436_0002_01_000009 Container Transitioned from RUNNING to COMPLETED
2024-02-24 06:44:57,270 INFO org.apache.hadoop.yarn.server.resourcemanager.RMAuditLogger: USER=ubuntu	OPERATION=AM Released Container	TARGET=SchedulerApp	RESULT=SUCCESS	APPID=application_1708736499436_0002	CONTAINERID=container_1708736499436_0002_01_000009
2024-02-24 06:44:57,270 INFO org.apache.hadoop.yarn.server.resourcemanager.scheduler.SchedulerNode: Released container container_1708736499436_0002_01_000009 of capacity <memory:1024, vCores:1> on host 5acd4955-724f-452a-817c-900b09ccd050-node1:38895, which currently has 2 containers, <memory:3072, vCores:2> used and <memory:5120, vCores:6> available, release resources=true
2024-02-24 06:44:58,047 INFO org.apache.hadoop.yarn.server.resourcemanager.scheduler.AppSchedulingInfo: checking for deactivate of application :application_1708736499436_0002
2024-02-24 06:44:59,216 INFO org.apache.hadoop.yarn.server.resourcemanager.rmcontainer.RMContainerImpl: container_1708736499436_0002_01_000010 Container Transitioned from RUNNING to COMPLETED
2024-02-24 06:44:59,216 INFO org.apache.hadoop.yarn.server.resourcemanager.RMAuditLogger: USER=ubuntu	OPERATION=AM Released Container	TARGET=SchedulerApp	RESULT=SUCCESS	APPID=application_1708736499436_0002	CONTAINERID=container_1708736499436_0002_01_000010
2024-02-24 06:44:59,216 INFO org.apache.hadoop.yarn.server.resourcemanager.scheduler.SchedulerNode: Released container container_1708736499436_0002_01_000010 of capacity <memory:1024, vCores:1> on host 5acd4955-724f-452a-817c-900b09ccd050-node1:38895, which currently has 1 containers, <memory:2048, vCores:1> used and <memory:6144, vCores:7> available, release resources=true
2024-02-24 06:44:59,587 INFO org.apache.hadoop.yarn.server.resourcemanager.rmapp.attempt.RMAppAttemptImpl: Updating application attempt appattempt_1708736499436_0002_000001 with final state: FINISHING, and exit status: -1000
2024-02-24 06:44:59,587 INFO org.apache.hadoop.yarn.server.resourcemanager.rmapp.attempt.RMAppAttemptImpl: appattempt_1708736499436_0002_000001 State change from RUNNING to FINAL_SAVING
2024-02-24 06:44:59,587 INFO org.apache.hadoop.yarn.server.resourcemanager.rmapp.RMAppImpl: Updating application application_1708736499436_0002 with final state: FINISHING
2024-02-24 06:44:59,587 INFO org.apache.hadoop.yarn.server.resourcemanager.rmapp.RMAppImpl: application_1708736499436_0002 State change from RUNNING to FINAL_SAVING on event=ATTEMPT_UNREGISTERED
2024-02-24 06:44:59,587 INFO org.apache.hadoop.yarn.server.resourcemanager.recovery.RMStateStore: Updating info for app: application_1708736499436_0002
2024-02-24 06:44:59,587 INFO org.apache.hadoop.yarn.server.resourcemanager.rmapp.attempt.RMAppAttemptImpl: appattempt_1708736499436_0002_000001 State change from FINAL_SAVING to FINISHING
2024-02-24 06:44:59,587 INFO org.apache.hadoop.yarn.server.resourcemanager.rmapp.RMAppImpl: application_1708736499436_0002 State change from FINAL_SAVING to FINISHING on event=APP_UPDATE_SAVED
2024-02-24 06:45:00,587 INFO org.apache.hadoop.yarn.server.resourcemanager.ApplicationMasterService: application_1708736499436_0002 unregistered successfully. 
2024-02-24 06:45:05,943 INFO org.apache.hadoop.yarn.server.resourcemanager.rmcontainer.RMContainerImpl: container_1708736499436_0002_01_000001 Container Transitioned from RUNNING to COMPLETED
2024-02-24 06:45:05,943 INFO org.apache.hadoop.yarn.server.resourcemanager.ApplicationMasterService: Unregistering app attempt : appattempt_1708736499436_0002_000001
2024-02-24 06:45:05,943 INFO org.apache.hadoop.yarn.server.resourcemanager.RMAuditLogger: USER=ubuntu	OPERATION=AM Released Container	TARGET=SchedulerApp	RESULT=SUCCESS	APPID=application_1708736499436_0002	CONTAINERID=container_1708736499436_0002_01_000001
2024-02-24 06:45:05,943 INFO org.apache.hadoop.yarn.server.resourcemanager.security.AMRMTokenSecretManager: Application finished, removing password for appattempt_1708736499436_0002_000001
2024-02-24 06:45:05,943 INFO org.apache.hadoop.yarn.server.resourcemanager.rmapp.attempt.RMAppAttemptImpl: appattempt_1708736499436_0002_000001 State change from FINISHING to FINISHED
2024-02-24 06:45:05,943 INFO org.apache.hadoop.yarn.server.resourcemanager.rmapp.RMAppImpl: application_1708736499436_0002 State change from FINISHING to FINISHED on event=ATTEMPT_FINISHED
2024-02-24 06:45:05,943 INFO org.apache.hadoop.yarn.server.resourcemanager.scheduler.SchedulerNode: Released container container_1708736499436_0002_01_000001 of capacity <memory:2048, vCores:1> on host 5acd4955-724f-452a-817c-900b09ccd050-node1:38895, which currently has 0 containers, <memory:0, vCores:0> used and <memory:8192, vCores:8> available, release resources=true
2024-02-24 06:45:05,943 INFO org.apache.hadoop.yarn.server.resourcemanager.RMAuditLogger: USER=ubuntu	OPERATION=Application Finished - Succeeded	TARGET=RMAppManager	RESULT=SUCCESS	APPID=application_1708736499436_0002
2024-02-24 06:45:05,943 INFO org.apache.hadoop.yarn.server.resourcemanager.scheduler.capacity.CapacityScheduler: Application Attempt appattempt_1708736499436_0002_000001 is done. finalState=FINISHED
2024-02-24 06:45:05,943 INFO org.apache.hadoop.yarn.server.resourcemanager.amlauncher.AMLauncher: Cleaning master appattempt_1708736499436_0002_000001
2024-02-24 06:45:05,943 INFO org.apache.hadoop.yarn.server.resourcemanager.RMAppManager$ApplicationSummary: appId=application_1708736499436_0002,name=word count,user=ubuntu,queue=default,state=FINISHED,trackingUrl=http://5acd4955-724f-452a-817c-900b09ccd050-node1:8088/proxy/application_1708736499436_0002/,appMasterHost=5acd4955-724f-452a-817c-900b09ccd050-node1,startTime=1708757085535,finishTime=1708757099587,finalStatus=SUCCEEDED,memorySeconds=74146,vcoreSeconds=49,preemptedMemorySeconds=0,preemptedVcoreSeconds=0,preemptedAMContainers=0,preemptedNonAMContainers=0,preemptedResources=<memory:0\, vCores:0>,applicationType=MAPREDUCE
2024-02-24 06:45:05,950 INFO org.apache.hadoop.yarn.server.resourcemanager.scheduler.AppSchedulingInfo: Application application_1708736499436_0002 requests cleared
2024-02-24 06:45:05,950 INFO org.apache.hadoop.yarn.server.resourcemanager.scheduler.capacity.LeafQueue: Application removed - appId: application_1708736499436_0002 user: ubuntu queue: default #user-pending-applications: 0 #user-active-applications: 0 #queue-pending-applications: 0 #queue-active-applications: 0
2024-02-24 06:45:05,950 INFO org.apache.hadoop.yarn.server.resourcemanager.scheduler.capacity.ParentQueue: Application removed - appId: application_1708736499436_0002 user: ubuntu leaf-queue of parent: root #applications: 0
2024-02-24 06:45:07,944 INFO org.apache.hadoop.yarn.server.resourcemanager.scheduler.AbstractYarnScheduler: Container container_1708736499436_0002_01_000010 completed with event FINISHED, but corresponding RMContainer doesn't exist.
2024-02-24 07:20:14,799 INFO org.apache.hadoop.yarn.server.resourcemanager.ClientRMService: Allocated new applicationId: 3
2024-02-24 07:20:15,129 INFO org.apache.hadoop.yarn.server.resourcemanager.scheduler.capacity.CapacityScheduler: Application 'application_1708736499436_0003' is submitted without priority hence considering default queue/cluster priority: 0
2024-02-24 07:20:15,129 INFO org.apache.hadoop.yarn.server.resourcemanager.scheduler.capacity.CapacityScheduler: Priority '0' is acceptable in queue : default for application: application_1708736499436_0003 for the user: ubuntu
2024-02-24 07:20:15,129 INFO org.apache.hadoop.yarn.server.resourcemanager.ClientRMService: Application with id 3 submitted by user ubuntu
2024-02-24 07:20:15,129 INFO org.apache.hadoop.yarn.server.resourcemanager.RMAuditLogger: USER=ubuntu	IP=10.30.6.115	OPERATION=Submit Application Request	TARGET=ClientRMService	RESULT=SUCCESS	APPID=application_1708736499436_0003
2024-02-24 07:20:15,129 INFO org.apache.hadoop.yarn.server.resourcemanager.rmapp.RMAppImpl: Storing application with id application_1708736499436_0003
2024-02-24 07:20:15,129 INFO org.apache.hadoop.yarn.server.resourcemanager.rmapp.RMAppImpl: application_1708736499436_0003 State change from NEW to NEW_SAVING on event=START
2024-02-24 07:20:15,129 INFO org.apache.hadoop.yarn.server.resourcemanager.recovery.RMStateStore: Storing info for app: application_1708736499436_0003
2024-02-24 07:20:15,130 INFO org.apache.hadoop.yarn.server.resourcemanager.rmapp.RMAppImpl: application_1708736499436_0003 State change from NEW_SAVING to SUBMITTED on event=APP_NEW_SAVED
2024-02-24 07:20:15,130 INFO org.apache.hadoop.yarn.server.resourcemanager.scheduler.capacity.ParentQueue: Application added - appId: application_1708736499436_0003 user: ubuntu leaf-queue of parent: root #applications: 1
2024-02-24 07:20:15,130 INFO org.apache.hadoop.yarn.server.resourcemanager.scheduler.capacity.CapacityScheduler: Accepted application application_1708736499436_0003 from user: ubuntu, in queue: default
2024-02-24 07:20:15,131 INFO org.apache.hadoop.yarn.server.resourcemanager.rmapp.RMAppImpl: application_1708736499436_0003 State change from SUBMITTED to ACCEPTED on event=APP_ACCEPTED
2024-02-24 07:20:15,131 INFO org.apache.hadoop.yarn.server.resourcemanager.ApplicationMasterService: Registering app attempt : appattempt_1708736499436_0003_000001
2024-02-24 07:20:15,139 INFO org.apache.hadoop.yarn.server.resourcemanager.rmapp.attempt.RMAppAttemptImpl: appattempt_1708736499436_0003_000001 State change from NEW to SUBMITTED
2024-02-24 07:20:15,140 WARN org.apache.hadoop.yarn.server.resourcemanager.scheduler.capacity.LeafQueue: maximum-am-resource-percent is insufficient to start a single application in queue, it is likely set too low. skipping enforcement to allow at least one application to start
2024-02-24 07:20:15,140 WARN org.apache.hadoop.yarn.server.resourcemanager.scheduler.capacity.LeafQueue: maximum-am-resource-percent is insufficient to start a single application in queue for user, it is likely set too low. skipping enforcement to allow at least one application to start
2024-02-24 07:20:15,140 INFO org.apache.hadoop.yarn.server.resourcemanager.scheduler.capacity.LeafQueue: Application application_1708736499436_0003 from user: ubuntu activated in queue: default
2024-02-24 07:20:15,140 INFO org.apache.hadoop.yarn.server.resourcemanager.scheduler.capacity.LeafQueue: Application added - appId: application_1708736499436_0003 user: ubuntu, leaf-queue: default #user-pending-applications: 0 #user-active-applications: 1 #queue-pending-applications: 0 #queue-active-applications: 1
2024-02-24 07:20:15,141 INFO org.apache.hadoop.yarn.server.resourcemanager.scheduler.capacity.CapacityScheduler: Added Application Attempt appattempt_1708736499436_0003_000001 to scheduler from user ubuntu in queue default
2024-02-24 07:20:15,141 INFO org.apache.hadoop.yarn.server.resourcemanager.rmapp.attempt.RMAppAttemptImpl: appattempt_1708736499436_0003_000001 State change from SUBMITTED to SCHEDULED
2024-02-24 07:20:15,874 INFO org.apache.hadoop.yarn.server.resourcemanager.rmcontainer.RMContainerImpl: container_1708736499436_0003_01_000001 Container Transitioned from NEW to ALLOCATED
2024-02-24 07:20:15,874 INFO org.apache.hadoop.yarn.server.resourcemanager.RMAuditLogger: USER=ubuntu	OPERATION=AM Allocated Container	TARGET=SchedulerApp	RESULT=SUCCESS	APPID=application_1708736499436_0003	CONTAINERID=container_1708736499436_0003_01_000001
2024-02-24 07:20:15,874 INFO org.apache.hadoop.yarn.server.resourcemanager.scheduler.SchedulerNode: Assigned container container_1708736499436_0003_01_000001 of capacity <memory:2048, vCores:1> on host 5acd4955-724f-452a-817c-900b09ccd050-node1:38895, which has 1 containers, <memory:2048, vCores:1> used and <memory:6144, vCores:7> available after allocation
2024-02-24 07:20:15,874 INFO org.apache.hadoop.yarn.server.resourcemanager.scheduler.capacity.allocator.AbstractContainerAllocator: assignedContainer application attempt=appattempt_1708736499436_0003_000001 container=container_1708736499436_0003_01_000001 queue=org.apache.hadoop.yarn.server.resourcemanager.scheduler.capacity.allocator.RegularContainerAllocator@3ce2b56a clusterResource=<memory:8192, vCores:8> type=OFF_SWITCH
2024-02-24 07:20:15,874 INFO org.apache.hadoop.yarn.server.resourcemanager.scheduler.capacity.ParentQueue: Re-sorting assigned queue: root.default stats: default: capacity=1.0, absoluteCapacity=1.0, usedResources=<memory:2048, vCores:1>, usedCapacity=0.25, absoluteUsedCapacity=0.25, numApps=1, numContainers=1
2024-02-24 07:20:15,875 INFO org.apache.hadoop.yarn.server.resourcemanager.scheduler.capacity.ParentQueue: assignedContainer queue=root usedCapacity=0.25 absoluteUsedCapacity=0.25 used=<memory:2048, vCores:1> cluster=<memory:8192, vCores:8>
2024-02-24 07:20:15,875 INFO org.apache.hadoop.yarn.server.resourcemanager.security.NMTokenSecretManagerInRM: Sending NMToken for nodeId : 5acd4955-724f-452a-817c-900b09ccd050-node1:38895 for container : container_1708736499436_0003_01_000001
2024-02-24 07:20:15,876 INFO org.apache.hadoop.yarn.server.resourcemanager.rmcontainer.RMContainerImpl: container_1708736499436_0003_01_000001 Container Transitioned from ALLOCATED to ACQUIRED
2024-02-24 07:20:15,876 INFO org.apache.hadoop.yarn.server.resourcemanager.security.NMTokenSecretManagerInRM: Clear node set for appattempt_1708736499436_0003_000001
2024-02-24 07:20:15,876 INFO org.apache.hadoop.yarn.server.resourcemanager.rmapp.attempt.RMAppAttemptImpl: Storing attempt: AppId: application_1708736499436_0003 AttemptId: appattempt_1708736499436_0003_000001 MasterContainer: Container: [ContainerId: container_1708736499436_0003_01_000001, Version: 0, NodeId: 5acd4955-724f-452a-817c-900b09ccd050-node1:38895, NodeHttpAddress: 5acd4955-724f-452a-817c-900b09ccd050-node1:8042, Resource: <memory:2048, vCores:1>, Priority: 0, Token: Token { kind: ContainerToken, service: 10.30.6.115:38895 }, ]
2024-02-24 07:20:15,877 INFO org.apache.hadoop.yarn.server.resourcemanager.rmapp.attempt.RMAppAttemptImpl: appattempt_1708736499436_0003_000001 State change from SCHEDULED to ALLOCATED_SAVING
2024-02-24 07:20:15,877 INFO org.apache.hadoop.yarn.server.resourcemanager.rmapp.attempt.RMAppAttemptImpl: appattempt_1708736499436_0003_000001 State change from ALLOCATED_SAVING to ALLOCATED
2024-02-24 07:20:15,878 INFO org.apache.hadoop.yarn.server.resourcemanager.amlauncher.AMLauncher: Launching masterappattempt_1708736499436_0003_000001
2024-02-24 07:20:15,880 INFO org.apache.hadoop.yarn.server.resourcemanager.amlauncher.AMLauncher: Setting up container Container: [ContainerId: container_1708736499436_0003_01_000001, Version: 0, NodeId: 5acd4955-724f-452a-817c-900b09ccd050-node1:38895, NodeHttpAddress: 5acd4955-724f-452a-817c-900b09ccd050-node1:8042, Resource: <memory:2048, vCores:1>, Priority: 0, Token: Token { kind: ContainerToken, service: 10.30.6.115:38895 }, ] for AM appattempt_1708736499436_0003_000001
2024-02-24 07:20:15,880 INFO org.apache.hadoop.yarn.server.resourcemanager.security.AMRMTokenSecretManager: Create AMRMToken for ApplicationAttempt: appattempt_1708736499436_0003_000001
2024-02-24 07:20:15,880 INFO org.apache.hadoop.yarn.server.resourcemanager.security.AMRMTokenSecretManager: Creating password for appattempt_1708736499436_0003_000001
2024-02-24 07:20:15,889 INFO org.apache.hadoop.yarn.server.resourcemanager.amlauncher.AMLauncher: Done launching container Container: [ContainerId: container_1708736499436_0003_01_000001, Version: 0, NodeId: 5acd4955-724f-452a-817c-900b09ccd050-node1:38895, NodeHttpAddress: 5acd4955-724f-452a-817c-900b09ccd050-node1:8042, Resource: <memory:2048, vCores:1>, Priority: 0, Token: Token { kind: ContainerToken, service: 10.30.6.115:38895 }, ] for AM appattempt_1708736499436_0003_000001
2024-02-24 07:20:15,889 INFO org.apache.hadoop.yarn.server.resourcemanager.rmapp.attempt.RMAppAttemptImpl: appattempt_1708736499436_0003_000001 State change from ALLOCATED to LAUNCHED
2024-02-24 07:20:16,875 INFO org.apache.hadoop.yarn.server.resourcemanager.rmcontainer.RMContainerImpl: container_1708736499436_0003_01_000001 Container Transitioned from ACQUIRED to RUNNING
2024-02-24 07:20:18,439 INFO SecurityLogger.org.apache.hadoop.ipc.Server: Auth successful for appattempt_1708736499436_0003_000001 (auth:SIMPLE)
2024-02-24 07:20:18,441 INFO org.apache.hadoop.yarn.server.resourcemanager.ApplicationMasterService: AM registration appattempt_1708736499436_0003_000001
2024-02-24 07:20:18,441 INFO org.apache.hadoop.yarn.server.resourcemanager.RMAuditLogger: USER=ubuntu	IP=10.30.6.115	OPERATION=Register App Master	TARGET=ApplicationMasterService	RESULT=SUCCESS	APPID=application_1708736499436_0003	APPATTEMPTID=appattempt_1708736499436_0003_000001
2024-02-24 07:20:18,441 INFO org.apache.hadoop.yarn.server.resourcemanager.rmapp.attempt.RMAppAttemptImpl: appattempt_1708736499436_0003_000001 State change from LAUNCHED to RUNNING
2024-02-24 07:20:18,442 INFO org.apache.hadoop.yarn.server.resourcemanager.rmapp.RMAppImpl: application_1708736499436_0003 State change from ACCEPTED to RUNNING on event=ATTEMPT_REGISTERED
2024-02-24 07:20:19,877 INFO org.apache.hadoop.yarn.server.resourcemanager.rmcontainer.RMContainerImpl: container_1708736499436_0003_01_000002 Container Transitioned from NEW to ALLOCATED
2024-02-24 07:20:19,877 INFO org.apache.hadoop.yarn.server.resourcemanager.RMAuditLogger: USER=ubuntu	OPERATION=AM Allocated Container	TARGET=SchedulerApp	RESULT=SUCCESS	APPID=application_1708736499436_0003	CONTAINERID=container_1708736499436_0003_01_000002
2024-02-24 07:20:19,877 INFO org.apache.hadoop.yarn.server.resourcemanager.scheduler.SchedulerNode: Assigned container container_1708736499436_0003_01_000002 of capacity <memory:1024, vCores:1> on host 5acd4955-724f-452a-817c-900b09ccd050-node1:38895, which has 2 containers, <memory:3072, vCores:2> used and <memory:5120, vCores:6> available after allocation
2024-02-24 07:20:19,877 INFO org.apache.hadoop.yarn.server.resourcemanager.scheduler.capacity.allocator.AbstractContainerAllocator: assignedContainer application attempt=appattempt_1708736499436_0003_000001 container=container_1708736499436_0003_01_000002 queue=org.apache.hadoop.yarn.server.resourcemanager.scheduler.capacity.allocator.RegularContainerAllocator@3ce2b56a clusterResource=<memory:8192, vCores:8> type=NODE_LOCAL
2024-02-24 07:20:19,877 INFO org.apache.hadoop.yarn.server.resourcemanager.scheduler.capacity.ParentQueue: Re-sorting assigned queue: root.default stats: default: capacity=1.0, absoluteCapacity=1.0, usedResources=<memory:3072, vCores:2>, usedCapacity=0.375, absoluteUsedCapacity=0.375, numApps=1, numContainers=2
2024-02-24 07:20:19,878 INFO org.apache.hadoop.yarn.server.resourcemanager.scheduler.capacity.ParentQueue: assignedContainer queue=root usedCapacity=0.375 absoluteUsedCapacity=0.375 used=<memory:3072, vCores:2> cluster=<memory:8192, vCores:8>
2024-02-24 07:20:19,878 INFO org.apache.hadoop.yarn.server.resourcemanager.rmcontainer.RMContainerImpl: container_1708736499436_0003_01_000003 Container Transitioned from NEW to ALLOCATED
2024-02-24 07:20:19,878 INFO org.apache.hadoop.yarn.server.resourcemanager.RMAuditLogger: USER=ubuntu	OPERATION=AM Allocated Container	TARGET=SchedulerApp	RESULT=SUCCESS	APPID=application_1708736499436_0003	CONTAINERID=container_1708736499436_0003_01_000003
2024-02-24 07:20:19,878 INFO org.apache.hadoop.yarn.server.resourcemanager.scheduler.SchedulerNode: Assigned container container_1708736499436_0003_01_000003 of capacity <memory:1024, vCores:1> on host 5acd4955-724f-452a-817c-900b09ccd050-node1:38895, which has 3 containers, <memory:4096, vCores:3> used and <memory:4096, vCores:5> available after allocation
2024-02-24 07:20:19,878 INFO org.apache.hadoop.yarn.server.resourcemanager.scheduler.capacity.allocator.AbstractContainerAllocator: assignedContainer application attempt=appattempt_1708736499436_0003_000001 container=container_1708736499436_0003_01_000003 queue=org.apache.hadoop.yarn.server.resourcemanager.scheduler.capacity.allocator.RegularContainerAllocator@3ce2b56a clusterResource=<memory:8192, vCores:8> type=NODE_LOCAL
2024-02-24 07:20:19,878 INFO org.apache.hadoop.yarn.server.resourcemanager.scheduler.capacity.ParentQueue: Re-sorting assigned queue: root.default stats: default: capacity=1.0, absoluteCapacity=1.0, usedResources=<memory:4096, vCores:3>, usedCapacity=0.5, absoluteUsedCapacity=0.5, numApps=1, numContainers=3
2024-02-24 07:20:19,878 INFO org.apache.hadoop.yarn.server.resourcemanager.scheduler.capacity.ParentQueue: assignedContainer queue=root usedCapacity=0.5 absoluteUsedCapacity=0.5 used=<memory:4096, vCores:3> cluster=<memory:8192, vCores:8>
2024-02-24 07:20:19,879 INFO org.apache.hadoop.yarn.server.resourcemanager.rmcontainer.RMContainerImpl: container_1708736499436_0003_01_000004 Container Transitioned from NEW to ALLOCATED
2024-02-24 07:20:19,879 INFO org.apache.hadoop.yarn.server.resourcemanager.RMAuditLogger: USER=ubuntu	OPERATION=AM Allocated Container	TARGET=SchedulerApp	RESULT=SUCCESS	APPID=application_1708736499436_0003	CONTAINERID=container_1708736499436_0003_01_000004
2024-02-24 07:20:19,879 INFO org.apache.hadoop.yarn.server.resourcemanager.scheduler.SchedulerNode: Assigned container container_1708736499436_0003_01_000004 of capacity <memory:1024, vCores:1> on host 5acd4955-724f-452a-817c-900b09ccd050-node1:38895, which has 4 containers, <memory:5120, vCores:4> used and <memory:3072, vCores:4> available after allocation
2024-02-24 07:20:19,879 INFO org.apache.hadoop.yarn.server.resourcemanager.scheduler.capacity.allocator.AbstractContainerAllocator: assignedContainer application attempt=appattempt_1708736499436_0003_000001 container=container_1708736499436_0003_01_000004 queue=org.apache.hadoop.yarn.server.resourcemanager.scheduler.capacity.allocator.RegularContainerAllocator@3ce2b56a clusterResource=<memory:8192, vCores:8> type=NODE_LOCAL
2024-02-24 07:20:19,879 INFO org.apache.hadoop.yarn.server.resourcemanager.scheduler.capacity.ParentQueue: Re-sorting assigned queue: root.default stats: default: capacity=1.0, absoluteCapacity=1.0, usedResources=<memory:5120, vCores:4>, usedCapacity=0.625, absoluteUsedCapacity=0.625, numApps=1, numContainers=4
2024-02-24 07:20:19,879 INFO org.apache.hadoop.yarn.server.resourcemanager.scheduler.capacity.ParentQueue: assignedContainer queue=root usedCapacity=0.625 absoluteUsedCapacity=0.625 used=<memory:5120, vCores:4> cluster=<memory:8192, vCores:8>
2024-02-24 07:20:19,879 INFO org.apache.hadoop.yarn.server.resourcemanager.rmcontainer.RMContainerImpl: container_1708736499436_0003_01_000005 Container Transitioned from NEW to ALLOCATED
2024-02-24 07:20:19,879 INFO org.apache.hadoop.yarn.server.resourcemanager.RMAuditLogger: USER=ubuntu	OPERATION=AM Allocated Container	TARGET=SchedulerApp	RESULT=SUCCESS	APPID=application_1708736499436_0003	CONTAINERID=container_1708736499436_0003_01_000005
2024-02-24 07:20:19,879 INFO org.apache.hadoop.yarn.server.resourcemanager.scheduler.SchedulerNode: Assigned container container_1708736499436_0003_01_000005 of capacity <memory:1024, vCores:1> on host 5acd4955-724f-452a-817c-900b09ccd050-node1:38895, which has 5 containers, <memory:6144, vCores:5> used and <memory:2048, vCores:3> available after allocation
2024-02-24 07:20:19,879 INFO org.apache.hadoop.yarn.server.resourcemanager.scheduler.capacity.allocator.AbstractContainerAllocator: assignedContainer application attempt=appattempt_1708736499436_0003_000001 container=container_1708736499436_0003_01_000005 queue=org.apache.hadoop.yarn.server.resourcemanager.scheduler.capacity.allocator.RegularContainerAllocator@3ce2b56a clusterResource=<memory:8192, vCores:8> type=NODE_LOCAL
2024-02-24 07:20:19,879 INFO org.apache.hadoop.yarn.server.resourcemanager.scheduler.capacity.ParentQueue: Re-sorting assigned queue: root.default stats: default: capacity=1.0, absoluteCapacity=1.0, usedResources=<memory:6144, vCores:5>, usedCapacity=0.75, absoluteUsedCapacity=0.75, numApps=1, numContainers=5
2024-02-24 07:20:19,879 INFO org.apache.hadoop.yarn.server.resourcemanager.scheduler.capacity.ParentQueue: assignedContainer queue=root usedCapacity=0.75 absoluteUsedCapacity=0.75 used=<memory:6144, vCores:5> cluster=<memory:8192, vCores:8>
2024-02-24 07:20:19,879 INFO org.apache.hadoop.yarn.server.resourcemanager.rmcontainer.RMContainerImpl: container_1708736499436_0003_01_000006 Container Transitioned from NEW to ALLOCATED
2024-02-24 07:20:19,879 INFO org.apache.hadoop.yarn.server.resourcemanager.RMAuditLogger: USER=ubuntu	OPERATION=AM Allocated Container	TARGET=SchedulerApp	RESULT=SUCCESS	APPID=application_1708736499436_0003	CONTAINERID=container_1708736499436_0003_01_000006
2024-02-24 07:20:19,879 INFO org.apache.hadoop.yarn.server.resourcemanager.scheduler.SchedulerNode: Assigned container container_1708736499436_0003_01_000006 of capacity <memory:1024, vCores:1> on host 5acd4955-724f-452a-817c-900b09ccd050-node1:38895, which has 6 containers, <memory:7168, vCores:6> used and <memory:1024, vCores:2> available after allocation
2024-02-24 07:20:19,879 INFO org.apache.hadoop.yarn.server.resourcemanager.scheduler.capacity.allocator.AbstractContainerAllocator: assignedContainer application attempt=appattempt_1708736499436_0003_000001 container=container_1708736499436_0003_01_000006 queue=org.apache.hadoop.yarn.server.resourcemanager.scheduler.capacity.allocator.RegularContainerAllocator@3ce2b56a clusterResource=<memory:8192, vCores:8> type=NODE_LOCAL
2024-02-24 07:20:19,879 INFO org.apache.hadoop.yarn.server.resourcemanager.scheduler.capacity.ParentQueue: Re-sorting assigned queue: root.default stats: default: capacity=1.0, absoluteCapacity=1.0, usedResources=<memory:7168, vCores:6>, usedCapacity=0.875, absoluteUsedCapacity=0.875, numApps=1, numContainers=6
2024-02-24 07:20:19,879 INFO org.apache.hadoop.yarn.server.resourcemanager.scheduler.capacity.ParentQueue: assignedContainer queue=root usedCapacity=0.875 absoluteUsedCapacity=0.875 used=<memory:7168, vCores:6> cluster=<memory:8192, vCores:8>
2024-02-24 07:20:19,880 INFO org.apache.hadoop.yarn.server.resourcemanager.rmcontainer.RMContainerImpl: container_1708736499436_0003_01_000007 Container Transitioned from NEW to ALLOCATED
2024-02-24 07:20:19,880 INFO org.apache.hadoop.yarn.server.resourcemanager.RMAuditLogger: USER=ubuntu	OPERATION=AM Allocated Container	TARGET=SchedulerApp	RESULT=SUCCESS	APPID=application_1708736499436_0003	CONTAINERID=container_1708736499436_0003_01_000007
2024-02-24 07:20:19,880 INFO org.apache.hadoop.yarn.server.resourcemanager.scheduler.SchedulerNode: Assigned container container_1708736499436_0003_01_000007 of capacity <memory:1024, vCores:1> on host 5acd4955-724f-452a-817c-900b09ccd050-node1:38895, which has 7 containers, <memory:8192, vCores:7> used and <memory:0, vCores:1> available after allocation
2024-02-24 07:20:19,880 INFO org.apache.hadoop.yarn.server.resourcemanager.scheduler.capacity.allocator.AbstractContainerAllocator: assignedContainer application attempt=appattempt_1708736499436_0003_000001 container=container_1708736499436_0003_01_000007 queue=org.apache.hadoop.yarn.server.resourcemanager.scheduler.capacity.allocator.RegularContainerAllocator@3ce2b56a clusterResource=<memory:8192, vCores:8> type=NODE_LOCAL
2024-02-24 07:20:19,880 INFO org.apache.hadoop.yarn.server.resourcemanager.scheduler.capacity.ParentQueue: Re-sorting assigned queue: root.default stats: default: capacity=1.0, absoluteCapacity=1.0, usedResources=<memory:8192, vCores:7>, usedCapacity=1.0, absoluteUsedCapacity=1.0, numApps=1, numContainers=7
2024-02-24 07:20:19,880 INFO org.apache.hadoop.yarn.server.resourcemanager.scheduler.capacity.ParentQueue: assignedContainer queue=root usedCapacity=1.0 absoluteUsedCapacity=1.0 used=<memory:8192, vCores:7> cluster=<memory:8192, vCores:8>
2024-02-24 07:20:20,472 INFO org.apache.hadoop.yarn.server.resourcemanager.security.NMTokenSecretManagerInRM: Sending NMToken for nodeId : 5acd4955-724f-452a-817c-900b09ccd050-node1:38895 for container : container_1708736499436_0003_01_000002
2024-02-24 07:20:20,473 INFO org.apache.hadoop.yarn.server.resourcemanager.rmcontainer.RMContainerImpl: container_1708736499436_0003_01_000002 Container Transitioned from ALLOCATED to ACQUIRED
2024-02-24 07:20:20,473 INFO org.apache.hadoop.yarn.server.resourcemanager.rmcontainer.RMContainerImpl: container_1708736499436_0003_01_000003 Container Transitioned from ALLOCATED to ACQUIRED
2024-02-24 07:20:20,474 INFO org.apache.hadoop.yarn.server.resourcemanager.rmcontainer.RMContainerImpl: container_1708736499436_0003_01_000004 Container Transitioned from ALLOCATED to ACQUIRED
2024-02-24 07:20:20,475 INFO org.apache.hadoop.yarn.server.resourcemanager.rmcontainer.RMContainerImpl: container_1708736499436_0003_01_000005 Container Transitioned from ALLOCATED to ACQUIRED
2024-02-24 07:20:20,475 INFO org.apache.hadoop.yarn.server.resourcemanager.rmcontainer.RMContainerImpl: container_1708736499436_0003_01_000006 Container Transitioned from ALLOCATED to ACQUIRED
2024-02-24 07:20:20,476 INFO org.apache.hadoop.yarn.server.resourcemanager.rmcontainer.RMContainerImpl: container_1708736499436_0003_01_000007 Container Transitioned from ALLOCATED to ACQUIRED
2024-02-24 07:20:20,878 INFO org.apache.hadoop.yarn.server.resourcemanager.rmcontainer.RMContainerImpl: container_1708736499436_0003_01_000002 Container Transitioned from ACQUIRED to RUNNING
2024-02-24 07:20:20,878 INFO org.apache.hadoop.yarn.server.resourcemanager.rmcontainer.RMContainerImpl: container_1708736499436_0003_01_000003 Container Transitioned from ACQUIRED to RUNNING
2024-02-24 07:20:20,879 INFO org.apache.hadoop.yarn.server.resourcemanager.rmcontainer.RMContainerImpl: container_1708736499436_0003_01_000004 Container Transitioned from ACQUIRED to RUNNING
2024-02-24 07:20:20,879 INFO org.apache.hadoop.yarn.server.resourcemanager.rmcontainer.RMContainerImpl: container_1708736499436_0003_01_000005 Container Transitioned from ACQUIRED to RUNNING
2024-02-24 07:20:20,879 INFO org.apache.hadoop.yarn.server.resourcemanager.rmcontainer.RMContainerImpl: container_1708736499436_0003_01_000006 Container Transitioned from ACQUIRED to RUNNING
2024-02-24 07:20:20,879 INFO org.apache.hadoop.yarn.server.resourcemanager.rmcontainer.RMContainerImpl: container_1708736499436_0003_01_000007 Container Transitioned from ACQUIRED to RUNNING
2024-02-24 07:20:24,010 INFO org.apache.hadoop.yarn.server.resourcemanager.rmcontainer.RMContainerImpl: container_1708736499436_0003_01_000003 Container Transitioned from RUNNING to COMPLETED
2024-02-24 07:20:24,011 INFO org.apache.hadoop.yarn.server.resourcemanager.RMAuditLogger: USER=ubuntu	OPERATION=AM Released Container	TARGET=SchedulerApp	RESULT=SUCCESS	APPID=application_1708736499436_0003	CONTAINERID=container_1708736499436_0003_01_000003
2024-02-24 07:20:24,011 INFO org.apache.hadoop.yarn.server.resourcemanager.scheduler.SchedulerNode: Released container container_1708736499436_0003_01_000003 of capacity <memory:1024, vCores:1> on host 5acd4955-724f-452a-817c-900b09ccd050-node1:38895, which currently has 6 containers, <memory:7168, vCores:6> used and <memory:1024, vCores:2> available, release resources=true
2024-02-24 07:20:24,011 INFO org.apache.hadoop.yarn.server.resourcemanager.rmcontainer.RMContainerImpl: container_1708736499436_0003_01_000008 Container Transitioned from NEW to ALLOCATED
2024-02-24 07:20:24,011 INFO org.apache.hadoop.yarn.server.resourcemanager.RMAuditLogger: USER=ubuntu	OPERATION=AM Allocated Container	TARGET=SchedulerApp	RESULT=SUCCESS	APPID=application_1708736499436_0003	CONTAINERID=container_1708736499436_0003_01_000008
2024-02-24 07:20:24,011 INFO org.apache.hadoop.yarn.server.resourcemanager.scheduler.SchedulerNode: Assigned container container_1708736499436_0003_01_000008 of capacity <memory:1024, vCores:1> on host 5acd4955-724f-452a-817c-900b09ccd050-node1:38895, which has 7 containers, <memory:8192, vCores:7> used and <memory:0, vCores:1> available after allocation
2024-02-24 07:20:24,011 INFO org.apache.hadoop.yarn.server.resourcemanager.scheduler.capacity.allocator.AbstractContainerAllocator: assignedContainer application attempt=appattempt_1708736499436_0003_000001 container=container_1708736499436_0003_01_000008 queue=org.apache.hadoop.yarn.server.resourcemanager.scheduler.capacity.allocator.RegularContainerAllocator@3ce2b56a clusterResource=<memory:8192, vCores:8> type=NODE_LOCAL
2024-02-24 07:20:24,011 INFO org.apache.hadoop.yarn.server.resourcemanager.scheduler.capacity.ParentQueue: Re-sorting assigned queue: root.default stats: default: capacity=1.0, absoluteCapacity=1.0, usedResources=<memory:8192, vCores:7>, usedCapacity=1.0, absoluteUsedCapacity=1.0, numApps=1, numContainers=7
2024-02-24 07:20:24,011 INFO org.apache.hadoop.yarn.server.resourcemanager.scheduler.capacity.ParentQueue: assignedContainer queue=root usedCapacity=1.0 absoluteUsedCapacity=1.0 used=<memory:8192, vCores:7> cluster=<memory:8192, vCores:8>
2024-02-24 07:20:24,136 INFO org.apache.hadoop.yarn.server.resourcemanager.rmcontainer.RMContainerImpl: container_1708736499436_0003_01_000007 Container Transitioned from RUNNING to COMPLETED
2024-02-24 07:20:24,136 INFO org.apache.hadoop.yarn.server.resourcemanager.RMAuditLogger: USER=ubuntu	OPERATION=AM Released Container	TARGET=SchedulerApp	RESULT=SUCCESS	APPID=application_1708736499436_0003	CONTAINERID=container_1708736499436_0003_01_000007
2024-02-24 07:20:24,137 INFO org.apache.hadoop.yarn.server.resourcemanager.scheduler.SchedulerNode: Released container container_1708736499436_0003_01_000007 of capacity <memory:1024, vCores:1> on host 5acd4955-724f-452a-817c-900b09ccd050-node1:38895, which currently has 6 containers, <memory:7168, vCores:6> used and <memory:1024, vCores:2> available, release resources=true
2024-02-24 07:20:24,137 INFO org.apache.hadoop.yarn.server.resourcemanager.rmcontainer.RMContainerImpl: container_1708736499436_0003_01_000009 Container Transitioned from NEW to ALLOCATED
2024-02-24 07:20:24,137 INFO org.apache.hadoop.yarn.server.resourcemanager.RMAuditLogger: USER=ubuntu	OPERATION=AM Allocated Container	TARGET=SchedulerApp	RESULT=SUCCESS	APPID=application_1708736499436_0003	CONTAINERID=container_1708736499436_0003_01_000009
2024-02-24 07:20:24,137 INFO org.apache.hadoop.yarn.server.resourcemanager.scheduler.SchedulerNode: Assigned container container_1708736499436_0003_01_000009 of capacity <memory:1024, vCores:1> on host 5acd4955-724f-452a-817c-900b09ccd050-node1:38895, which has 7 containers, <memory:8192, vCores:7> used and <memory:0, vCores:1> available after allocation
2024-02-24 07:20:24,137 INFO org.apache.hadoop.yarn.server.resourcemanager.scheduler.capacity.allocator.AbstractContainerAllocator: assignedContainer application attempt=appattempt_1708736499436_0003_000001 container=container_1708736499436_0003_01_000009 queue=org.apache.hadoop.yarn.server.resourcemanager.scheduler.capacity.allocator.RegularContainerAllocator@3ce2b56a clusterResource=<memory:8192, vCores:8> type=NODE_LOCAL
2024-02-24 07:20:24,137 INFO org.apache.hadoop.yarn.server.resourcemanager.scheduler.capacity.ParentQueue: Re-sorting assigned queue: root.default stats: default: capacity=1.0, absoluteCapacity=1.0, usedResources=<memory:8192, vCores:7>, usedCapacity=1.0, absoluteUsedCapacity=1.0, numApps=1, numContainers=7
2024-02-24 07:20:24,137 INFO org.apache.hadoop.yarn.server.resourcemanager.scheduler.capacity.ParentQueue: assignedContainer queue=root usedCapacity=1.0 absoluteUsedCapacity=1.0 used=<memory:8192, vCores:7> cluster=<memory:8192, vCores:8>
2024-02-24 07:20:24,178 INFO org.apache.hadoop.yarn.server.resourcemanager.rmcontainer.RMContainerImpl: container_1708736499436_0003_01_000004 Container Transitioned from RUNNING to COMPLETED
2024-02-24 07:20:24,178 INFO org.apache.hadoop.yarn.server.resourcemanager.RMAuditLogger: USER=ubuntu	OPERATION=AM Released Container	TARGET=SchedulerApp	RESULT=SUCCESS	APPID=application_1708736499436_0003	CONTAINERID=container_1708736499436_0003_01_000004
2024-02-24 07:20:24,178 INFO org.apache.hadoop.yarn.server.resourcemanager.scheduler.SchedulerNode: Released container container_1708736499436_0003_01_000004 of capacity <memory:1024, vCores:1> on host 5acd4955-724f-452a-817c-900b09ccd050-node1:38895, which currently has 6 containers, <memory:7168, vCores:6> used and <memory:1024, vCores:2> available, release resources=true
2024-02-24 07:20:24,231 INFO org.apache.hadoop.yarn.server.resourcemanager.rmcontainer.RMContainerImpl: container_1708736499436_0003_01_000002 Container Transitioned from RUNNING to COMPLETED
2024-02-24 07:20:24,231 INFO org.apache.hadoop.yarn.server.resourcemanager.RMAuditLogger: USER=ubuntu	OPERATION=AM Released Container	TARGET=SchedulerApp	RESULT=SUCCESS	APPID=application_1708736499436_0003	CONTAINERID=container_1708736499436_0003_01_000002
2024-02-24 07:20:24,231 INFO org.apache.hadoop.yarn.server.resourcemanager.scheduler.SchedulerNode: Released container container_1708736499436_0003_01_000002 of capacity <memory:1024, vCores:1> on host 5acd4955-724f-452a-817c-900b09ccd050-node1:38895, which currently has 5 containers, <memory:6144, vCores:5> used and <memory:2048, vCores:3> available, release resources=true
2024-02-24 07:20:24,244 INFO org.apache.hadoop.yarn.server.resourcemanager.rmcontainer.RMContainerImpl: container_1708736499436_0003_01_000006 Container Transitioned from RUNNING to COMPLETED
2024-02-24 07:20:24,244 INFO org.apache.hadoop.yarn.server.resourcemanager.RMAuditLogger: USER=ubuntu	OPERATION=AM Released Container	TARGET=SchedulerApp	RESULT=SUCCESS	APPID=application_1708736499436_0003	CONTAINERID=container_1708736499436_0003_01_000006
2024-02-24 07:20:24,244 INFO org.apache.hadoop.yarn.server.resourcemanager.scheduler.SchedulerNode: Released container container_1708736499436_0003_01_000006 of capacity <memory:1024, vCores:1> on host 5acd4955-724f-452a-817c-900b09ccd050-node1:38895, which currently has 4 containers, <memory:5120, vCores:4> used and <memory:3072, vCores:4> available, release resources=true
2024-02-24 07:20:24,296 INFO org.apache.hadoop.yarn.server.resourcemanager.rmcontainer.RMContainerImpl: container_1708736499436_0003_01_000005 Container Transitioned from RUNNING to COMPLETED
2024-02-24 07:20:24,296 INFO org.apache.hadoop.yarn.server.resourcemanager.RMAuditLogger: USER=ubuntu	OPERATION=AM Released Container	TARGET=SchedulerApp	RESULT=SUCCESS	APPID=application_1708736499436_0003	CONTAINERID=container_1708736499436_0003_01_000005
2024-02-24 07:20:24,296 INFO org.apache.hadoop.yarn.server.resourcemanager.scheduler.SchedulerNode: Released container container_1708736499436_0003_01_000005 of capacity <memory:1024, vCores:1> on host 5acd4955-724f-452a-817c-900b09ccd050-node1:38895, which currently has 3 containers, <memory:4096, vCores:3> used and <memory:4096, vCores:5> available, release resources=true
2024-02-24 07:20:24,506 INFO org.apache.hadoop.yarn.server.resourcemanager.rmcontainer.RMContainerImpl: container_1708736499436_0003_01_000008 Container Transitioned from ALLOCATED to ACQUIRED
2024-02-24 07:20:24,506 INFO org.apache.hadoop.yarn.server.resourcemanager.rmcontainer.RMContainerImpl: container_1708736499436_0003_01_000009 Container Transitioned from ALLOCATED to ACQUIRED
2024-02-24 07:20:25,297 INFO org.apache.hadoop.yarn.server.resourcemanager.rmcontainer.RMContainerImpl: container_1708736499436_0003_01_000008 Container Transitioned from ACQUIRED to RUNNING
2024-02-24 07:20:25,298 INFO org.apache.hadoop.yarn.server.resourcemanager.rmcontainer.RMContainerImpl: container_1708736499436_0003_01_000009 Container Transitioned from ACQUIRED to RUNNING
2024-02-24 07:20:25,516 INFO org.apache.hadoop.yarn.server.resourcemanager.scheduler.AppSchedulingInfo: checking for deactivate of application :application_1708736499436_0003
2024-02-24 07:20:26,299 INFO org.apache.hadoop.yarn.server.resourcemanager.rmcontainer.RMContainerImpl: container_1708736499436_0003_01_000010 Container Transitioned from NEW to ALLOCATED
2024-02-24 07:20:26,299 INFO org.apache.hadoop.yarn.server.resourcemanager.RMAuditLogger: USER=ubuntu	OPERATION=AM Allocated Container	TARGET=SchedulerApp	RESULT=SUCCESS	APPID=application_1708736499436_0003	CONTAINERID=container_1708736499436_0003_01_000010
2024-02-24 07:20:26,299 INFO org.apache.hadoop.yarn.server.resourcemanager.scheduler.SchedulerNode: Assigned container container_1708736499436_0003_01_000010 of capacity <memory:1024, vCores:1> on host 5acd4955-724f-452a-817c-900b09ccd050-node1:38895, which has 4 containers, <memory:5120, vCores:4> used and <memory:3072, vCores:4> available after allocation
2024-02-24 07:20:26,299 INFO org.apache.hadoop.yarn.server.resourcemanager.scheduler.capacity.allocator.AbstractContainerAllocator: assignedContainer application attempt=appattempt_1708736499436_0003_000001 container=container_1708736499436_0003_01_000010 queue=org.apache.hadoop.yarn.server.resourcemanager.scheduler.capacity.allocator.RegularContainerAllocator@3ce2b56a clusterResource=<memory:8192, vCores:8> type=OFF_SWITCH
2024-02-24 07:20:26,299 INFO org.apache.hadoop.yarn.server.resourcemanager.scheduler.capacity.ParentQueue: Re-sorting assigned queue: root.default stats: default: capacity=1.0, absoluteCapacity=1.0, usedResources=<memory:5120, vCores:4>, usedCapacity=0.625, absoluteUsedCapacity=0.625, numApps=1, numContainers=4
2024-02-24 07:20:26,299 INFO org.apache.hadoop.yarn.server.resourcemanager.scheduler.capacity.ParentQueue: assignedContainer queue=root usedCapacity=0.625 absoluteUsedCapacity=0.625 used=<memory:5120, vCores:4> cluster=<memory:8192, vCores:8>
2024-02-24 07:20:26,519 INFO org.apache.hadoop.yarn.server.resourcemanager.rmcontainer.RMContainerImpl: container_1708736499436_0003_01_000010 Container Transitioned from ALLOCATED to ACQUIRED
2024-02-24 07:20:26,624 INFO org.apache.hadoop.yarn.server.resourcemanager.rmcontainer.RMContainerImpl: container_1708736499436_0003_01_000010 Container Transitioned from ACQUIRED to RUNNING
2024-02-24 07:20:26,624 INFO org.apache.hadoop.yarn.server.resourcemanager.rmcontainer.RMContainerImpl: container_1708736499436_0003_01_000008 Container Transitioned from RUNNING to COMPLETED
2024-02-24 07:20:26,624 INFO org.apache.hadoop.yarn.server.resourcemanager.RMAuditLogger: USER=ubuntu	OPERATION=AM Released Container	TARGET=SchedulerApp	RESULT=SUCCESS	APPID=application_1708736499436_0003	CONTAINERID=container_1708736499436_0003_01_000008
2024-02-24 07:20:26,624 INFO org.apache.hadoop.yarn.server.resourcemanager.scheduler.SchedulerNode: Released container container_1708736499436_0003_01_000008 of capacity <memory:1024, vCores:1> on host 5acd4955-724f-452a-817c-900b09ccd050-node1:38895, which currently has 3 containers, <memory:4096, vCores:3> used and <memory:4096, vCores:5> available, release resources=true
2024-02-24 07:20:26,736 INFO org.apache.hadoop.yarn.server.resourcemanager.rmcontainer.RMContainerImpl: container_1708736499436_0003_01_000009 Container Transitioned from RUNNING to COMPLETED
2024-02-24 07:20:26,736 INFO org.apache.hadoop.yarn.server.resourcemanager.RMAuditLogger: USER=ubuntu	OPERATION=AM Released Container	TARGET=SchedulerApp	RESULT=SUCCESS	APPID=application_1708736499436_0003	CONTAINERID=container_1708736499436_0003_01_000009
2024-02-24 07:20:26,736 INFO org.apache.hadoop.yarn.server.resourcemanager.scheduler.SchedulerNode: Released container container_1708736499436_0003_01_000009 of capacity <memory:1024, vCores:1> on host 5acd4955-724f-452a-817c-900b09ccd050-node1:38895, which currently has 2 containers, <memory:3072, vCores:2> used and <memory:5120, vCores:6> available, release resources=true
2024-02-24 07:20:27,522 INFO org.apache.hadoop.yarn.server.resourcemanager.scheduler.AppSchedulingInfo: checking for deactivate of application :application_1708736499436_0003
2024-02-24 07:20:28,201 INFO org.apache.hadoop.yarn.server.resourcemanager.rmapp.attempt.RMAppAttemptImpl: Updating application attempt appattempt_1708736499436_0003_000001 with final state: FINISHING, and exit status: -1000
2024-02-24 07:20:28,201 INFO org.apache.hadoop.yarn.server.resourcemanager.rmapp.attempt.RMAppAttemptImpl: appattempt_1708736499436_0003_000001 State change from RUNNING to FINAL_SAVING
2024-02-24 07:20:28,201 INFO org.apache.hadoop.yarn.server.resourcemanager.rmapp.RMAppImpl: Updating application application_1708736499436_0003 with final state: FINISHING
2024-02-24 07:20:28,201 INFO org.apache.hadoop.yarn.server.resourcemanager.rmapp.RMAppImpl: application_1708736499436_0003 State change from RUNNING to FINAL_SAVING on event=ATTEMPT_UNREGISTERED
2024-02-24 07:20:28,201 INFO org.apache.hadoop.yarn.server.resourcemanager.recovery.RMStateStore: Updating info for app: application_1708736499436_0003
2024-02-24 07:20:28,201 INFO org.apache.hadoop.yarn.server.resourcemanager.rmapp.attempt.RMAppAttemptImpl: appattempt_1708736499436_0003_000001 State change from FINAL_SAVING to FINISHING
2024-02-24 07:20:28,201 INFO org.apache.hadoop.yarn.server.resourcemanager.rmapp.RMAppImpl: application_1708736499436_0003 State change from FINAL_SAVING to FINISHING on event=APP_UPDATE_SAVED
2024-02-24 07:20:28,203 INFO org.apache.hadoop.yarn.server.resourcemanager.rmcontainer.RMContainerImpl: container_1708736499436_0003_01_000010 Container Transitioned from RUNNING to COMPLETED
2024-02-24 07:20:28,203 INFO org.apache.hadoop.yarn.server.resourcemanager.RMAuditLogger: USER=ubuntu	OPERATION=AM Released Container	TARGET=SchedulerApp	RESULT=SUCCESS	APPID=application_1708736499436_0003	CONTAINERID=container_1708736499436_0003_01_000010
2024-02-24 07:20:28,204 INFO org.apache.hadoop.yarn.server.resourcemanager.scheduler.SchedulerNode: Released container container_1708736499436_0003_01_000010 of capacity <memory:1024, vCores:1> on host 5acd4955-724f-452a-817c-900b09ccd050-node1:38895, which currently has 1 containers, <memory:2048, vCores:1> used and <memory:6144, vCores:7> available, release resources=true
2024-02-24 07:20:29,201 INFO org.apache.hadoop.yarn.server.resourcemanager.ApplicationMasterService: application_1708736499436_0003 unregistered successfully. 
2024-02-24 07:20:34,662 INFO org.apache.hadoop.yarn.server.resourcemanager.rmcontainer.RMContainerImpl: container_1708736499436_0003_01_000001 Container Transitioned from RUNNING to COMPLETED
2024-02-24 07:20:34,662 INFO org.apache.hadoop.yarn.server.resourcemanager.ApplicationMasterService: Unregistering app attempt : appattempt_1708736499436_0003_000001
2024-02-24 07:20:34,662 INFO org.apache.hadoop.yarn.server.resourcemanager.RMAuditLogger: USER=ubuntu	OPERATION=AM Released Container	TARGET=SchedulerApp	RESULT=SUCCESS	APPID=application_1708736499436_0003	CONTAINERID=container_1708736499436_0003_01_000001
2024-02-24 07:20:34,662 INFO org.apache.hadoop.yarn.server.resourcemanager.security.AMRMTokenSecretManager: Application finished, removing password for appattempt_1708736499436_0003_000001
2024-02-24 07:20:34,662 INFO org.apache.hadoop.yarn.server.resourcemanager.rmapp.attempt.RMAppAttemptImpl: appattempt_1708736499436_0003_000001 State change from FINISHING to FINISHED
2024-02-24 07:20:34,662 INFO org.apache.hadoop.yarn.server.resourcemanager.rmapp.RMAppImpl: application_1708736499436_0003 State change from FINISHING to FINISHED on event=ATTEMPT_FINISHED
2024-02-24 07:20:34,662 INFO org.apache.hadoop.yarn.server.resourcemanager.RMAuditLogger: USER=ubuntu	OPERATION=Application Finished - Succeeded	TARGET=RMAppManager	RESULT=SUCCESS	APPID=application_1708736499436_0003
2024-02-24 07:20:34,663 INFO org.apache.hadoop.yarn.server.resourcemanager.scheduler.SchedulerNode: Released container container_1708736499436_0003_01_000001 of capacity <memory:2048, vCores:1> on host 5acd4955-724f-452a-817c-900b09ccd050-node1:38895, which currently has 0 containers, <memory:0, vCores:0> used and <memory:8192, vCores:8> available, release resources=true
2024-02-24 07:20:34,663 INFO org.apache.hadoop.yarn.server.resourcemanager.scheduler.capacity.CapacityScheduler: Application Attempt appattempt_1708736499436_0003_000001 is done. finalState=FINISHED
2024-02-24 07:20:34,663 INFO org.apache.hadoop.yarn.server.resourcemanager.RMAppManager$ApplicationSummary: appId=application_1708736499436_0003,name=word count,user=ubuntu,queue=default,state=FINISHED,trackingUrl=http://5acd4955-724f-452a-817c-900b09ccd050-node1:8088/proxy/application_1708736499436_0003/,appMasterHost=5acd4955-724f-452a-817c-900b09ccd050-node1,startTime=1708759215129,finishTime=1708759228201,finalStatus=SUCCEEDED,memorySeconds=72204,vcoreSeconds=47,preemptedMemorySeconds=0,preemptedVcoreSeconds=0,preemptedAMContainers=0,preemptedNonAMContainers=0,preemptedResources=<memory:0\, vCores:0>,applicationType=MAPREDUCE
2024-02-24 07:20:34,663 INFO org.apache.hadoop.yarn.server.resourcemanager.scheduler.AppSchedulingInfo: Application application_1708736499436_0003 requests cleared
2024-02-24 07:20:34,663 INFO org.apache.hadoop.yarn.server.resourcemanager.scheduler.capacity.LeafQueue: Application removed - appId: application_1708736499436_0003 user: ubuntu queue: default #user-pending-applications: 0 #user-active-applications: 0 #queue-pending-applications: 0 #queue-active-applications: 0
2024-02-24 07:20:34,663 INFO org.apache.hadoop.yarn.server.resourcemanager.amlauncher.AMLauncher: Cleaning master appattempt_1708736499436_0003_000001
2024-02-24 07:20:34,663 INFO org.apache.hadoop.yarn.server.resourcemanager.scheduler.capacity.ParentQueue: Application removed - appId: application_1708736499436_0003 user: ubuntu leaf-queue of parent: root #applications: 0
2024-02-24 07:20:36,663 INFO org.apache.hadoop.yarn.server.resourcemanager.scheduler.AbstractYarnScheduler: Container container_1708736499436_0003_01_000010 completed with event FINISHED, but corresponding RMContainer doesn't exist.
2024-02-24 07:25:22,805 INFO org.apache.hadoop.yarn.server.resourcemanager.ClientRMService: Allocated new applicationId: 4
2024-02-24 07:25:23,520 INFO org.apache.hadoop.yarn.server.resourcemanager.scheduler.capacity.CapacityScheduler: Application 'application_1708736499436_0004' is submitted without priority hence considering default queue/cluster priority: 0
2024-02-24 07:25:23,520 INFO org.apache.hadoop.yarn.server.resourcemanager.scheduler.capacity.CapacityScheduler: Priority '0' is acceptable in queue : default for application: application_1708736499436_0004 for the user: ubuntu
2024-02-24 07:25:23,520 INFO org.apache.hadoop.yarn.server.resourcemanager.ClientRMService: Application with id 4 submitted by user ubuntu
2024-02-24 07:25:23,520 INFO org.apache.hadoop.yarn.server.resourcemanager.RMAuditLogger: USER=ubuntu	IP=10.30.6.115	OPERATION=Submit Application Request	TARGET=ClientRMService	RESULT=SUCCESS	APPID=application_1708736499436_0004
2024-02-24 07:25:23,520 INFO org.apache.hadoop.yarn.server.resourcemanager.rmapp.RMAppImpl: Storing application with id application_1708736499436_0004
2024-02-24 07:25:23,520 INFO org.apache.hadoop.yarn.server.resourcemanager.rmapp.RMAppImpl: application_1708736499436_0004 State change from NEW to NEW_SAVING on event=START
2024-02-24 07:25:23,521 INFO org.apache.hadoop.yarn.server.resourcemanager.recovery.RMStateStore: Storing info for app: application_1708736499436_0004
2024-02-24 07:25:23,521 INFO org.apache.hadoop.yarn.server.resourcemanager.rmapp.RMAppImpl: application_1708736499436_0004 State change from NEW_SAVING to SUBMITTED on event=APP_NEW_SAVED
2024-02-24 07:25:23,521 INFO org.apache.hadoop.yarn.server.resourcemanager.scheduler.capacity.ParentQueue: Application added - appId: application_1708736499436_0004 user: ubuntu leaf-queue of parent: root #applications: 1
2024-02-24 07:25:23,521 INFO org.apache.hadoop.yarn.server.resourcemanager.scheduler.capacity.CapacityScheduler: Accepted application application_1708736499436_0004 from user: ubuntu, in queue: default
2024-02-24 07:25:23,523 INFO org.apache.hadoop.yarn.server.resourcemanager.rmapp.RMAppImpl: application_1708736499436_0004 State change from SUBMITTED to ACCEPTED on event=APP_ACCEPTED
2024-02-24 07:25:23,523 INFO org.apache.hadoop.yarn.server.resourcemanager.ApplicationMasterService: Registering app attempt : appattempt_1708736499436_0004_000001
2024-02-24 07:25:23,523 INFO org.apache.hadoop.yarn.server.resourcemanager.rmapp.attempt.RMAppAttemptImpl: appattempt_1708736499436_0004_000001 State change from NEW to SUBMITTED
2024-02-24 07:25:23,523 WARN org.apache.hadoop.yarn.server.resourcemanager.scheduler.capacity.LeafQueue: maximum-am-resource-percent is insufficient to start a single application in queue, it is likely set too low. skipping enforcement to allow at least one application to start
2024-02-24 07:25:23,523 WARN org.apache.hadoop.yarn.server.resourcemanager.scheduler.capacity.LeafQueue: maximum-am-resource-percent is insufficient to start a single application in queue for user, it is likely set too low. skipping enforcement to allow at least one application to start
2024-02-24 07:25:23,523 INFO org.apache.hadoop.yarn.server.resourcemanager.scheduler.capacity.LeafQueue: Application application_1708736499436_0004 from user: ubuntu activated in queue: default
2024-02-24 07:25:23,523 INFO org.apache.hadoop.yarn.server.resourcemanager.scheduler.capacity.LeafQueue: Application added - appId: application_1708736499436_0004 user: ubuntu, leaf-queue: default #user-pending-applications: 0 #user-active-applications: 1 #queue-pending-applications: 0 #queue-active-applications: 1
2024-02-24 07:25:23,523 INFO org.apache.hadoop.yarn.server.resourcemanager.scheduler.capacity.CapacityScheduler: Added Application Attempt appattempt_1708736499436_0004_000001 to scheduler from user ubuntu in queue default
2024-02-24 07:25:23,524 INFO org.apache.hadoop.yarn.server.resourcemanager.rmapp.attempt.RMAppAttemptImpl: appattempt_1708736499436_0004_000001 State change from SUBMITTED to SCHEDULED
2024-02-24 07:25:23,773 INFO org.apache.hadoop.yarn.server.resourcemanager.rmcontainer.RMContainerImpl: container_1708736499436_0004_01_000001 Container Transitioned from NEW to ALLOCATED
2024-02-24 07:25:23,773 INFO org.apache.hadoop.yarn.server.resourcemanager.RMAuditLogger: USER=ubuntu	OPERATION=AM Allocated Container	TARGET=SchedulerApp	RESULT=SUCCESS	APPID=application_1708736499436_0004	CONTAINERID=container_1708736499436_0004_01_000001
2024-02-24 07:25:23,773 INFO org.apache.hadoop.yarn.server.resourcemanager.scheduler.SchedulerNode: Assigned container container_1708736499436_0004_01_000001 of capacity <memory:2048, vCores:1> on host 5acd4955-724f-452a-817c-900b09ccd050-node1:38895, which has 1 containers, <memory:2048, vCores:1> used and <memory:6144, vCores:7> available after allocation
2024-02-24 07:25:23,773 INFO org.apache.hadoop.yarn.server.resourcemanager.scheduler.capacity.allocator.AbstractContainerAllocator: assignedContainer application attempt=appattempt_1708736499436_0004_000001 container=container_1708736499436_0004_01_000001 queue=org.apache.hadoop.yarn.server.resourcemanager.scheduler.capacity.allocator.RegularContainerAllocator@2226b84 clusterResource=<memory:8192, vCores:8> type=OFF_SWITCH
2024-02-24 07:25:23,774 INFO org.apache.hadoop.yarn.server.resourcemanager.security.NMTokenSecretManagerInRM: Sending NMToken for nodeId : 5acd4955-724f-452a-817c-900b09ccd050-node1:38895 for container : container_1708736499436_0004_01_000001
2024-02-24 07:25:23,775 INFO org.apache.hadoop.yarn.server.resourcemanager.rmcontainer.RMContainerImpl: container_1708736499436_0004_01_000001 Container Transitioned from ALLOCATED to ACQUIRED
2024-02-24 07:25:23,775 INFO org.apache.hadoop.yarn.server.resourcemanager.security.NMTokenSecretManagerInRM: Clear node set for appattempt_1708736499436_0004_000001
2024-02-24 07:25:23,775 INFO org.apache.hadoop.yarn.server.resourcemanager.rmapp.attempt.RMAppAttemptImpl: Storing attempt: AppId: application_1708736499436_0004 AttemptId: appattempt_1708736499436_0004_000001 MasterContainer: Container: [ContainerId: container_1708736499436_0004_01_000001, Version: 0, NodeId: 5acd4955-724f-452a-817c-900b09ccd050-node1:38895, NodeHttpAddress: 5acd4955-724f-452a-817c-900b09ccd050-node1:8042, Resource: <memory:2048, vCores:1>, Priority: 0, Token: Token { kind: ContainerToken, service: 10.30.6.115:38895 }, ]
2024-02-24 07:25:23,775 INFO org.apache.hadoop.yarn.server.resourcemanager.scheduler.capacity.ParentQueue: Re-sorting assigned queue: root.default stats: default: capacity=1.0, absoluteCapacity=1.0, usedResources=<memory:2048, vCores:1>, usedCapacity=0.25, absoluteUsedCapacity=0.25, numApps=1, numContainers=1
2024-02-24 07:25:23,775 INFO org.apache.hadoop.yarn.server.resourcemanager.scheduler.capacity.ParentQueue: assignedContainer queue=root usedCapacity=0.25 absoluteUsedCapacity=0.25 used=<memory:2048, vCores:1> cluster=<memory:8192, vCores:8>
2024-02-24 07:25:23,775 INFO org.apache.hadoop.yarn.server.resourcemanager.rmapp.attempt.RMAppAttemptImpl: appattempt_1708736499436_0004_000001 State change from SCHEDULED to ALLOCATED_SAVING
2024-02-24 07:25:23,775 INFO org.apache.hadoop.yarn.server.resourcemanager.rmapp.attempt.RMAppAttemptImpl: appattempt_1708736499436_0004_000001 State change from ALLOCATED_SAVING to ALLOCATED
2024-02-24 07:25:23,776 INFO org.apache.hadoop.yarn.server.resourcemanager.amlauncher.AMLauncher: Launching masterappattempt_1708736499436_0004_000001
2024-02-24 07:25:23,777 INFO org.apache.hadoop.yarn.server.resourcemanager.amlauncher.AMLauncher: Setting up container Container: [ContainerId: container_1708736499436_0004_01_000001, Version: 0, NodeId: 5acd4955-724f-452a-817c-900b09ccd050-node1:38895, NodeHttpAddress: 5acd4955-724f-452a-817c-900b09ccd050-node1:8042, Resource: <memory:2048, vCores:1>, Priority: 0, Token: Token { kind: ContainerToken, service: 10.30.6.115:38895 }, ] for AM appattempt_1708736499436_0004_000001
2024-02-24 07:25:23,778 INFO org.apache.hadoop.yarn.server.resourcemanager.security.AMRMTokenSecretManager: Create AMRMToken for ApplicationAttempt: appattempt_1708736499436_0004_000001
2024-02-24 07:25:23,778 INFO org.apache.hadoop.yarn.server.resourcemanager.security.AMRMTokenSecretManager: Creating password for appattempt_1708736499436_0004_000001
2024-02-24 07:25:23,788 INFO org.apache.hadoop.yarn.server.resourcemanager.amlauncher.AMLauncher: Done launching container Container: [ContainerId: container_1708736499436_0004_01_000001, Version: 0, NodeId: 5acd4955-724f-452a-817c-900b09ccd050-node1:38895, NodeHttpAddress: 5acd4955-724f-452a-817c-900b09ccd050-node1:8042, Resource: <memory:2048, vCores:1>, Priority: 0, Token: Token { kind: ContainerToken, service: 10.30.6.115:38895 }, ] for AM appattempt_1708736499436_0004_000001
2024-02-24 07:25:23,789 INFO org.apache.hadoop.yarn.server.resourcemanager.rmapp.attempt.RMAppAttemptImpl: appattempt_1708736499436_0004_000001 State change from ALLOCATED to LAUNCHED
2024-02-24 07:25:24,774 INFO org.apache.hadoop.yarn.server.resourcemanager.rmcontainer.RMContainerImpl: container_1708736499436_0004_01_000001 Container Transitioned from ACQUIRED to RUNNING
2024-02-24 07:25:26,256 INFO SecurityLogger.org.apache.hadoop.ipc.Server: Auth successful for appattempt_1708736499436_0004_000001 (auth:SIMPLE)
2024-02-24 07:25:26,258 INFO org.apache.hadoop.yarn.server.resourcemanager.ApplicationMasterService: AM registration appattempt_1708736499436_0004_000001
2024-02-24 07:25:26,258 INFO org.apache.hadoop.yarn.server.resourcemanager.RMAuditLogger: USER=ubuntu	IP=10.30.6.115	OPERATION=Register App Master	TARGET=ApplicationMasterService	RESULT=SUCCESS	APPID=application_1708736499436_0004	APPATTEMPTID=appattempt_1708736499436_0004_000001
2024-02-24 07:25:26,258 INFO org.apache.hadoop.yarn.server.resourcemanager.rmapp.attempt.RMAppAttemptImpl: appattempt_1708736499436_0004_000001 State change from LAUNCHED to RUNNING
2024-02-24 07:25:26,259 INFO org.apache.hadoop.yarn.server.resourcemanager.rmapp.RMAppImpl: application_1708736499436_0004 State change from ACCEPTED to RUNNING on event=ATTEMPT_REGISTERED
2024-02-24 07:25:27,776 INFO org.apache.hadoop.yarn.server.resourcemanager.rmcontainer.RMContainerImpl: container_1708736499436_0004_01_000002 Container Transitioned from NEW to ALLOCATED
2024-02-24 07:25:27,777 INFO org.apache.hadoop.yarn.server.resourcemanager.RMAuditLogger: USER=ubuntu	OPERATION=AM Allocated Container	TARGET=SchedulerApp	RESULT=SUCCESS	APPID=application_1708736499436_0004	CONTAINERID=container_1708736499436_0004_01_000002
2024-02-24 07:25:27,777 INFO org.apache.hadoop.yarn.server.resourcemanager.scheduler.SchedulerNode: Assigned container container_1708736499436_0004_01_000002 of capacity <memory:1024, vCores:1> on host 5acd4955-724f-452a-817c-900b09ccd050-node1:38895, which has 2 containers, <memory:3072, vCores:2> used and <memory:5120, vCores:6> available after allocation
2024-02-24 07:25:27,777 INFO org.apache.hadoop.yarn.server.resourcemanager.scheduler.capacity.allocator.AbstractContainerAllocator: assignedContainer application attempt=appattempt_1708736499436_0004_000001 container=container_1708736499436_0004_01_000002 queue=org.apache.hadoop.yarn.server.resourcemanager.scheduler.capacity.allocator.RegularContainerAllocator@2226b84 clusterResource=<memory:8192, vCores:8> type=NODE_LOCAL
2024-02-24 07:25:27,777 INFO org.apache.hadoop.yarn.server.resourcemanager.scheduler.capacity.ParentQueue: Re-sorting assigned queue: root.default stats: default: capacity=1.0, absoluteCapacity=1.0, usedResources=<memory:3072, vCores:2>, usedCapacity=0.375, absoluteUsedCapacity=0.375, numApps=1, numContainers=2
2024-02-24 07:25:27,777 INFO org.apache.hadoop.yarn.server.resourcemanager.scheduler.capacity.ParentQueue: assignedContainer queue=root usedCapacity=0.375 absoluteUsedCapacity=0.375 used=<memory:3072, vCores:2> cluster=<memory:8192, vCores:8>
2024-02-24 07:25:27,777 INFO org.apache.hadoop.yarn.server.resourcemanager.rmcontainer.RMContainerImpl: container_1708736499436_0004_01_000003 Container Transitioned from NEW to ALLOCATED
2024-02-24 07:25:27,777 INFO org.apache.hadoop.yarn.server.resourcemanager.RMAuditLogger: USER=ubuntu	OPERATION=AM Allocated Container	TARGET=SchedulerApp	RESULT=SUCCESS	APPID=application_1708736499436_0004	CONTAINERID=container_1708736499436_0004_01_000003
2024-02-24 07:25:27,777 INFO org.apache.hadoop.yarn.server.resourcemanager.scheduler.SchedulerNode: Assigned container container_1708736499436_0004_01_000003 of capacity <memory:1024, vCores:1> on host 5acd4955-724f-452a-817c-900b09ccd050-node1:38895, which has 3 containers, <memory:4096, vCores:3> used and <memory:4096, vCores:5> available after allocation
2024-02-24 07:25:27,777 INFO org.apache.hadoop.yarn.server.resourcemanager.scheduler.capacity.allocator.AbstractContainerAllocator: assignedContainer application attempt=appattempt_1708736499436_0004_000001 container=container_1708736499436_0004_01_000003 queue=org.apache.hadoop.yarn.server.resourcemanager.scheduler.capacity.allocator.RegularContainerAllocator@2226b84 clusterResource=<memory:8192, vCores:8> type=NODE_LOCAL
2024-02-24 07:25:27,777 INFO org.apache.hadoop.yarn.server.resourcemanager.scheduler.capacity.ParentQueue: Re-sorting assigned queue: root.default stats: default: capacity=1.0, absoluteCapacity=1.0, usedResources=<memory:4096, vCores:3>, usedCapacity=0.5, absoluteUsedCapacity=0.5, numApps=1, numContainers=3
2024-02-24 07:25:27,777 INFO org.apache.hadoop.yarn.server.resourcemanager.scheduler.capacity.ParentQueue: assignedContainer queue=root usedCapacity=0.5 absoluteUsedCapacity=0.5 used=<memory:4096, vCores:3> cluster=<memory:8192, vCores:8>
2024-02-24 07:25:27,777 INFO org.apache.hadoop.yarn.server.resourcemanager.rmcontainer.RMContainerImpl: container_1708736499436_0004_01_000004 Container Transitioned from NEW to ALLOCATED
2024-02-24 07:25:27,777 INFO org.apache.hadoop.yarn.server.resourcemanager.RMAuditLogger: USER=ubuntu	OPERATION=AM Allocated Container	TARGET=SchedulerApp	RESULT=SUCCESS	APPID=application_1708736499436_0004	CONTAINERID=container_1708736499436_0004_01_000004
2024-02-24 07:25:27,777 INFO org.apache.hadoop.yarn.server.resourcemanager.scheduler.SchedulerNode: Assigned container container_1708736499436_0004_01_000004 of capacity <memory:1024, vCores:1> on host 5acd4955-724f-452a-817c-900b09ccd050-node1:38895, which has 4 containers, <memory:5120, vCores:4> used and <memory:3072, vCores:4> available after allocation
2024-02-24 07:25:27,777 INFO org.apache.hadoop.yarn.server.resourcemanager.scheduler.capacity.allocator.AbstractContainerAllocator: assignedContainer application attempt=appattempt_1708736499436_0004_000001 container=container_1708736499436_0004_01_000004 queue=org.apache.hadoop.yarn.server.resourcemanager.scheduler.capacity.allocator.RegularContainerAllocator@2226b84 clusterResource=<memory:8192, vCores:8> type=NODE_LOCAL
2024-02-24 07:25:27,778 INFO org.apache.hadoop.yarn.server.resourcemanager.scheduler.capacity.ParentQueue: Re-sorting assigned queue: root.default stats: default: capacity=1.0, absoluteCapacity=1.0, usedResources=<memory:5120, vCores:4>, usedCapacity=0.625, absoluteUsedCapacity=0.625, numApps=1, numContainers=4
2024-02-24 07:25:27,778 INFO org.apache.hadoop.yarn.server.resourcemanager.scheduler.capacity.ParentQueue: assignedContainer queue=root usedCapacity=0.625 absoluteUsedCapacity=0.625 used=<memory:5120, vCores:4> cluster=<memory:8192, vCores:8>
2024-02-24 07:25:27,778 INFO org.apache.hadoop.yarn.server.resourcemanager.rmcontainer.RMContainerImpl: container_1708736499436_0004_01_000005 Container Transitioned from NEW to ALLOCATED
2024-02-24 07:25:27,778 INFO org.apache.hadoop.yarn.server.resourcemanager.RMAuditLogger: USER=ubuntu	OPERATION=AM Allocated Container	TARGET=SchedulerApp	RESULT=SUCCESS	APPID=application_1708736499436_0004	CONTAINERID=container_1708736499436_0004_01_000005
2024-02-24 07:25:27,778 INFO org.apache.hadoop.yarn.server.resourcemanager.scheduler.SchedulerNode: Assigned container container_1708736499436_0004_01_000005 of capacity <memory:1024, vCores:1> on host 5acd4955-724f-452a-817c-900b09ccd050-node1:38895, which has 5 containers, <memory:6144, vCores:5> used and <memory:2048, vCores:3> available after allocation
2024-02-24 07:25:27,778 INFO org.apache.hadoop.yarn.server.resourcemanager.scheduler.capacity.allocator.AbstractContainerAllocator: assignedContainer application attempt=appattempt_1708736499436_0004_000001 container=container_1708736499436_0004_01_000005 queue=org.apache.hadoop.yarn.server.resourcemanager.scheduler.capacity.allocator.RegularContainerAllocator@2226b84 clusterResource=<memory:8192, vCores:8> type=NODE_LOCAL
2024-02-24 07:25:27,778 INFO org.apache.hadoop.yarn.server.resourcemanager.scheduler.capacity.ParentQueue: Re-sorting assigned queue: root.default stats: default: capacity=1.0, absoluteCapacity=1.0, usedResources=<memory:6144, vCores:5>, usedCapacity=0.75, absoluteUsedCapacity=0.75, numApps=1, numContainers=5
2024-02-24 07:25:27,778 INFO org.apache.hadoop.yarn.server.resourcemanager.scheduler.capacity.ParentQueue: assignedContainer queue=root usedCapacity=0.75 absoluteUsedCapacity=0.75 used=<memory:6144, vCores:5> cluster=<memory:8192, vCores:8>
2024-02-24 07:25:27,778 INFO org.apache.hadoop.yarn.server.resourcemanager.rmcontainer.RMContainerImpl: container_1708736499436_0004_01_000006 Container Transitioned from NEW to ALLOCATED
2024-02-24 07:25:27,778 INFO org.apache.hadoop.yarn.server.resourcemanager.RMAuditLogger: USER=ubuntu	OPERATION=AM Allocated Container	TARGET=SchedulerApp	RESULT=SUCCESS	APPID=application_1708736499436_0004	CONTAINERID=container_1708736499436_0004_01_000006
2024-02-24 07:25:27,778 INFO org.apache.hadoop.yarn.server.resourcemanager.scheduler.SchedulerNode: Assigned container container_1708736499436_0004_01_000006 of capacity <memory:1024, vCores:1> on host 5acd4955-724f-452a-817c-900b09ccd050-node1:38895, which has 6 containers, <memory:7168, vCores:6> used and <memory:1024, vCores:2> available after allocation
2024-02-24 07:25:27,778 INFO org.apache.hadoop.yarn.server.resourcemanager.scheduler.capacity.allocator.AbstractContainerAllocator: assignedContainer application attempt=appattempt_1708736499436_0004_000001 container=container_1708736499436_0004_01_000006 queue=org.apache.hadoop.yarn.server.resourcemanager.scheduler.capacity.allocator.RegularContainerAllocator@2226b84 clusterResource=<memory:8192, vCores:8> type=NODE_LOCAL
2024-02-24 07:25:27,778 INFO org.apache.hadoop.yarn.server.resourcemanager.scheduler.capacity.ParentQueue: Re-sorting assigned queue: root.default stats: default: capacity=1.0, absoluteCapacity=1.0, usedResources=<memory:7168, vCores:6>, usedCapacity=0.875, absoluteUsedCapacity=0.875, numApps=1, numContainers=6
2024-02-24 07:25:27,778 INFO org.apache.hadoop.yarn.server.resourcemanager.scheduler.capacity.ParentQueue: assignedContainer queue=root usedCapacity=0.875 absoluteUsedCapacity=0.875 used=<memory:7168, vCores:6> cluster=<memory:8192, vCores:8>
2024-02-24 07:25:27,778 INFO org.apache.hadoop.yarn.server.resourcemanager.rmcontainer.RMContainerImpl: container_1708736499436_0004_01_000007 Container Transitioned from NEW to ALLOCATED
2024-02-24 07:25:27,778 INFO org.apache.hadoop.yarn.server.resourcemanager.RMAuditLogger: USER=ubuntu	OPERATION=AM Allocated Container	TARGET=SchedulerApp	RESULT=SUCCESS	APPID=application_1708736499436_0004	CONTAINERID=container_1708736499436_0004_01_000007
2024-02-24 07:25:27,778 INFO org.apache.hadoop.yarn.server.resourcemanager.scheduler.SchedulerNode: Assigned container container_1708736499436_0004_01_000007 of capacity <memory:1024, vCores:1> on host 5acd4955-724f-452a-817c-900b09ccd050-node1:38895, which has 7 containers, <memory:8192, vCores:7> used and <memory:0, vCores:1> available after allocation
2024-02-24 07:25:27,778 INFO org.apache.hadoop.yarn.server.resourcemanager.scheduler.capacity.allocator.AbstractContainerAllocator: assignedContainer application attempt=appattempt_1708736499436_0004_000001 container=container_1708736499436_0004_01_000007 queue=org.apache.hadoop.yarn.server.resourcemanager.scheduler.capacity.allocator.RegularContainerAllocator@2226b84 clusterResource=<memory:8192, vCores:8> type=NODE_LOCAL
2024-02-24 07:25:27,779 INFO org.apache.hadoop.yarn.server.resourcemanager.scheduler.capacity.ParentQueue: Re-sorting assigned queue: root.default stats: default: capacity=1.0, absoluteCapacity=1.0, usedResources=<memory:8192, vCores:7>, usedCapacity=1.0, absoluteUsedCapacity=1.0, numApps=1, numContainers=7
2024-02-24 07:25:27,779 INFO org.apache.hadoop.yarn.server.resourcemanager.scheduler.capacity.ParentQueue: assignedContainer queue=root usedCapacity=1.0 absoluteUsedCapacity=1.0 used=<memory:8192, vCores:7> cluster=<memory:8192, vCores:8>
2024-02-24 07:25:28,290 INFO org.apache.hadoop.yarn.server.resourcemanager.security.NMTokenSecretManagerInRM: Sending NMToken for nodeId : 5acd4955-724f-452a-817c-900b09ccd050-node1:38895 for container : container_1708736499436_0004_01_000002
2024-02-24 07:25:28,291 INFO org.apache.hadoop.yarn.server.resourcemanager.rmcontainer.RMContainerImpl: container_1708736499436_0004_01_000002 Container Transitioned from ALLOCATED to ACQUIRED
2024-02-24 07:25:28,291 INFO org.apache.hadoop.yarn.server.resourcemanager.rmcontainer.RMContainerImpl: container_1708736499436_0004_01_000003 Container Transitioned from ALLOCATED to ACQUIRED
2024-02-24 07:25:28,292 INFO org.apache.hadoop.yarn.server.resourcemanager.rmcontainer.RMContainerImpl: container_1708736499436_0004_01_000004 Container Transitioned from ALLOCATED to ACQUIRED
2024-02-24 07:25:28,292 INFO org.apache.hadoop.yarn.server.resourcemanager.rmcontainer.RMContainerImpl: container_1708736499436_0004_01_000005 Container Transitioned from ALLOCATED to ACQUIRED
2024-02-24 07:25:28,292 INFO org.apache.hadoop.yarn.server.resourcemanager.rmcontainer.RMContainerImpl: container_1708736499436_0004_01_000006 Container Transitioned from ALLOCATED to ACQUIRED
2024-02-24 07:25:28,293 INFO org.apache.hadoop.yarn.server.resourcemanager.rmcontainer.RMContainerImpl: container_1708736499436_0004_01_000007 Container Transitioned from ALLOCATED to ACQUIRED
2024-02-24 07:25:28,777 INFO org.apache.hadoop.yarn.server.resourcemanager.rmcontainer.RMContainerImpl: container_1708736499436_0004_01_000002 Container Transitioned from ACQUIRED to RUNNING
2024-02-24 07:25:28,777 INFO org.apache.hadoop.yarn.server.resourcemanager.rmcontainer.RMContainerImpl: container_1708736499436_0004_01_000003 Container Transitioned from ACQUIRED to RUNNING
2024-02-24 07:25:28,778 INFO org.apache.hadoop.yarn.server.resourcemanager.rmcontainer.RMContainerImpl: container_1708736499436_0004_01_000004 Container Transitioned from ACQUIRED to RUNNING
2024-02-24 07:25:28,778 INFO org.apache.hadoop.yarn.server.resourcemanager.rmcontainer.RMContainerImpl: container_1708736499436_0004_01_000005 Container Transitioned from ACQUIRED to RUNNING
2024-02-24 07:25:28,778 INFO org.apache.hadoop.yarn.server.resourcemanager.rmcontainer.RMContainerImpl: container_1708736499436_0004_01_000006 Container Transitioned from ACQUIRED to RUNNING
2024-02-24 07:25:28,778 INFO org.apache.hadoop.yarn.server.resourcemanager.rmcontainer.RMContainerImpl: container_1708736499436_0004_01_000007 Container Transitioned from ACQUIRED to RUNNING
2024-02-24 07:25:31,950 INFO org.apache.hadoop.yarn.server.resourcemanager.rmcontainer.RMContainerImpl: container_1708736499436_0004_01_000004 Container Transitioned from RUNNING to COMPLETED
2024-02-24 07:25:31,950 INFO org.apache.hadoop.yarn.server.resourcemanager.RMAuditLogger: USER=ubuntu	OPERATION=AM Released Container	TARGET=SchedulerApp	RESULT=SUCCESS	APPID=application_1708736499436_0004	CONTAINERID=container_1708736499436_0004_01_000004
2024-02-24 07:25:31,950 INFO org.apache.hadoop.yarn.server.resourcemanager.scheduler.SchedulerNode: Released container container_1708736499436_0004_01_000004 of capacity <memory:1024, vCores:1> on host 5acd4955-724f-452a-817c-900b09ccd050-node1:38895, which currently has 6 containers, <memory:7168, vCores:6> used and <memory:1024, vCores:2> available, release resources=true
2024-02-24 07:25:31,951 INFO org.apache.hadoop.yarn.server.resourcemanager.rmcontainer.RMContainerImpl: container_1708736499436_0004_01_000008 Container Transitioned from NEW to ALLOCATED
2024-02-24 07:25:31,951 INFO org.apache.hadoop.yarn.server.resourcemanager.RMAuditLogger: USER=ubuntu	OPERATION=AM Allocated Container	TARGET=SchedulerApp	RESULT=SUCCESS	APPID=application_1708736499436_0004	CONTAINERID=container_1708736499436_0004_01_000008
2024-02-24 07:25:31,951 INFO org.apache.hadoop.yarn.server.resourcemanager.scheduler.SchedulerNode: Assigned container container_1708736499436_0004_01_000008 of capacity <memory:1024, vCores:1> on host 5acd4955-724f-452a-817c-900b09ccd050-node1:38895, which has 7 containers, <memory:8192, vCores:7> used and <memory:0, vCores:1> available after allocation
2024-02-24 07:25:31,951 INFO org.apache.hadoop.yarn.server.resourcemanager.scheduler.capacity.allocator.AbstractContainerAllocator: assignedContainer application attempt=appattempt_1708736499436_0004_000001 container=container_1708736499436_0004_01_000008 queue=org.apache.hadoop.yarn.server.resourcemanager.scheduler.capacity.allocator.RegularContainerAllocator@2226b84 clusterResource=<memory:8192, vCores:8> type=NODE_LOCAL
2024-02-24 07:25:31,951 INFO org.apache.hadoop.yarn.server.resourcemanager.scheduler.capacity.ParentQueue: Re-sorting assigned queue: root.default stats: default: capacity=1.0, absoluteCapacity=1.0, usedResources=<memory:8192, vCores:7>, usedCapacity=1.0, absoluteUsedCapacity=1.0, numApps=1, numContainers=7
2024-02-24 07:25:31,951 INFO org.apache.hadoop.yarn.server.resourcemanager.scheduler.capacity.ParentQueue: assignedContainer queue=root usedCapacity=1.0 absoluteUsedCapacity=1.0 used=<memory:8192, vCores:7> cluster=<memory:8192, vCores:8>
2024-02-24 07:25:31,972 INFO org.apache.hadoop.yarn.server.resourcemanager.rmcontainer.RMContainerImpl: container_1708736499436_0004_01_000002 Container Transitioned from RUNNING to COMPLETED
2024-02-24 07:25:31,972 INFO org.apache.hadoop.yarn.server.resourcemanager.RMAuditLogger: USER=ubuntu	OPERATION=AM Released Container	TARGET=SchedulerApp	RESULT=SUCCESS	APPID=application_1708736499436_0004	CONTAINERID=container_1708736499436_0004_01_000002
2024-02-24 07:25:31,973 INFO org.apache.hadoop.yarn.server.resourcemanager.scheduler.SchedulerNode: Released container container_1708736499436_0004_01_000002 of capacity <memory:1024, vCores:1> on host 5acd4955-724f-452a-817c-900b09ccd050-node1:38895, which currently has 6 containers, <memory:7168, vCores:6> used and <memory:1024, vCores:2> available, release resources=true
2024-02-24 07:25:31,974 INFO org.apache.hadoop.yarn.server.resourcemanager.rmcontainer.RMContainerImpl: container_1708736499436_0004_01_000009 Container Transitioned from NEW to ALLOCATED
2024-02-24 07:25:31,974 INFO org.apache.hadoop.yarn.server.resourcemanager.RMAuditLogger: USER=ubuntu	OPERATION=AM Allocated Container	TARGET=SchedulerApp	RESULT=SUCCESS	APPID=application_1708736499436_0004	CONTAINERID=container_1708736499436_0004_01_000009
2024-02-24 07:25:31,974 INFO org.apache.hadoop.yarn.server.resourcemanager.scheduler.SchedulerNode: Assigned container container_1708736499436_0004_01_000009 of capacity <memory:1024, vCores:1> on host 5acd4955-724f-452a-817c-900b09ccd050-node1:38895, which has 7 containers, <memory:8192, vCores:7> used and <memory:0, vCores:1> available after allocation
2024-02-24 07:25:31,974 INFO org.apache.hadoop.yarn.server.resourcemanager.scheduler.capacity.allocator.AbstractContainerAllocator: assignedContainer application attempt=appattempt_1708736499436_0004_000001 container=container_1708736499436_0004_01_000009 queue=org.apache.hadoop.yarn.server.resourcemanager.scheduler.capacity.allocator.RegularContainerAllocator@2226b84 clusterResource=<memory:8192, vCores:8> type=NODE_LOCAL
2024-02-24 07:25:31,974 INFO org.apache.hadoop.yarn.server.resourcemanager.scheduler.capacity.ParentQueue: Re-sorting assigned queue: root.default stats: default: capacity=1.0, absoluteCapacity=1.0, usedResources=<memory:8192, vCores:7>, usedCapacity=1.0, absoluteUsedCapacity=1.0, numApps=1, numContainers=7
2024-02-24 07:25:31,974 INFO org.apache.hadoop.yarn.server.resourcemanager.scheduler.capacity.ParentQueue: assignedContainer queue=root usedCapacity=1.0 absoluteUsedCapacity=1.0 used=<memory:8192, vCores:7> cluster=<memory:8192, vCores:8>
2024-02-24 07:25:31,991 INFO org.apache.hadoop.yarn.server.resourcemanager.rmcontainer.RMContainerImpl: container_1708736499436_0004_01_000005 Container Transitioned from RUNNING to COMPLETED
2024-02-24 07:25:31,991 INFO org.apache.hadoop.yarn.server.resourcemanager.RMAuditLogger: USER=ubuntu	OPERATION=AM Released Container	TARGET=SchedulerApp	RESULT=SUCCESS	APPID=application_1708736499436_0004	CONTAINERID=container_1708736499436_0004_01_000005
2024-02-24 07:25:31,992 INFO org.apache.hadoop.yarn.server.resourcemanager.scheduler.SchedulerNode: Released container container_1708736499436_0004_01_000005 of capacity <memory:1024, vCores:1> on host 5acd4955-724f-452a-817c-900b09ccd050-node1:38895, which currently has 6 containers, <memory:7168, vCores:6> used and <memory:1024, vCores:2> available, release resources=true
2024-02-24 07:25:31,992 INFO org.apache.hadoop.yarn.server.resourcemanager.rmcontainer.RMContainerImpl: container_1708736499436_0004_01_000007 Container Transitioned from RUNNING to COMPLETED
2024-02-24 07:25:31,992 INFO org.apache.hadoop.yarn.server.resourcemanager.RMAuditLogger: USER=ubuntu	OPERATION=AM Released Container	TARGET=SchedulerApp	RESULT=SUCCESS	APPID=application_1708736499436_0004	CONTAINERID=container_1708736499436_0004_01_000007
2024-02-24 07:25:31,992 INFO org.apache.hadoop.yarn.server.resourcemanager.scheduler.SchedulerNode: Released container container_1708736499436_0004_01_000007 of capacity <memory:1024, vCores:1> on host 5acd4955-724f-452a-817c-900b09ccd050-node1:38895, which currently has 5 containers, <memory:6144, vCores:5> used and <memory:2048, vCores:3> available, release resources=true
2024-02-24 07:25:32,003 INFO org.apache.hadoop.yarn.server.resourcemanager.rmcontainer.RMContainerImpl: container_1708736499436_0004_01_000003 Container Transitioned from RUNNING to COMPLETED
2024-02-24 07:25:32,003 INFO org.apache.hadoop.yarn.server.resourcemanager.RMAuditLogger: USER=ubuntu	OPERATION=AM Released Container	TARGET=SchedulerApp	RESULT=SUCCESS	APPID=application_1708736499436_0004	CONTAINERID=container_1708736499436_0004_01_000003
2024-02-24 07:25:32,003 INFO org.apache.hadoop.yarn.server.resourcemanager.scheduler.SchedulerNode: Released container container_1708736499436_0004_01_000003 of capacity <memory:1024, vCores:1> on host 5acd4955-724f-452a-817c-900b09ccd050-node1:38895, which currently has 4 containers, <memory:5120, vCores:4> used and <memory:3072, vCores:4> available, release resources=true
2024-02-24 07:25:32,119 INFO org.apache.hadoop.yarn.server.resourcemanager.rmcontainer.RMContainerImpl: container_1708736499436_0004_01_000006 Container Transitioned from RUNNING to COMPLETED
2024-02-24 07:25:32,119 INFO org.apache.hadoop.yarn.server.resourcemanager.RMAuditLogger: USER=ubuntu	OPERATION=AM Released Container	TARGET=SchedulerApp	RESULT=SUCCESS	APPID=application_1708736499436_0004	CONTAINERID=container_1708736499436_0004_01_000006
2024-02-24 07:25:32,120 INFO org.apache.hadoop.yarn.server.resourcemanager.scheduler.SchedulerNode: Released container container_1708736499436_0004_01_000006 of capacity <memory:1024, vCores:1> on host 5acd4955-724f-452a-817c-900b09ccd050-node1:38895, which currently has 3 containers, <memory:4096, vCores:3> used and <memory:4096, vCores:5> available, release resources=true
2024-02-24 07:25:32,311 INFO org.apache.hadoop.yarn.server.resourcemanager.rmcontainer.RMContainerImpl: container_1708736499436_0004_01_000008 Container Transitioned from ALLOCATED to ACQUIRED
2024-02-24 07:25:32,312 INFO org.apache.hadoop.yarn.server.resourcemanager.rmcontainer.RMContainerImpl: container_1708736499436_0004_01_000009 Container Transitioned from ALLOCATED to ACQUIRED
2024-02-24 07:25:33,121 INFO org.apache.hadoop.yarn.server.resourcemanager.rmcontainer.RMContainerImpl: container_1708736499436_0004_01_000008 Container Transitioned from ACQUIRED to RUNNING
2024-02-24 07:25:33,121 INFO org.apache.hadoop.yarn.server.resourcemanager.rmcontainer.RMContainerImpl: container_1708736499436_0004_01_000009 Container Transitioned from ACQUIRED to RUNNING
2024-02-24 07:25:33,320 INFO org.apache.hadoop.yarn.server.resourcemanager.scheduler.AppSchedulingInfo: checking for deactivate of application :application_1708736499436_0004
2024-02-24 07:25:34,122 INFO org.apache.hadoop.yarn.server.resourcemanager.rmcontainer.RMContainerImpl: container_1708736499436_0004_01_000010 Container Transitioned from NEW to ALLOCATED
2024-02-24 07:25:34,122 INFO org.apache.hadoop.yarn.server.resourcemanager.RMAuditLogger: USER=ubuntu	OPERATION=AM Allocated Container	TARGET=SchedulerApp	RESULT=SUCCESS	APPID=application_1708736499436_0004	CONTAINERID=container_1708736499436_0004_01_000010
2024-02-24 07:25:34,122 INFO org.apache.hadoop.yarn.server.resourcemanager.scheduler.SchedulerNode: Assigned container container_1708736499436_0004_01_000010 of capacity <memory:1024, vCores:1> on host 5acd4955-724f-452a-817c-900b09ccd050-node1:38895, which has 4 containers, <memory:5120, vCores:4> used and <memory:3072, vCores:4> available after allocation
2024-02-24 07:25:34,122 INFO org.apache.hadoop.yarn.server.resourcemanager.scheduler.capacity.allocator.AbstractContainerAllocator: assignedContainer application attempt=appattempt_1708736499436_0004_000001 container=container_1708736499436_0004_01_000010 queue=org.apache.hadoop.yarn.server.resourcemanager.scheduler.capacity.allocator.RegularContainerAllocator@2226b84 clusterResource=<memory:8192, vCores:8> type=OFF_SWITCH
2024-02-24 07:25:34,122 INFO org.apache.hadoop.yarn.server.resourcemanager.scheduler.capacity.ParentQueue: Re-sorting assigned queue: root.default stats: default: capacity=1.0, absoluteCapacity=1.0, usedResources=<memory:5120, vCores:4>, usedCapacity=0.625, absoluteUsedCapacity=0.625, numApps=1, numContainers=4
2024-02-24 07:25:34,122 INFO org.apache.hadoop.yarn.server.resourcemanager.scheduler.capacity.ParentQueue: assignedContainer queue=root usedCapacity=0.625 absoluteUsedCapacity=0.625 used=<memory:5120, vCores:4> cluster=<memory:8192, vCores:8>
2024-02-24 07:25:34,324 INFO org.apache.hadoop.yarn.server.resourcemanager.rmcontainer.RMContainerImpl: container_1708736499436_0004_01_000010 Container Transitioned from ALLOCATED to ACQUIRED
2024-02-24 07:25:34,527 INFO org.apache.hadoop.yarn.server.resourcemanager.rmcontainer.RMContainerImpl: container_1708736499436_0004_01_000010 Container Transitioned from ACQUIRED to RUNNING
2024-02-24 07:25:34,528 INFO org.apache.hadoop.yarn.server.resourcemanager.rmcontainer.RMContainerImpl: container_1708736499436_0004_01_000008 Container Transitioned from RUNNING to COMPLETED
2024-02-24 07:25:34,528 INFO org.apache.hadoop.yarn.server.resourcemanager.RMAuditLogger: USER=ubuntu	OPERATION=AM Released Container	TARGET=SchedulerApp	RESULT=SUCCESS	APPID=application_1708736499436_0004	CONTAINERID=container_1708736499436_0004_01_000008
2024-02-24 07:25:34,528 INFO org.apache.hadoop.yarn.server.resourcemanager.scheduler.SchedulerNode: Released container container_1708736499436_0004_01_000008 of capacity <memory:1024, vCores:1> on host 5acd4955-724f-452a-817c-900b09ccd050-node1:38895, which currently has 3 containers, <memory:4096, vCores:3> used and <memory:4096, vCores:5> available, release resources=true
2024-02-24 07:25:34,675 INFO org.apache.hadoop.yarn.server.resourcemanager.rmcontainer.RMContainerImpl: container_1708736499436_0004_01_000009 Container Transitioned from RUNNING to COMPLETED
2024-02-24 07:25:34,675 INFO org.apache.hadoop.yarn.server.resourcemanager.RMAuditLogger: USER=ubuntu	OPERATION=AM Released Container	TARGET=SchedulerApp	RESULT=SUCCESS	APPID=application_1708736499436_0004	CONTAINERID=container_1708736499436_0004_01_000009
2024-02-24 07:25:34,675 INFO org.apache.hadoop.yarn.server.resourcemanager.scheduler.SchedulerNode: Released container container_1708736499436_0004_01_000009 of capacity <memory:1024, vCores:1> on host 5acd4955-724f-452a-817c-900b09ccd050-node1:38895, which currently has 2 containers, <memory:3072, vCores:2> used and <memory:5120, vCores:6> available, release resources=true
2024-02-24 07:25:35,327 INFO org.apache.hadoop.yarn.server.resourcemanager.scheduler.AppSchedulingInfo: checking for deactivate of application :application_1708736499436_0004
2024-02-24 07:25:36,175 INFO org.apache.hadoop.yarn.server.resourcemanager.rmapp.attempt.RMAppAttemptImpl: Updating application attempt appattempt_1708736499436_0004_000001 with final state: FINISHING, and exit status: -1000
2024-02-24 07:25:36,175 INFO org.apache.hadoop.yarn.server.resourcemanager.rmapp.attempt.RMAppAttemptImpl: appattempt_1708736499436_0004_000001 State change from RUNNING to FINAL_SAVING
2024-02-24 07:25:36,175 INFO org.apache.hadoop.yarn.server.resourcemanager.rmapp.RMAppImpl: Updating application application_1708736499436_0004 with final state: FINISHING
2024-02-24 07:25:36,175 INFO org.apache.hadoop.yarn.server.resourcemanager.rmapp.RMAppImpl: application_1708736499436_0004 State change from RUNNING to FINAL_SAVING on event=ATTEMPT_UNREGISTERED
2024-02-24 07:25:36,175 INFO org.apache.hadoop.yarn.server.resourcemanager.recovery.RMStateStore: Updating info for app: application_1708736499436_0004
2024-02-24 07:25:36,175 INFO org.apache.hadoop.yarn.server.resourcemanager.rmapp.attempt.RMAppAttemptImpl: appattempt_1708736499436_0004_000001 State change from FINAL_SAVING to FINISHING
2024-02-24 07:25:36,175 INFO org.apache.hadoop.yarn.server.resourcemanager.rmapp.RMAppImpl: application_1708736499436_0004 State change from FINAL_SAVING to FINISHING on event=APP_UPDATE_SAVED
2024-02-24 07:25:36,187 INFO org.apache.hadoop.yarn.server.resourcemanager.rmcontainer.RMContainerImpl: container_1708736499436_0004_01_000010 Container Transitioned from RUNNING to COMPLETED
2024-02-24 07:25:36,187 INFO org.apache.hadoop.yarn.server.resourcemanager.RMAuditLogger: USER=ubuntu	OPERATION=AM Released Container	TARGET=SchedulerApp	RESULT=SUCCESS	APPID=application_1708736499436_0004	CONTAINERID=container_1708736499436_0004_01_000010
2024-02-24 07:25:36,188 INFO org.apache.hadoop.yarn.server.resourcemanager.scheduler.SchedulerNode: Released container container_1708736499436_0004_01_000010 of capacity <memory:1024, vCores:1> on host 5acd4955-724f-452a-817c-900b09ccd050-node1:38895, which currently has 1 containers, <memory:2048, vCores:1> used and <memory:6144, vCores:7> available, release resources=true
2024-02-24 07:25:37,176 INFO org.apache.hadoop.yarn.server.resourcemanager.ApplicationMasterService: application_1708736499436_0004 unregistered successfully. 
2024-02-24 07:25:42,630 INFO org.apache.hadoop.yarn.server.resourcemanager.rmcontainer.RMContainerImpl: container_1708736499436_0004_01_000001 Container Transitioned from RUNNING to COMPLETED
2024-02-24 07:25:42,630 INFO org.apache.hadoop.yarn.server.resourcemanager.RMAuditLogger: USER=ubuntu	OPERATION=AM Released Container	TARGET=SchedulerApp	RESULT=SUCCESS	APPID=application_1708736499436_0004	CONTAINERID=container_1708736499436_0004_01_000001
2024-02-24 07:25:42,630 INFO org.apache.hadoop.yarn.server.resourcemanager.scheduler.SchedulerNode: Released container container_1708736499436_0004_01_000001 of capacity <memory:2048, vCores:1> on host 5acd4955-724f-452a-817c-900b09ccd050-node1:38895, which currently has 0 containers, <memory:0, vCores:0> used and <memory:8192, vCores:8> available, release resources=true
2024-02-24 07:25:42,630 INFO org.apache.hadoop.yarn.server.resourcemanager.ApplicationMasterService: Unregistering app attempt : appattempt_1708736499436_0004_000001
2024-02-24 07:25:42,630 INFO org.apache.hadoop.yarn.server.resourcemanager.security.AMRMTokenSecretManager: Application finished, removing password for appattempt_1708736499436_0004_000001
2024-02-24 07:25:42,630 INFO org.apache.hadoop.yarn.server.resourcemanager.rmapp.attempt.RMAppAttemptImpl: appattempt_1708736499436_0004_000001 State change from FINISHING to FINISHED
2024-02-24 07:25:42,630 INFO org.apache.hadoop.yarn.server.resourcemanager.rmapp.RMAppImpl: application_1708736499436_0004 State change from FINISHING to FINISHED on event=ATTEMPT_FINISHED
2024-02-24 07:25:42,630 INFO org.apache.hadoop.yarn.server.resourcemanager.RMAuditLogger: USER=ubuntu	OPERATION=Application Finished - Succeeded	TARGET=RMAppManager	RESULT=SUCCESS	APPID=application_1708736499436_0004
2024-02-24 07:25:42,630 INFO org.apache.hadoop.yarn.server.resourcemanager.RMAppManager$ApplicationSummary: appId=application_1708736499436_0004,name=word count,user=ubuntu,queue=default,state=FINISHED,trackingUrl=http://5acd4955-724f-452a-817c-900b09ccd050-node1:8088/proxy/application_1708736499436_0004/,appMasterHost=5acd4955-724f-452a-817c-900b09ccd050-node1,startTime=1708759523520,finishTime=1708759536175,finalStatus=SUCCEEDED,memorySeconds=72106,vcoreSeconds=48,preemptedMemorySeconds=0,preemptedVcoreSeconds=0,preemptedAMContainers=0,preemptedNonAMContainers=0,preemptedResources=<memory:0\, vCores:0>,applicationType=MAPREDUCE
2024-02-24 07:25:42,630 INFO org.apache.hadoop.yarn.server.resourcemanager.scheduler.capacity.CapacityScheduler: Application Attempt appattempt_1708736499436_0004_000001 is done. finalState=FINISHED
2024-02-24 07:25:42,631 INFO org.apache.hadoop.yarn.server.resourcemanager.scheduler.AppSchedulingInfo: Application application_1708736499436_0004 requests cleared
2024-02-24 07:25:42,631 INFO org.apache.hadoop.yarn.server.resourcemanager.scheduler.capacity.LeafQueue: Application removed - appId: application_1708736499436_0004 user: ubuntu queue: default #user-pending-applications: 0 #user-active-applications: 0 #queue-pending-applications: 0 #queue-active-applications: 0
2024-02-24 07:25:42,631 INFO org.apache.hadoop.yarn.server.resourcemanager.scheduler.capacity.ParentQueue: Application removed - appId: application_1708736499436_0004 user: ubuntu leaf-queue of parent: root #applications: 0
2024-02-24 07:25:42,633 INFO org.apache.hadoop.yarn.server.resourcemanager.amlauncher.AMLauncher: Cleaning master appattempt_1708736499436_0004_000001
2024-02-24 07:25:44,631 INFO org.apache.hadoop.yarn.server.resourcemanager.scheduler.AbstractYarnScheduler: Container container_1708736499436_0004_01_000010 completed with event FINISHED, but corresponding RMContainer doesn't exist.
